Workbook

Sheet ダッシュボード
A1: テスト進捗ダッシュボード
A2: 基準日: | B2: 46086 | F2: 週範囲From: | H2: To:
A4: ■ 実施進捗
A5: チーム | B5: 日次 | D5: 週次 | H5: 総計
B6: 予定 | C6: 実績 | D6: 予定 | E6: 実績 | F6: 残数 | G6: 遅延 | H6: 総数 | I6: 予定累計 | J6: 実績累計 | K6: 残数 | L6: 遅延 | M6: 予定消化率 | N6: 実績消化率 | O6: 乖離 | P6: 状態
A7: 全体 | B7: =IFERROR(INDEX('進捗サマリー_ALL'!D6:D30,MATCH($B$2,'進捗サマリー_ALL'!A6:A30,0)),0) | C7: =IFERROR(INDEX('進捗サマリー_ALL'!E6:E30,MATCH($B$2,'進捗サマリー_ALL'!A6:A30,0)),0) | D7: =IF(OR($G$2="",$I$2=""),"-",SUMIFS('進捗サマリー_ALL'!D6:D30,'進捗サマリー_ALL'!A6:A30,">="&$G$2,'進捗サマリー_ALL'!A6:A30,"<="&$I$2)) | E7: =IF(OR($G$2="",$I$2=""),"-",SUMIFS('進捗サマリー_ALL'!E6:E30,'進捗サマリー_ALL'!A6:A30,">="&$G$2,'進捗サマリー_ALL'!A6:A30,"<="&$I$2)) | F7: =IF(OR($G$2="",$I$2=""),"-",D7-E7) | G7: =IF(OR($G$2="",$I$2=""),"-",IF(F7>0,F7,0)) | H7: ='進捗サマリー_ALL'!D5 | I7: =IFERROR(INDEX('進捗サマリー_ALL'!G6:G30,MATCH($B$2,'進捗サマリー_ALL'!A6:A30,0)),0) | J7: =IFERROR(INDEX('進捗サマリー_ALL'!H6:H30,MATCH($B$2,'進捗サマリー_ALL'!A6:A30,0)),0) | K7: =H7-J7 | L7: =I7-J7 | M7: =IF(H7=0,0,I7/H7) | N7: =IF(H7=0,0,J7/H7) | O7: =N7-M7 | P7: =IF(J7>=H7,"完了",IF(L7>0,"遅延","順調"))
A8: オンライン | B8: =IFERROR(INDEX('進捗サマリー_オンライン'!D6:D23,MATCH($B$2,'進捗サマリー_オンライン'!A6:A23,0)),0) | C8: =IFERROR(INDEX('進捗サマリー_オンライン'!E6:E23,MATCH($B$2,'進捗サマリー_オンライン'!A6:A23,0)),0) | D8: =IF(OR($G$2="",$I$2=""),"-",SUMIFS('進捗サマリー_オンライン'!D6:D23,'進捗サマリー_オンライン'!A6:A23,">="&$G$2,'進捗サマリー_オンライン'!A6:A23,"<="&$I$2)) | E8: =IF(OR($G$2="",$I$2=""),"-",SUMIFS('進捗サマリー_オンライン'!E6:E23,'進捗サマリー_オンライン'!A6:A23,">="&$G$2,'進捗サマリー_オンライン'!A6:A23,"<="&$I$2)) | F8: =IF(OR($G$2="",$I$2=""),"-",D8-E8) | G8: =IF(OR($G$2="",$I$2=""),"-",IF(F8>0,F8,0)) | H8: ='進捗サマリー_オンライン'!D5 | I8: =IFERROR(INDEX('進捗サマリー_オンライン'!G6:G23,MATCH($B$2,'進捗サマリー_オンライン'!A6:A23,0)),0) | J8: =IFERROR(INDEX('進捗サマリー_オンライン'!H6:H23,MATCH($B$2,'進捗サマリー_オンライン'!A6:A23,0)),0) | K8: =H8-J8 | L8: =I8-J8 | M8: =IF(H8=0,0,I8/H8) | N8: =IF(H8=0,0,J8/H8) | O8: =N8-M8 | P8: =IF(J8>=H8,"完了",IF(L8>0,"遅延","順調"))
A9: バッチ | B9: =IFERROR(INDEX('進捗サマリー_バッチ'!D6:D30,MATCH($B$2,'進捗サマリー_バッチ'!A6:A30,0)),0) | C9: =IFERROR(INDEX('進捗サマリー_バッチ'!E6:E30,MATCH($B$2,'進捗サマリー_バッチ'!A6:A30,0)),0) | D9: =IF(OR($G$2="",$I$2=""),"-",SUMIFS('進捗サマリー_バッチ'!D6:D30,'進捗サマリー_バッチ'!A6:A30,">="&$G$2,'進捗サマリー_バッチ'!A6:A30,"<="&$I$2)) | E9: =IF(OR($G$2="",$I$2=""),"-",SUMIFS('進捗サマリー_バッチ'!E6:E30,'進捗サマリー_バッチ'!A6:A30,">="&$G$2,'進捗サマリー_バッチ'!A6:A30,"<="&$I$2)) | F9: =IF(OR($G$2="",$I$2=""),"-",D9-E9) | G9: =IF(OR($G$2="",$I$2=""),"-",IF(F9>0,F9,0)) | H9: ='進捗サマリー_バッチ'!D5 | I9: =IFERROR(INDEX('進捗サマリー_バッチ'!G6:G30,MATCH($B$2,'進捗サマリー_バッチ'!A6:A30,0)),0) | J9: =IFERROR(INDEX('進捗サマリー_バッチ'!H6:H30,MATCH($B$2,'進捗サマリー_バッチ'!A6:A30,0)),0) | K9: =H9-J9 | L9: =I9-J9 | M9: =IF(H9=0,0,I9/H9) | N9: =IF(H9=0,0,J9/H9) | O9: =N9-M9 | P9: =IF(J9>=H9,"完了",IF(L9>0,"遅延","順調"))
A10: 基盤 | B10: =IFERROR(INDEX('進捗サマリー_基盤'!D6:D24,MATCH($B$2,'進捗サマリー_基盤'!A6:A24,0)),0) | C10: =IFERROR(INDEX('進捗サマリー_基盤'!E6:E24,MATCH($B$2,'進捗サマリー_基盤'!A6:A24,0)),0) | D10: =IF(OR($G$2="",$I$2=""),"-",SUMIFS('進捗サマリー_基盤'!D6:D24,'進捗サマリー_基盤'!A6:A24,">="&$G$2,'進捗サマリー_基盤'!A6:A24,"<="&$I$2)) | E10: =IF(OR($G$2="",$I$2=""),"-",SUMIFS('進捗サマリー_基盤'!E6:E24,'進捗サマリー_基盤'!A6:A24,">="&$G$2,'進捗サマリー_基盤'!A6:A24,"<="&$I$2)) | F10: =IF(OR($G$2="",$I$2=""),"-",D10-E10) | G10: =IF(OR($G$2="",$I$2=""),"-",IF(F10>0,F10,0)) | H10: ='進捗サマリー_基盤'!D5 | I10: =IFERROR(INDEX('進捗サマリー_基盤'!G6:G24,MATCH($B$2,'進捗サマリー_基盤'!A6:A24,0)),0) | J10: =IFERROR(INDEX('進捗サマリー_基盤'!H6:H24,MATCH($B$2,'進捗サマリー_基盤'!A6:A24,0)),0) | K10: =H10-J10 | L10: =I10-J10 | M10: =IF(H10=0,0,I10/H10) | N10: =IF(H10=0,0,J10/H10) | O10: =N10-M10 | P10: =IF(J10>=H10,"完了",IF(L10>0,"遅延","順調"))
A11: 運用 | B11: =IFERROR(INDEX('進捗サマリー_運用'!D6:D25,MATCH($B$2,'進捗サマリー_運用'!A6:A25,0)),0) | C11: =IFERROR(INDEX('進捗サマリー_運用'!E6:E25,MATCH($B$2,'進捗サマリー_運用'!A6:A25,0)),0) | D11: =IF(OR($G$2="",$I$2=""),"-",SUMIFS('進捗サマリー_運用'!D6:D25,'進捗サマリー_運用'!A6:A25,">="&$G$2,'進捗サマリー_運用'!A6:A25,"<="&$I$2)) | E11: =IF(OR($G$2="",$I$2=""),"-",SUMIFS('進捗サマリー_運用'!E6:E25,'進捗サマリー_運用'!A6:A25,">="&$G$2,'進捗サマリー_運用'!A6:A25,"<="&$I$2)) | F11: =IF(OR($G$2="",$I$2=""),"-",D11-E11) | G11: =IF(OR($G$2="",$I$2=""),"-",IF(F11>0,F11,0)) | H11: ='進捗サマリー_運用'!D5 | I11: =IFERROR(INDEX('進捗サマリー_運用'!G6:G25,MATCH($B$2,'進捗サマリー_運用'!A6:A25,0)),0) | J11: =IFERROR(INDEX('進捗サマリー_運用'!H6:H25,MATCH($B$2,'進捗サマリー_運用'!A6:A25,0)),0) | K11: =H11-J11 | L11: =I11-J11 | M11: =IF(H11=0,0,I11/H11) | N11: =IF(H11=0,0,J11/H11) | O11: =N11-M11 | P11: =IF(J11>=H11,"完了",IF(L11>0,"遅延","順調"))
A13: ■ 検証進捗
A14: チーム | B14: 日次 | D14: 週次 | H14: 総計
B15: 予定 | C15: 実績 | D15: 予定 | E15: 実績 | F15: 残数 | G15: 遅延 | H15: 総数 | I15: 予定累計 | J15: 実績累計 | K15: 残数 | L15: 遅延 | M15: 予定消化率 | N15: 実績消化率 | O15: 乖離 | P15: 状態
A16: 全体 | B16: =IFERROR(INDEX('進捗サマリー_ALL'!K6:K30,MATCH($B$2,'進捗サマリー_ALL'!A6:A30,0)),0) | C16: =IFERROR(INDEX('進捗サマリー_ALL'!L6:L30,MATCH($B$2,'進捗サマリー_ALL'!A6:A30,0)),0) | D16: =IF(OR($G$2="",$I$2=""),"-",SUMIFS('進捗サマリー_ALL'!K6:K30,'進捗サマリー_ALL'!A6:A30,">="&$G$2,'進捗サマリー_ALL'!A6:A30,"<="&$I$2)) | E16: =IF(OR($G$2="",$I$2=""),"-",SUMIFS('進捗サマリー_ALL'!L6:L30,'進捗サマリー_ALL'!A6:A30,">="&$G$2,'進捗サマリー_ALL'!A6:A30,"<="&$I$2)) | F16: =IF(OR($G$2="",$I$2=""),"-",D16-E16) | G16: =IF(OR($G$2="",$I$2=""),"-",IF(F16>0,F16,0)) | H16: ='進捗サマリー_ALL'!K5 | I16: =IFERROR(INDEX('進捗サマリー_ALL'!N6:N30,MATCH($B$2,'進捗サマリー_ALL'!A6:A30,0)),0) | J16: =IFERROR(INDEX('進捗サマリー_ALL'!O6:O30,MATCH($B$2,'進捗サマリー_ALL'!A6:A30,0)),0) | K16: =H16-J16 | L16: =I16-J16 | M16: =IF(H16=0,0,I16/H16) | N16: =IF(H16=0,0,J16/H16) | O16: =N16-M16 | P16: =IF(J16>=H16,"完了",IF(L16>0,"遅延","順調"))
A17: オンライン | B17: =IFERROR(INDEX('進捗サマリー_オンライン'!K6:K23,MATCH($B$2,'進捗サマリー_オンライン'!A6:A23,0)),0) | C17: =IFERROR(INDEX('進捗サマリー_オンライン'!L6:L23,MATCH($B$2,'進捗サマリー_オンライン'!A6:A23,0)),0) | D17: =IF(OR($G$2="",$I$2=""),"-",SUMIFS('進捗サマリー_オンライン'!K6:K23,'進捗サマリー_オンライン'!A6:A23,">="&$G$2,'進捗サマリー_オンライン'!A6:A23,"<="&$I$2)) | E17: =IF(OR($G$2="",$I$2=""),"-",SUMIFS('進捗サマリー_オンライン'!L6:L23,'進捗サマリー_オンライン'!A6:A23,">="&$G$2,'進捗サマリー_オンライン'!A6:A23,"<="&$I$2)) | F17: =IF(OR($G$2="",$I$2=""),"-",D17-E17) | G17: =IF(OR($G$2="",$I$2=""),"-",IF(F17>0,F17,0)) | H17: ='進捗サマリー_オンライン'!K5 | I17: =IFERROR(INDEX('進捗サマリー_オンライン'!N6:N23,MATCH($B$2,'進捗サマリー_オンライン'!A6:A23,0)),0) | J17: =IFERROR(INDEX('進捗サマリー_オンライン'!O6:O23,MATCH($B$2,'進捗サマリー_オンライン'!A6:A23,0)),0) | K17: =H17-J17 | L17: =I17-J17 | M17: =IF(H17=0,0,I17/H17) | N17: =IF(H17=0,0,J17/H17) | O17: =N17-M17 | P17: =IF(J17>=H17,"完了",IF(L17>0,"遅延","順調"))
A18: バッチ | B18: =IFERROR(INDEX('進捗サマリー_バッチ'!K6:K30,MATCH($B$2,'進捗サマリー_バッチ'!A6:A30,0)),0) | C18: =IFERROR(INDEX('進捗サマリー_バッチ'!L6:L30,MATCH($B$2,'進捗サマリー_バッチ'!A6:A30,0)),0) | D18: =IF(OR($G$2="",$I$2=""),"-",SUMIFS('進捗サマリー_バッチ'!K6:K30,'進捗サマリー_バッチ'!A6:A30,">="&$G$2,'進捗サマリー_バッチ'!A6:A30,"<="&$I$2)) | E18: =IF(OR($G$2="",$I$2=""),"-",SUMIFS('進捗サマリー_バッチ'!L6:L30,'進捗サマリー_バッチ'!A6:A30,">="&$G$2,'進捗サマリー_バッチ'!A6:A30,"<="&$I$2)) | F18: =IF(OR($G$2="",$I$2=""),"-",D18-E18) | G18: =IF(OR($G$2="",$I$2=""),"-",IF(F18>0,F18,0)) | H18: ='進捗サマリー_バッチ'!K5 | I18: =IFERROR(INDEX('進捗サマリー_バッチ'!N6:N30,MATCH($B$2,'進捗サマリー_バッチ'!A6:A30,0)),0) | J18: =IFERROR(INDEX('進捗サマリー_バッチ'!O6:O30,MATCH($B$2,'進捗サマリー_バッチ'!A6:A30,0)),0) | K18: =H18-J18 | L18: =I18-J18 | M18: =IF(H18=0,0,I18/H18) | N18: =IF(H18=0,0,J18/H18) | O18: =N18-M18 | P18: =IF(J18>=H18,"完了",IF(L18>0,"遅延","順調"))
A19: 基盤 | B19: =IFERROR(INDEX('進捗サマリー_基盤'!K6:K24,MATCH($B$2,'進捗サマリー_基盤'!A6:A24,0)),0) | C19: =IFERROR(INDEX('進捗サマリー_基盤'!L6:L24,MATCH($B$2,'進捗サマリー_基盤'!A6:A24,0)),0) | D19: =IF(OR($G$2="",$I$2=""),"-",SUMIFS('進捗サマリー_基盤'!K6:K24,'進捗サマリー_基盤'!A6:A24,">="&$G$2,'進捗サマリー_基盤'!A6:A24,"<="&$I$2)) | E19: =IF(OR($G$2="",$I$2=""),"-",SUMIFS('進捗サマリー_基盤'!L6:L24,'進捗サマリー_基盤'!A6:A24,">="&$G$2,'進捗サマリー_基盤'!A6:A24,"<="&$I$2)) | F19: =IF(OR($G$2="",$I$2=""),"-",D19-E19) | G19: =IF(OR($G$2="",$I$2=""),"-",IF(F19>0,F19,0)) | H19: ='進捗サマリー_基盤'!K5 | I19: =IFERROR(INDEX('進捗サマリー_基盤'!N6:N24,MATCH($B$2,'進捗サマリー_基盤'!A6:A24,0)),0) | J19: =IFERROR(INDEX('進捗サマリー_基盤'!O6:O24,MATCH($B$2,'進捗サマリー_基盤'!A6:A24,0)),0) | K19: =H19-J19 | L19: =I19-J19 | M19: =IF(H19=0,0,I19/H19) | N19: =IF(H19=0,0,J19/H19) | O19: =N19-M19 | P19: =IF(J19>=H19,"完了",IF(L19>0,"遅延","順調"))
A20: 運用 | B20: =IFERROR(INDEX('進捗サマリー_運用'!K6:K25,MATCH($B$2,'進捗サマリー_運用'!A6:A25,0)),0) | C20: =IFERROR(INDEX('進捗サマリー_運用'!L6:L25,MATCH($B$2,'進捗サマリー_運用'!A6:A25,0)),0) | D20: =IF(OR($G$2="",$I$2=""),"-",SUMIFS('進捗サマリー_運用'!K6:K25,'進捗サマリー_運用'!A6:A25,">="&$G$2,'進捗サマリー_運用'!A6:A25,"<="&$I$2)) | E20: =IF(OR($G$2="",$I$2=""),"-",SUMIFS('進捗サマリー_運用'!L6:L25,'進捗サマリー_運用'!A6:A25,">="&$G$2,'進捗サマリー_運用'!A6:A25,"<="&$I$2)) | F20: =IF(OR($G$2="",$I$2=""),"-",D20-E20) | G20: =IF(OR($G$2="",$I$2=""),"-",IF(F20>0,F20,0)) | H20: ='進捗サマリー_運用'!K5 | I20: =IFERROR(INDEX('進捗サマリー_運用'!N6:N25,MATCH($B$2,'進捗サマリー_運用'!A6:A25,0)),0) | J20: =IFERROR(INDEX('進捗サマリー_運用'!O6:O25,MATCH($B$2,'進捗サマリー_運用'!A6:A25,0)),0) | K20: =H20-J20 | L20: =I20-J20 | M20: =IF(H20=0,0,I20/H20) | N20: =IF(H20=0,0,J20/H20) | O20: =N20-M20 | P20: =IF(J20>=H20,"完了",IF(L20>0,"遅延","順調"))
A22: ■ 進捗推移チャート（左: 実施 / 右: 検証） ※実施予定=青、検証予定=緑、実績=オレンジ

Sheet 要対応一覧
A1: 要対応一覧（12件）
A2: 基準日: 2026/03/05
A4: ■ 遅延サマリー
A5: 項目 | B5: 遅延件数
A6: 実施者_遅延 | B6: =COUNTIF(明細!$H$5:$H$76,"遅延")
A7: 検証者_遅延 | B7: =COUNTIF(明細!$K$5:$K$76,"遅延")
A9: ■ 遅延一覧
A10: No. | B10: チーム名 | C10: シート名 | D10: テストID | E10: 実施予定 | F10: 実施実績 | G10: 検証予定 | H10: 検証実績
A11: 1 | B11: バッチ | C11: ITB-EV003-SC001-B-001 | D11: ITB-EV003-SC001-B-001-004 | E11: 2026/03/02 | F11: 未完了 | G11: 2026/03/05 | H11: 未完了
A12: 2 | B12: バッチ | C12: ITB-EV003-SC001-B-001 | D12: ITB-EV003-SC001-B-001-006 | E12: 2026/02/24 | F12: 未完了 | G12: 2026/02/26 | H12: 未完了
A13: 3 | B13: バッチ | C13: ITB-EV003-SC001-B-001 | D13: ITB-EV003-SC001-B-001-008 | E13: 2026/03/05 | F13: 未完了 | G13: 2026/03/08 | H13: 未完了
A14: 4 | B14: バッチ | C14: ITB-EV003-SC002-B-001 | D14: ITB-EV003-SC002-B-001-002 | E14: 2026/02/26 | F14: 未完了 | G14: 2026/02/28 | H14: 未完了
A15: 5 | B15: バッチ | C15: ITB-EV004-SC001-B-001 | D15: ITB-EV004-SC001-B-001-002 | E15: 2026/02/23 | F15: 2026/02/25 | G15: 2026/02/25 | H15: 未完了
A16: 6 | B16: バッチ | C16: ITB-EV004-SC001-B-001 | D16: ITB-EV004-SC001-B-001-006 | E16: 2026/02/28 | F16: 未完了 | G16: 2026/03/04 | H16: 未完了
A17: 7 | B17: 基盤 | C17: ITB-EV005-SC001-I-001 | D17: ITB-EV005-SC001-I-001-004 | E17: 2026/03/02 | F17: 未完了 | G17: 2026/03/05 | H17: 未完了
A18: 8 | B18: 基盤 | C18: ITB-EV005-SC001-I-001 | D18: ITB-EV005-SC001-I-001-006 | E18: 2026/02/25 | F18: 2026/02/26 | G18: 2026/02/28 | H18: 未完了
A19: 9 | B19: 基盤 | C19: ITB-EV005-SC002-I-001 | D19: ITB-EV005-SC002-I-001-005 | E19: 2026/02/26 | F19: 未完了 | G19: 2026/03/01 | H19: 未完了
A20: 10 | B20: 運用 | C20: ITB-EV006-SC001-U-001 | D20: ITB-EV006-SC001-U-001-004 | E20: 2026/02/26 | F20: 未完了 | G20: 2026/03/02 | H20: 未完了
A21: 11 | B21: 運用 | C21: ITB-EV006-SC001-U-001 | D21: ITB-EV006-SC001-U-001-006 | E21: 2026/03/01 | F21: 2026/02/28 | G21: 2026/03/03 | H21: 未完了
A22: 12 | B22: 運用 | C22: ITB-EV006-SC002-U-001 | D22: ITB-EV006-SC002-U-001-003 | E22: 2026/03/01 | F22: 2026/02/28 | G22: 2026/03/05 | H22: 未完了

Sheet 進捗サマリー_ALL
A1: テスト進捗サマリー（全体）
A2: 集計期間: 2026/02/22 ～ 2026/03/18 (25日間) | R2: 基準日: | S2: =ダッシュボード!$B$2
A3: 共通 | D3: 実施 | K3: 検証 | R3: 合計
A4: 日付 | B4: 曜 | C4: 営業日 | D4: 予定 | E4: 実績 | F4: 消化率 | G4: 予定累計 | H4: 実績累計 | I4: 累計消化率 | J4: 判定 | K4: 予定 | L4: 実績 | M4: 消化率 | N4: 予定累計 | O4: 実績累計 | P4: 累計消化率 | Q4: 判定 | R4: 予定 | S4: 実績
A5: 合計 | D5: =SUM(D6:D30) | E5: =SUM(E6:E30) | F5: =IF(D5=0,0,E5/D5) | G5: =D5 | H5: =E5 | I5: =IF(G5=0,"",H5/G5) | J5: =IF(I5>=1,"完了",IF(H5>=G5,"順調","遅延")) | K5: =SUM(K6:K30) | L5: =SUM(L6:L30) | M5: =IF(K5=0,0,L5/K5) | N5: =K5 | O5: =L5 | P5: =IF(N5=0,"",O5/N5) | Q5: =IF(P5>=1,"完了",IF(O5>=N5,"順調","遅延")) | R5: =D5+K5 | S5: =E5+L5
A6: 46075 | B6: =CHOOSE(WEEKDAY(A6,2),"月","火","水","木","金","土","日") | C6: =IF(OR(WEEKDAY(A6,2)>=6,COUNTIF(祝日マスタ!$A:$A,A6)>0),"非営業日","営業日") | D6: =COUNTIFS(明細!$F$5:$F$76,A6) | E6: =COUNTIFS(明細!$G$5:$G$76,A6) | F6: =IF(D6=0,0,E6/D6) | G6: =SUM($D$6:D6) | H6: =SUM($E$6:E6) | I6: =IF(G6=0,"",H6/G6) | J6: =IF(A6>$S$2,"予定",IF(G6=0,"－",IF(I6>=1,"完了",IF(H6>=G6,"順調","遅延")))) | K6: =COUNTIFS(明細!$I$5:$I$76,A6) | L6: =COUNTIFS(明細!$J$5:$J$76,A6) | M6: =IF(K6=0,0,L6/K6) | N6: =SUM($K$6:K6) | O6: =SUM($L$6:L6) | P6: =IF(N6=0,"",O6/N6) | Q6: =IF(A6>$S$2,"予定",IF(N6=0,"－",IF(P6>=1,"完了",IF(O6>=N6,"順調","遅延")))) | R6: =D6+K6 | S6: =E6+L6
A7: 46076 | B7: =CHOOSE(WEEKDAY(A7,2),"月","火","水","木","金","土","日") | C7: =IF(OR(WEEKDAY(A7,2)>=6,COUNTIF(祝日マスタ!$A:$A,A7)>0),"非営業日","営業日") | D7: =COUNTIFS(明細!$F$5:$F$76,A7) | E7: =COUNTIFS(明細!$G$5:$G$76,A7) | F7: =IF(D7=0,0,E7/D7) | G7: =SUM($D$6:D7) | H7: =SUM($E$6:E7) | I7: =IF(G7=0,"",H7/G7) | J7: =IF(A7>$S$2,"予定",IF(G7=0,"－",IF(I7>=1,"完了",IF(H7>=G7,"順調","遅延")))) | K7: =COUNTIFS(明細!$I$5:$I$76,A7) | L7: =COUNTIFS(明細!$J$5:$J$76,A7) | M7: =IF(K7=0,0,L7/K7) | N7: =SUM($K$6:K7) | O7: =SUM($L$6:L7) | P7: =IF(N7=0,"",O7/N7) | Q7: =IF(A7>$S$2,"予定",IF(N7=0,"－",IF(P7>=1,"完了",IF(O7>=N7,"順調","遅延")))) | R7: =D7+K7 | S7: =E7+L7
A8: 46077 | B8: =CHOOSE(WEEKDAY(A8,2),"月","火","水","木","金","土","日") | C8: =IF(OR(WEEKDAY(A8,2)>=6,COUNTIF(祝日マスタ!$A:$A,A8)>0),"非営業日","営業日") | D8: =COUNTIFS(明細!$F$5:$F$76,A8) | E8: =COUNTIFS(明細!$G$5:$G$76,A8) | F8: =IF(D8=0,0,E8/D8) | G8: =SUM($D$6:D8) | H8: =SUM($E$6:E8) | I8: =IF(G8=0,"",H8/G8) | J8: =IF(A8>$S$2,"予定",IF(G8=0,"－",IF(I8>=1,"完了",IF(H8>=G8,"順調","遅延")))) | K8: =COUNTIFS(明細!$I$5:$I$76,A8) | L8: =COUNTIFS(明細!$J$5:$J$76,A8) | M8: =IF(K8=0,0,L8/K8) | N8: =SUM($K$6:K8) | O8: =SUM($L$6:L8) | P8: =IF(N8=0,"",O8/N8) | Q8: =IF(A8>$S$2,"予定",IF(N8=0,"－",IF(P8>=1,"完了",IF(O8>=N8,"順調","遅延")))) | R8: =D8+K8 | S8: =E8+L8
A9: 46078 | B9: =CHOOSE(WEEKDAY(A9,2),"月","火","水","木","金","土","日") | C9: =IF(OR(WEEKDAY(A9,2)>=6,COUNTIF(祝日マスタ!$A:$A,A9)>0),"非営業日","営業日") | D9: =COUNTIFS(明細!$F$5:$F$76,A9) | E9: =COUNTIFS(明細!$G$5:$G$76,A9) | F9: =IF(D9=0,0,E9/D9) | G9: =SUM($D$6:D9) | H9: =SUM($E$6:E9) | I9: =IF(G9=0,"",H9/G9) | J9: =IF(A9>$S$2,"予定",IF(G9=0,"－",IF(I9>=1,"完了",IF(H9>=G9,"順調","遅延")))) | K9: =COUNTIFS(明細!$I$5:$I$76,A9) | L9: =COUNTIFS(明細!$J$5:$J$76,A9) | M9: =IF(K9=0,0,L9/K9) | N9: =SUM($K$6:K9) | O9: =SUM($L$6:L9) | P9: =IF(N9=0,"",O9/N9) | Q9: =IF(A9>$S$2,"予定",IF(N9=0,"－",IF(P9>=1,"完了",IF(O9>=N9,"順調","遅延")))) | R9: =D9+K9 | S9: =E9+L9
A10: 46079 | B10: =CHOOSE(WEEKDAY(A10,2),"月","火","水","木","金","土","日") | C10: =IF(OR(WEEKDAY(A10,2)>=6,COUNTIF(祝日マスタ!$A:$A,A10)>0),"非営業日","営業日") | D10: =COUNTIFS(明細!$F$5:$F$76,A10) | E10: =COUNTIFS(明細!$G$5:$G$76,A10) | F10: =IF(D10=0,0,E10/D10) | G10: =SUM($D$6:D10) | H10: =SUM($E$6:E10) | I10: =IF(G10=0,"",H10/G10) | J10: =IF(A10>$S$2,"予定",IF(G10=0,"－",IF(I10>=1,"完了",IF(H10>=G10,"順調","遅延")))) | K10: =COUNTIFS(明細!$I$5:$I$76,A10) | L10: =COUNTIFS(明細!$J$5:$J$76,A10) | M10: =IF(K10=0,0,L10/K10) | N10: =SUM($K$6:K10) | O10: =SUM($L$6:L10) | P10: =IF(N10=0,"",O10/N10) | Q10: =IF(A10>$S$2,"予定",IF(N10=0,"－",IF(P10>=1,"完了",IF(O10>=N10,"順調","遅延")))) | R10: =D10+K10 | S10: =E10+L10
A11: 46080 | B11: =CHOOSE(WEEKDAY(A11,2),"月","火","水","木","金","土","日") | C11: =IF(OR(WEEKDAY(A11,2)>=6,COUNTIF(祝日マスタ!$A:$A,A11)>0),"非営業日","営業日") | D11: =COUNTIFS(明細!$F$5:$F$76,A11) | E11: =COUNTIFS(明細!$G$5:$G$76,A11) | F11: =IF(D11=0,0,E11/D11) | G11: =SUM($D$6:D11) | H11: =SUM($E$6:E11) | I11: =IF(G11=0,"",H11/G11) | J11: =IF(A11>$S$2,"予定",IF(G11=0,"－",IF(I11>=1,"完了",IF(H11>=G11,"順調","遅延")))) | K11: =COUNTIFS(明細!$I$5:$I$76,A11) | L11: =COUNTIFS(明細!$J$5:$J$76,A11) | M11: =IF(K11=0,0,L11/K11) | N11: =SUM($K$6:K11) | O11: =SUM($L$6:L11) | P11: =IF(N11=0,"",O11/N11) | Q11: =IF(A11>$S$2,"予定",IF(N11=0,"－",IF(P11>=1,"完了",IF(O11>=N11,"順調","遅延")))) | R11: =D11+K11 | S11: =E11+L11
A12: 46081 | B12: =CHOOSE(WEEKDAY(A12,2),"月","火","水","木","金","土","日") | C12: =IF(OR(WEEKDAY(A12,2)>=6,COUNTIF(祝日マスタ!$A:$A,A12)>0),"非営業日","営業日") | D12: =COUNTIFS(明細!$F$5:$F$76,A12) | E12: =COUNTIFS(明細!$G$5:$G$76,A12) | F12: =IF(D12=0,0,E12/D12) | G12: =SUM($D$6:D12) | H12: =SUM($E$6:E12) | I12: =IF(G12=0,"",H12/G12) | J12: =IF(A12>$S$2,"予定",IF(G12=0,"－",IF(I12>=1,"完了",IF(H12>=G12,"順調","遅延")))) | K12: =COUNTIFS(明細!$I$5:$I$76,A12) | L12: =COUNTIFS(明細!$J$5:$J$76,A12) | M12: =IF(K12=0,0,L12/K12) | N12: =SUM($K$6:K12) | O12: =SUM($L$6:L12) | P12: =IF(N12=0,"",O12/N12) | Q12: =IF(A12>$S$2,"予定",IF(N12=0,"－",IF(P12>=1,"完了",IF(O12>=N12,"順調","遅延")))) | R12: =D12+K12 | S12: =E12+L12
A13: 46082 | B13: =CHOOSE(WEEKDAY(A13,2),"月","火","水","木","金","土","日") | C13: =IF(OR(WEEKDAY(A13,2)>=6,COUNTIF(祝日マスタ!$A:$A,A13)>0),"非営業日","営業日") | D13: =COUNTIFS(明細!$F$5:$F$76,A13) | E13: =COUNTIFS(明細!$G$5:$G$76,A13) | F13: =IF(D13=0,0,E13/D13) | G13: =SUM($D$6:D13) | H13: =SUM($E$6:E13) | I13: =IF(G13=0,"",H13/G13) | J13: =IF(A13>$S$2,"予定",IF(G13=0,"－",IF(I13>=1,"完了",IF(H13>=G13,"順調","遅延")))) | K13: =COUNTIFS(明細!$I$5:$I$76,A13) | L13: =COUNTIFS(明細!$J$5:$J$76,A13) | M13: =IF(K13=0,0,L13/K13) | N13: =SUM($K$6:K13) | O13: =SUM($L$6:L13) | P13: =IF(N13=0,"",O13/N13) | Q13: =IF(A13>$S$2,"予定",IF(N13=0,"－",IF(P13>=1,"完了",IF(O13>=N13,"順調","遅延")))) | R13: =D13+K13 | S13: =E13+L13
A14: 46083 | B14: =CHOOSE(WEEKDAY(A14,2),"月","火","水","木","金","土","日") | C14: =IF(OR(WEEKDAY(A14,2)>=6,COUNTIF(祝日マスタ!$A:$A,A14)>0),"非営業日","営業日") | D14: =COUNTIFS(明細!$F$5:$F$76,A14) | E14: =COUNTIFS(明細!$G$5:$G$76,A14) | F14: =IF(D14=0,0,E14/D14) | G14: =SUM($D$6:D14) | H14: =SUM($E$6:E14) | I14: =IF(G14=0,"",H14/G14) | J14: =IF(A14>$S$2,"予定",IF(G14=0,"－",IF(I14>=1,"完了",IF(H14>=G14,"順調","遅延")))) | K14: =COUNTIFS(明細!$I$5:$I$76,A14) | L14: =COUNTIFS(明細!$J$5:$J$76,A14) | M14: =IF(K14=0,0,L14/K14) | N14: =SUM($K$6:K14) | O14: =SUM($L$6:L14) | P14: =IF(N14=0,"",O14/N14) | Q14: =IF(A14>$S$2,"予定",IF(N14=0,"－",IF(P14>=1,"完了",IF(O14>=N14,"順調","遅延")))) | R14: =D14+K14 | S14: =E14+L14
A15: 46084 | B15: =CHOOSE(WEEKDAY(A15,2),"月","火","水","木","金","土","日") | C15: =IF(OR(WEEKDAY(A15,2)>=6,COUNTIF(祝日マスタ!$A:$A,A15)>0),"非営業日","営業日") | D15: =COUNTIFS(明細!$F$5:$F$76,A15) | E15: =COUNTIFS(明細!$G$5:$G$76,A15) | F15: =IF(D15=0,0,E15/D15) | G15: =SUM($D$6:D15) | H15: =SUM($E$6:E15) | I15: =IF(G15=0,"",H15/G15) | J15: =IF(A15>$S$2,"予定",IF(G15=0,"－",IF(I15>=1,"完了",IF(H15>=G15,"順調","遅延")))) | K15: =COUNTIFS(明細!$I$5:$I$76,A15) | L15: =COUNTIFS(明細!$J$5:$J$76,A15) | M15: =IF(K15=0,0,L15/K15) | N15: =SUM($K$6:K15) | O15: =SUM($L$6:L15) | P15: =IF(N15=0,"",O15/N15) | Q15: =IF(A15>$S$2,"予定",IF(N15=0,"－",IF(P15>=1,"完了",IF(O15>=N15,"順調","遅延")))) | R15: =D15+K15 | S15: =E15+L15
A16: 46085 | B16: =CHOOSE(WEEKDAY(A16,2),"月","火","水","木","金","土","日") | C16: =IF(OR(WEEKDAY(A16,2)>=6,COUNTIF(祝日マスタ!$A:$A,A16)>0),"非営業日","営業日") | D16: =COUNTIFS(明細!$F$5:$F$76,A16) | E16: =COUNTIFS(明細!$G$5:$G$76,A16) | F16: =IF(D16=0,0,E16/D16) | G16: =SUM($D$6:D16) | H16: =SUM($E$6:E16) | I16: =IF(G16=0,"",H16/G16) | J16: =IF(A16>$S$2,"予定",IF(G16=0,"－",IF(I16>=1,"完了",IF(H16>=G16,"順調","遅延")))) | K16: =COUNTIFS(明細!$I$5:$I$76,A16) | L16: =COUNTIFS(明細!$J$5:$J$76,A16) | M16: =IF(K16=0,0,L16/K16) | N16: =SUM($K$6:K16) | O16: =SUM($L$6:L16) | P16: =IF(N16=0,"",O16/N16) | Q16: =IF(A16>$S$2,"予定",IF(N16=0,"－",IF(P16>=1,"完了",IF(O16>=N16,"順調","遅延")))) | R16: =D16+K16 | S16: =E16+L16
A17: 46086 | B17: =CHOOSE(WEEKDAY(A17,2),"月","火","水","木","金","土","日") | C17: =IF(OR(WEEKDAY(A17,2)>=6,COUNTIF(祝日マスタ!$A:$A,A17)>0),"非営業日","営業日") | D17: =COUNTIFS(明細!$F$5:$F$76,A17) | E17: =COUNTIFS(明細!$G$5:$G$76,A17) | F17: =IF(D17=0,0,E17/D17) | G17: =SUM($D$6:D17) | H17: =SUM($E$6:E17) | I17: =IF(G17=0,"",H17/G17) | J17: =IF(A17>$S$2,"予定",IF(G17=0,"－",IF(I17>=1,"完了",IF(H17>=G17,"順調","遅延")))) | K17: =COUNTIFS(明細!$I$5:$I$76,A17) | L17: =COUNTIFS(明細!$J$5:$J$76,A17) | M17: =IF(K17=0,0,L17/K17) | N17: =SUM($K$6:K17) | O17: =SUM($L$6:L17) | P17: =IF(N17=0,"",O17/N17) | Q17: =IF(A17>$S$2,"予定",IF(N17=0,"－",IF(P17>=1,"完了",IF(O17>=N17,"順調","遅延")))) | R17: =D17+K17 | S17: =E17+L17
... A30: 46099 | B30: =CHOOSE(WEEKDAY(A30,2),"月","火","水","木","金","土","日") | C30: =IF(OR(WEEKDAY(A30,2)>=6,COUNTIF(祝日マスタ!$A:$A,A30)>0),"非営業日","営業日") | D30: =COUNTIFS(明細!$F$5:$F$76,A30) | E30: =COUNTIFS(明細!$G$5:$G$76,A30) | F30: =IF(D30=0,0,E30/D30) | G30: =SUM($D$6:D30) | H30: =SUM($E$6:E30) | I30: =IF(G30=0,"",H30/G30) | J30: =IF(A30>$S$2,"予定",IF(G30=0,"－",IF(I30>=1,"完了",IF(H30>=G30,"順調","遅延")))) | K30: =COUNTIFS(明細!$I$5:$I$76,A30) | L30: =COUNTIFS(明細!$J$5:$J$76,A30) | M30: =IF(K30=0,0,L30/K30) | N30: =SUM($K$6:K30) | O30: =SUM($L$6:L30) | P30: =IF(N30=0,"",O30/N30) | Q30: =IF(A30>$S$2,"予定",IF(N30=0,"－",IF(P30>=1,"完了",IF(O30>=N30,"順調","遅延")))) | R30: =D30+K30 | S30: =E30+L30

Sheet 進捗サマリー_オンライン
A1: テスト進捗サマリー（オンライン）
A2: 集計期間: 2026/02/27 ～ 2026/03/16 (18日間) | R2: 基準日: | S2: =ダッシュボード!$B$2
A3: 共通 | D3: 実施 | K3: 検証 | R3: 合計
A4: 日付 | B4: 曜 | C4: 営業日 | D4: 予定 | E4: 実績 | F4: 消化率 | G4: 予定累計 | H4: 実績累計 | I4: 累計消化率 | J4: 判定 | K4: 予定 | L4: 実績 | M4: 消化率 | N4: 予定累計 | O4: 実績累計 | P4: 累計消化率 | Q4: 判定 | R4: 予定 | S4: 実績
A5: 合計 | D5: =SUM(D6:D23) | E5: =SUM(E6:E23) | F5: =IF(D5=0,0,E5/D5) | G5: =D5 | H5: =E5 | I5: =IF(G5=0,"",H5/G5) | J5: =IF(I5>=1,"完了",IF(H5>=G5,"順調","遅延")) | K5: =SUM(K6:K23) | L5: =SUM(L6:L23) | M5: =IF(K5=0,0,L5/K5) | N5: =K5 | O5: =L5 | P5: =IF(N5=0,"",O5/N5) | Q5: =IF(P5>=1,"完了",IF(O5>=N5,"順調","遅延")) | R5: =D5+K5 | S5: =E5+L5
A6: 46080 | B6: =CHOOSE(WEEKDAY(A6,2),"月","火","水","木","金","土","日") | C6: =IF(OR(WEEKDAY(A6,2)>=6,COUNTIF(祝日マスタ!$A:$A,A6)>0),"非営業日","営業日") | D6: =COUNTIFS(明細!$F$5:$F$76,A6,明細!$D$5:$D$76,"オンライン") | E6: =COUNTIFS(明細!$G$5:$G$76,A6,明細!$D$5:$D$76,"オンライン") | F6: =IF(D6=0,0,E6/D6) | G6: =SUM($D$6:D6) | H6: =SUM($E$6:E6) | I6: =IF(G6=0,"",H6/G6) | J6: =IF(A6>$S$2,"予定",IF(G6=0,"－",IF(I6>=1,"完了",IF(H6>=G6,"順調","遅延")))) | K6: =COUNTIFS(明細!$I$5:$I$76,A6,明細!$D$5:$D$76,"オンライン") | L6: =COUNTIFS(明細!$J$5:$J$76,A6,明細!$D$5:$D$76,"オンライン") | M6: =IF(K6=0,0,L6/K6) | N6: =SUM($K$6:K6) | O6: =SUM($L$6:L6) | P6: =IF(N6=0,"",O6/N6) | Q6: =IF(A6>$S$2,"予定",IF(N6=0,"－",IF(P6>=1,"完了",IF(O6>=N6,"順調","遅延")))) | R6: =D6+K6 | S6: =E6+L6
A7: 46081 | B7: =CHOOSE(WEEKDAY(A7,2),"月","火","水","木","金","土","日") | C7: =IF(OR(WEEKDAY(A7,2)>=6,COUNTIF(祝日マスタ!$A:$A,A7)>0),"非営業日","営業日") | D7: =COUNTIFS(明細!$F$5:$F$76,A7,明細!$D$5:$D$76,"オンライン") | E7: =COUNTIFS(明細!$G$5:$G$76,A7,明細!$D$5:$D$76,"オンライン") | F7: =IF(D7=0,0,E7/D7) | G7: =SUM($D$6:D7) | H7: =SUM($E$6:E7) | I7: =IF(G7=0,"",H7/G7) | J7: =IF(A7>$S$2,"予定",IF(G7=0,"－",IF(I7>=1,"完了",IF(H7>=G7,"順調","遅延")))) | K7: =COUNTIFS(明細!$I$5:$I$76,A7,明細!$D$5:$D$76,"オンライン") | L7: =COUNTIFS(明細!$J$5:$J$76,A7,明細!$D$5:$D$76,"オンライン") | M7: =IF(K7=0,0,L7/K7) | N7: =SUM($K$6:K7) | O7: =SUM($L$6:L7) | P7: =IF(N7=0,"",O7/N7) | Q7: =IF(A7>$S$2,"予定",IF(N7=0,"－",IF(P7>=1,"完了",IF(O7>=N7,"順調","遅延")))) | R7: =D7+K7 | S7: =E7+L7
A8: 46082 | B8: =CHOOSE(WEEKDAY(A8,2),"月","火","水","木","金","土","日") | C8: =IF(OR(WEEKDAY(A8,2)>=6,COUNTIF(祝日マスタ!$A:$A,A8)>0),"非営業日","営業日") | D8: =COUNTIFS(明細!$F$5:$F$76,A8,明細!$D$5:$D$76,"オンライン") | E8: =COUNTIFS(明細!$G$5:$G$76,A8,明細!$D$5:$D$76,"オンライン") | F8: =IF(D8=0,0,E8/D8) | G8: =SUM($D$6:D8) | H8: =SUM($E$6:E8) | I8: =IF(G8=0,"",H8/G8) | J8: =IF(A8>$S$2,"予定",IF(G8=0,"－",IF(I8>=1,"完了",IF(H8>=G8,"順調","遅延")))) | K8: =COUNTIFS(明細!$I$5:$I$76,A8,明細!$D$5:$D$76,"オンライン") | L8: =COUNTIFS(明細!$J$5:$J$76,A8,明細!$D$5:$D$76,"オンライン") | M8: =IF(K8=0,0,L8/K8) | N8: =SUM($K$6:K8) | O8: =SUM($L$6:L8) | P8: =IF(N8=0,"",O8/N8) | Q8: =IF(A8>$S$2,"予定",IF(N8=0,"－",IF(P8>=1,"完了",IF(O8>=N8,"順調","遅延")))) | R8: =D8+K8 | S8: =E8+L8
A9: 46083 | B9: =CHOOSE(WEEKDAY(A9,2),"月","火","水","木","金","土","日") | C9: =IF(OR(WEEKDAY(A9,2)>=6,COUNTIF(祝日マスタ!$A:$A,A9)>0),"非営業日","営業日") | D9: =COUNTIFS(明細!$F$5:$F$76,A9,明細!$D$5:$D$76,"オンライン") | E9: =COUNTIFS(明細!$G$5:$G$76,A9,明細!$D$5:$D$76,"オンライン") | F9: =IF(D9=0,0,E9/D9) | G9: =SUM($D$6:D9) | H9: =SUM($E$6:E9) | I9: =IF(G9=0,"",H9/G9) | J9: =IF(A9>$S$2,"予定",IF(G9=0,"－",IF(I9>=1,"完了",IF(H9>=G9,"順調","遅延")))) | K9: =COUNTIFS(明細!$I$5:$I$76,A9,明細!$D$5:$D$76,"オンライン") | L9: =COUNTIFS(明細!$J$5:$J$76,A9,明細!$D$5:$D$76,"オンライン") | M9: =IF(K9=0,0,L9/K9) | N9: =SUM($K$6:K9) | O9: =SUM($L$6:L9) | P9: =IF(N9=0,"",O9/N9) | Q9: =IF(A9>$S$2,"予定",IF(N9=0,"－",IF(P9>=1,"完了",IF(O9>=N9,"順調","遅延")))) | R9: =D9+K9 | S9: =E9+L9
A10: 46084 | B10: =CHOOSE(WEEKDAY(A10,2),"月","火","水","木","金","土","日") | C10: =IF(OR(WEEKDAY(A10,2)>=6,COUNTIF(祝日マスタ!$A:$A,A10)>0),"非営業日","営業日") | D10: =COUNTIFS(明細!$F$5:$F$76,A10,明細!$D$5:$D$76,"オンライン") | E10: =COUNTIFS(明細!$G$5:$G$76,A10,明細!$D$5:$D$76,"オンライン") | F10: =IF(D10=0,0,E10/D10) | G10: =SUM($D$6:D10) | H10: =SUM($E$6:E10) | I10: =IF(G10=0,"",H10/G10) | J10: =IF(A10>$S$2,"予定",IF(G10=0,"－",IF(I10>=1,"完了",IF(H10>=G10,"順調","遅延")))) | K10: =COUNTIFS(明細!$I$5:$I$76,A10,明細!$D$5:$D$76,"オンライン") | L10: =COUNTIFS(明細!$J$5:$J$76,A10,明細!$D$5:$D$76,"オンライン") | M10: =IF(K10=0,0,L10/K10) | N10: =SUM($K$6:K10) | O10: =SUM($L$6:L10) | P10: =IF(N10=0,"",O10/N10) | Q10: =IF(A10>$S$2,"予定",IF(N10=0,"－",IF(P10>=1,"完了",IF(O10>=N10,"順調","遅延")))) | R10: =D10+K10 | S10: =E10+L10
A11: 46085 | B11: =CHOOSE(WEEKDAY(A11,2),"月","火","水","木","金","土","日") | C11: =IF(OR(WEEKDAY(A11,2)>=6,COUNTIF(祝日マスタ!$A:$A,A11)>0),"非営業日","営業日") | D11: =COUNTIFS(明細!$F$5:$F$76,A11,明細!$D$5:$D$76,"オンライン") | E11: =COUNTIFS(明細!$G$5:$G$76,A11,明細!$D$5:$D$76,"オンライン") | F11: =IF(D11=0,0,E11/D11) | G11: =SUM($D$6:D11) | H11: =SUM($E$6:E11) | I11: =IF(G11=0,"",H11/G11) | J11: =IF(A11>$S$2,"予定",IF(G11=0,"－",IF(I11>=1,"完了",IF(H11>=G11,"順調","遅延")))) | K11: =COUNTIFS(明細!$I$5:$I$76,A11,明細!$D$5:$D$76,"オンライン") | L11: =COUNTIFS(明細!$J$5:$J$76,A11,明細!$D$5:$D$76,"オンライン") | M11: =IF(K11=0,0,L11/K11) | N11: =SUM($K$6:K11) | O11: =SUM($L$6:L11) | P11: =IF(N11=0,"",O11/N11) | Q11: =IF(A11>$S$2,"予定",IF(N11=0,"－",IF(P11>=1,"完了",IF(O11>=N11,"順調","遅延")))) | R11: =D11+K11 | S11: =E11+L11
A12: 46086 | B12: =CHOOSE(WEEKDAY(A12,2),"月","火","水","木","金","土","日") | C12: =IF(OR(WEEKDAY(A12,2)>=6,COUNTIF(祝日マスタ!$A:$A,A12)>0),"非営業日","営業日") | D12: =COUNTIFS(明細!$F$5:$F$76,A12,明細!$D$5:$D$76,"オンライン") | E12: =COUNTIFS(明細!$G$5:$G$76,A12,明細!$D$5:$D$76,"オンライン") | F12: =IF(D12=0,0,E12/D12) | G12: =SUM($D$6:D12) | H12: =SUM($E$6:E12) | I12: =IF(G12=0,"",H12/G12) | J12: =IF(A12>$S$2,"予定",IF(G12=0,"－",IF(I12>=1,"完了",IF(H12>=G12,"順調","遅延")))) | K12: =COUNTIFS(明細!$I$5:$I$76,A12,明細!$D$5:$D$76,"オンライン") | L12: =COUNTIFS(明細!$J$5:$J$76,A12,明細!$D$5:$D$76,"オンライン") | M12: =IF(K12=0,0,L12/K12) | N12: =SUM($K$6:K12) | O12: =SUM($L$6:L12) | P12: =IF(N12=0,"",O12/N12) | Q12: =IF(A12>$S$2,"予定",IF(N12=0,"－",IF(P12>=1,"完了",IF(O12>=N12,"順調","遅延")))) | R12: =D12+K12 | S12: =E12+L12
A13: 46087 | B13: =CHOOSE(WEEKDAY(A13,2),"月","火","水","木","金","土","日") | C13: =IF(OR(WEEKDAY(A13,2)>=6,COUNTIF(祝日マスタ!$A:$A,A13)>0),"非営業日","営業日") | D13: =COUNTIFS(明細!$F$5:$F$76,A13,明細!$D$5:$D$76,"オンライン") | E13: =COUNTIFS(明細!$G$5:$G$76,A13,明細!$D$5:$D$76,"オンライン") | F13: =IF(D13=0,0,E13/D13) | G13: =SUM($D$6:D13) | H13: =SUM($E$6:E13) | I13: =IF(G13=0,"",H13/G13) | J13: =IF(A13>$S$2,"予定",IF(G13=0,"－",IF(I13>=1,"完了",IF(H13>=G13,"順調","遅延")))) | K13: =COUNTIFS(明細!$I$5:$I$76,A13,明細!$D$5:$D$76,"オンライン") | L13: =COUNTIFS(明細!$J$5:$J$76,A13,明細!$D$5:$D$76,"オンライン") | M13: =IF(K13=0,0,L13/K13) | N13: =SUM($K$6:K13) | O13: =SUM($L$6:L13) | P13: =IF(N13=0,"",O13/N13) | Q13: =IF(A13>$S$2,"予定",IF(N13=0,"－",IF(P13>=1,"完了",IF(O13>=N13,"順調","遅延")))) | R13: =D13+K13 | S13: =E13+L13
A14: 46088 | B14: =CHOOSE(WEEKDAY(A14,2),"月","火","水","木","金","土","日") | C14: =IF(OR(WEEKDAY(A14,2)>=6,COUNTIF(祝日マスタ!$A:$A,A14)>0),"非営業日","営業日") | D14: =COUNTIFS(明細!$F$5:$F$76,A14,明細!$D$5:$D$76,"オンライン") | E14: =COUNTIFS(明細!$G$5:$G$76,A14,明細!$D$5:$D$76,"オンライン") | F14: =IF(D14=0,0,E14/D14) | G14: =SUM($D$6:D14) | H14: =SUM($E$6:E14) | I14: =IF(G14=0,"",H14/G14) | J14: =IF(A14>$S$2,"予定",IF(G14=0,"－",IF(I14>=1,"完了",IF(H14>=G14,"順調","遅延")))) | K14: =COUNTIFS(明細!$I$5:$I$76,A14,明細!$D$5:$D$76,"オンライン") | L14: =COUNTIFS(明細!$J$5:$J$76,A14,明細!$D$5:$D$76,"オンライン") | M14: =IF(K14=0,0,L14/K14) | N14: =SUM($K$6:K14) | O14: =SUM($L$6:L14) | P14: =IF(N14=0,"",O14/N14) | Q14: =IF(A14>$S$2,"予定",IF(N14=0,"－",IF(P14>=1,"完了",IF(O14>=N14,"順調","遅延")))) | R14: =D14+K14 | S14: =E14+L14
A15: 46089 | B15: =CHOOSE(WEEKDAY(A15,2),"月","火","水","木","金","土","日") | C15: =IF(OR(WEEKDAY(A15,2)>=6,COUNTIF(祝日マスタ!$A:$A,A15)>0),"非営業日","営業日") | D15: =COUNTIFS(明細!$F$5:$F$76,A15,明細!$D$5:$D$76,"オンライン") | E15: =COUNTIFS(明細!$G$5:$G$76,A15,明細!$D$5:$D$76,"オンライン") | F15: =IF(D15=0,0,E15/D15) | G15: =SUM($D$6:D15) | H15: =SUM($E$6:E15) | I15: =IF(G15=0,"",H15/G15) | J15: =IF(A15>$S$2,"予定",IF(G15=0,"－",IF(I15>=1,"完了",IF(H15>=G15,"順調","遅延")))) | K15: =COUNTIFS(明細!$I$5:$I$76,A15,明細!$D$5:$D$76,"オンライン") | L15: =COUNTIFS(明細!$J$5:$J$76,A15,明細!$D$5:$D$76,"オンライン") | M15: =IF(K15=0,0,L15/K15) | N15: =SUM($K$6:K15) | O15: =SUM($L$6:L15) | P15: =IF(N15=0,"",O15/N15) | Q15: =IF(A15>$S$2,"予定",IF(N15=0,"－",IF(P15>=1,"完了",IF(O15>=N15,"順調","遅延")))) | R15: =D15+K15 | S15: =E15+L15
A16: 46090 | B16: =CHOOSE(WEEKDAY(A16,2),"月","火","水","木","金","土","日") | C16: =IF(OR(WEEKDAY(A16,2)>=6,COUNTIF(祝日マスタ!$A:$A,A16)>0),"非営業日","営業日") | D16: =COUNTIFS(明細!$F$5:$F$76,A16,明細!$D$5:$D$76,"オンライン") | E16: =COUNTIFS(明細!$G$5:$G$76,A16,明細!$D$5:$D$76,"オンライン") | F16: =IF(D16=0,0,E16/D16) | G16: =SUM($D$6:D16) | H16: =SUM($E$6:E16) | I16: =IF(G16=0,"",H16/G16) | J16: =IF(A16>$S$2,"予定",IF(G16=0,"－",IF(I16>=1,"完了",IF(H16>=G16,"順調","遅延")))) | K16: =COUNTIFS(明細!$I$5:$I$76,A16,明細!$D$5:$D$76,"オンライン") | L16: =COUNTIFS(明細!$J$5:$J$76,A16,明細!$D$5:$D$76,"オンライン") | M16: =IF(K16=0,0,L16/K16) | N16: =SUM($K$6:K16) | O16: =SUM($L$6:L16) | P16: =IF(N16=0,"",O16/N16) | Q16: =IF(A16>$S$2,"予定",IF(N16=0,"－",IF(P16>=1,"完了",IF(O16>=N16,"順調","遅延")))) | R16: =D16+K16 | S16: =E16+L16
A17: 46091 | B17: =CHOOSE(WEEKDAY(A17,2),"月","火","水","木","金","土","日") | C17: =IF(OR(WEEKDAY(A17,2)>=6,COUNTIF(祝日マスタ!$A:$A,A17)>0),"非営業日","営業日") | D17: =COUNTIFS(明細!$F$5:$F$76,A17,明細!$D$5:$D$76,"オンライン") | E17: =COUNTIFS(明細!$G$5:$G$76,A17,明細!$D$5:$D$76,"オンライン") | F17: =IF(D17=0,0,E17/D17) | G17: =SUM($D$6:D17) | H17: =SUM($E$6:E17) | I17: =IF(G17=0,"",H17/G17) | J17: =IF(A17>$S$2,"予定",IF(G17=0,"－",IF(I17>=1,"完了",IF(H17>=G17,"順調","遅延")))) | K17: =COUNTIFS(明細!$I$5:$I$76,A17,明細!$D$5:$D$76,"オンライン") | L17: =COUNTIFS(明細!$J$5:$J$76,A17,明細!$D$5:$D$76,"オンライン") | M17: =IF(K17=0,0,L17/K17) | N17: =SUM($K$6:K17) | O17: =SUM($L$6:L17) | P17: =IF(N17=0,"",O17/N17) | Q17: =IF(A17>$S$2,"予定",IF(N17=0,"－",IF(P17>=1,"完了",IF(O17>=N17,"順調","遅延")))) | R17: =D17+K17 | S17: =E17+L17
... A23: 46097 | B23: =CHOOSE(WEEKDAY(A23,2),"月","火","水","木","金","土","日") | C23: =IF(OR(WEEKDAY(A23,2)>=6,COUNTIF(祝日マスタ!$A:$A,A23)>0),"非営業日","営業日") | D23: =COUNTIFS(明細!$F$5:$F$76,A23,明細!$D$5:$D$76,"オンライン") | E23: =COUNTIFS(明細!$G$5:$G$76,A23,明細!$D$5:$D$76,"オンライン") | F23: =IF(D23=0,0,E23/D23) | G23: =SUM($D$6:D23) | H23: =SUM($E$6:E23) | I23: =IF(G23=0,"",H23/G23) | J23: =IF(A23>$S$2,"予定",IF(G23=0,"－",IF(I23>=1,"完了",IF(H23>=G23,"順調","遅延")))) | K23: =COUNTIFS(明細!$I$5:$I$76,A23,明細!$D$5:$D$76,"オンライン") | L23: =COUNTIFS(明細!$J$5:$J$76,A23,明細!$D$5:$D$76,"オンライン") | M23: =IF(K23=0,0,L23/K23) | N23: =SUM($K$6:K23) | O23: =SUM($L$6:L23) | P23: =IF(N23=0,"",O23/N23) | Q23: =IF(A23>$S$2,"予定",IF(N23=0,"－",IF(P23>=1,"完了",IF(O23>=N23,"順調","遅延")))) | R23: =D23+K23 | S23: =E23+L23

Sheet 進捗サマリー_バッチ
A1: テスト進捗サマリー（バッチ）
A2: 集計期間: 2026/02/22 ～ 2026/03/18 (25日間) | R2: 基準日: | S2: =ダッシュボード!$B$2
A3: 共通 | D3: 実施 | K3: 検証 | R3: 合計
A4: 日付 | B4: 曜 | C4: 営業日 | D4: 予定 | E4: 実績 | F4: 消化率 | G4: 予定累計 | H4: 実績累計 | I4: 累計消化率 | J4: 判定 | K4: 予定 | L4: 実績 | M4: 消化率 | N4: 予定累計 | O4: 実績累計 | P4: 累計消化率 | Q4: 判定 | R4: 予定 | S4: 実績
A5: 合計 | D5: =SUM(D6:D30) | E5: =SUM(E6:E30) | F5: =IF(D5=0,0,E5/D5) | G5: =D5 | H5: =E5 | I5: =IF(G5=0,"",H5/G5) | J5: =IF(I5>=1,"完了",IF(H5>=G5,"順調","遅延")) | K5: =SUM(K6:K30) | L5: =SUM(L6:L30) | M5: =IF(K5=0,0,L5/K5) | N5: =K5 | O5: =L5 | P5: =IF(N5=0,"",O5/N5) | Q5: =IF(P5>=1,"完了",IF(O5>=N5,"順調","遅延")) | R5: =D5+K5 | S5: =E5+L5
A6: 46075 | B6: =CHOOSE(WEEKDAY(A6,2),"月","火","水","木","金","土","日") | C6: =IF(OR(WEEKDAY(A6,2)>=6,COUNTIF(祝日マスタ!$A:$A,A6)>0),"非営業日","営業日") | D6: =COUNTIFS(明細!$F$5:$F$76,A6,明細!$D$5:$D$76,"バッチ") | E6: =COUNTIFS(明細!$G$5:$G$76,A6,明細!$D$5:$D$76,"バッチ") | F6: =IF(D6=0,0,E6/D6) | G6: =SUM($D$6:D6) | H6: =SUM($E$6:E6) | I6: =IF(G6=0,"",H6/G6) | J6: =IF(A6>$S$2,"予定",IF(G6=0,"－",IF(I6>=1,"完了",IF(H6>=G6,"順調","遅延")))) | K6: =COUNTIFS(明細!$I$5:$I$76,A6,明細!$D$5:$D$76,"バッチ") | L6: =COUNTIFS(明細!$J$5:$J$76,A6,明細!$D$5:$D$76,"バッチ") | M6: =IF(K6=0,0,L6/K6) | N6: =SUM($K$6:K6) | O6: =SUM($L$6:L6) | P6: =IF(N6=0,"",O6/N6) | Q6: =IF(A6>$S$2,"予定",IF(N6=0,"－",IF(P6>=1,"完了",IF(O6>=N6,"順調","遅延")))) | R6: =D6+K6 | S6: =E6+L6
A7: 46076 | B7: =CHOOSE(WEEKDAY(A7,2),"月","火","水","木","金","土","日") | C7: =IF(OR(WEEKDAY(A7,2)>=6,COUNTIF(祝日マスタ!$A:$A,A7)>0),"非営業日","営業日") | D7: =COUNTIFS(明細!$F$5:$F$76,A7,明細!$D$5:$D$76,"バッチ") | E7: =COUNTIFS(明細!$G$5:$G$76,A7,明細!$D$5:$D$76,"バッチ") | F7: =IF(D7=0,0,E7/D7) | G7: =SUM($D$6:D7) | H7: =SUM($E$6:E7) | I7: =IF(G7=0,"",H7/G7) | J7: =IF(A7>$S$2,"予定",IF(G7=0,"－",IF(I7>=1,"完了",IF(H7>=G7,"順調","遅延")))) | K7: =COUNTIFS(明細!$I$5:$I$76,A7,明細!$D$5:$D$76,"バッチ") | L7: =COUNTIFS(明細!$J$5:$J$76,A7,明細!$D$5:$D$76,"バッチ") | M7: =IF(K7=0,0,L7/K7) | N7: =SUM($K$6:K7) | O7: =SUM($L$6:L7) | P7: =IF(N7=0,"",O7/N7) | Q7: =IF(A7>$S$2,"予定",IF(N7=0,"－",IF(P7>=1,"完了",IF(O7>=N7,"順調","遅延")))) | R7: =D7+K7 | S7: =E7+L7
A8: 46077 | B8: =CHOOSE(WEEKDAY(A8,2),"月","火","水","木","金","土","日") | C8: =IF(OR(WEEKDAY(A8,2)>=6,COUNTIF(祝日マスタ!$A:$A,A8)>0),"非営業日","営業日") | D8: =COUNTIFS(明細!$F$5:$F$76,A8,明細!$D$5:$D$76,"バッチ") | E8: =COUNTIFS(明細!$G$5:$G$76,A8,明細!$D$5:$D$76,"バッチ") | F8: =IF(D8=0,0,E8/D8) | G8: =SUM($D$6:D8) | H8: =SUM($E$6:E8) | I8: =IF(G8=0,"",H8/G8) | J8: =IF(A8>$S$2,"予定",IF(G8=0,"－",IF(I8>=1,"完了",IF(H8>=G8,"順調","遅延")))) | K8: =COUNTIFS(明細!$I$5:$I$76,A8,明細!$D$5:$D$76,"バッチ") | L8: =COUNTIFS(明細!$J$5:$J$76,A8,明細!$D$5:$D$76,"バッチ") | M8: =IF(K8=0,0,L8/K8) | N8: =SUM($K$6:K8) | O8: =SUM($L$6:L8) | P8: =IF(N8=0,"",O8/N8) | Q8: =IF(A8>$S$2,"予定",IF(N8=0,"－",IF(P8>=1,"完了",IF(O8>=N8,"順調","遅延")))) | R8: =D8+K8 | S8: =E8+L8
A9: 46078 | B9: =CHOOSE(WEEKDAY(A9,2),"月","火","水","木","金","土","日") | C9: =IF(OR(WEEKDAY(A9,2)>=6,COUNTIF(祝日マスタ!$A:$A,A9)>0),"非営業日","営業日") | D9: =COUNTIFS(明細!$F$5:$F$76,A9,明細!$D$5:$D$76,"バッチ") | E9: =COUNTIFS(明細!$G$5:$G$76,A9,明細!$D$5:$D$76,"バッチ") | F9: =IF(D9=0,0,E9/D9) | G9: =SUM($D$6:D9) | H9: =SUM($E$6:E9) | I9: =IF(G9=0,"",H9/G9) | J9: =IF(A9>$S$2,"予定",IF(G9=0,"－",IF(I9>=1,"完了",IF(H9>=G9,"順調","遅延")))) | K9: =COUNTIFS(明細!$I$5:$I$76,A9,明細!$D$5:$D$76,"バッチ") | L9: =COUNTIFS(明細!$J$5:$J$76,A9,明細!$D$5:$D$76,"バッチ") | M9: =IF(K9=0,0,L9/K9) | N9: =SUM($K$6:K9) | O9: =SUM($L$6:L9) | P9: =IF(N9=0,"",O9/N9) | Q9: =IF(A9>$S$2,"予定",IF(N9=0,"－",IF(P9>=1,"完了",IF(O9>=N9,"順調","遅延")))) | R9: =D9+K9 | S9: =E9+L9
A10: 46079 | B10: =CHOOSE(WEEKDAY(A10,2),"月","火","水","木","金","土","日") | C10: =IF(OR(WEEKDAY(A10,2)>=6,COUNTIF(祝日マスタ!$A:$A,A10)>0),"非営業日","営業日") | D10: =COUNTIFS(明細!$F$5:$F$76,A10,明細!$D$5:$D$76,"バッチ") | E10: =COUNTIFS(明細!$G$5:$G$76,A10,明細!$D$5:$D$76,"バッチ") | F10: =IF(D10=0,0,E10/D10) | G10: =SUM($D$6:D10) | H10: =SUM($E$6:E10) | I10: =IF(G10=0,"",H10/G10) | J10: =IF(A10>$S$2,"予定",IF(G10=0,"－",IF(I10>=1,"完了",IF(H10>=G10,"順調","遅延")))) | K10: =COUNTIFS(明細!$I$5:$I$76,A10,明細!$D$5:$D$76,"バッチ") | L10: =COUNTIFS(明細!$J$5:$J$76,A10,明細!$D$5:$D$76,"バッチ") | M10: =IF(K10=0,0,L10/K10) | N10: =SUM($K$6:K10) | O10: =SUM($L$6:L10) | P10: =IF(N10=0,"",O10/N10) | Q10: =IF(A10>$S$2,"予定",IF(N10=0,"－",IF(P10>=1,"完了",IF(O10>=N10,"順調","遅延")))) | R10: =D10+K10 | S10: =E10+L10
A11: 46080 | B11: =CHOOSE(WEEKDAY(A11,2),"月","火","水","木","金","土","日") | C11: =IF(OR(WEEKDAY(A11,2)>=6,COUNTIF(祝日マスタ!$A:$A,A11)>0),"非営業日","営業日") | D11: =COUNTIFS(明細!$F$5:$F$76,A11,明細!$D$5:$D$76,"バッチ") | E11: =COUNTIFS(明細!$G$5:$G$76,A11,明細!$D$5:$D$76,"バッチ") | F11: =IF(D11=0,0,E11/D11) | G11: =SUM($D$6:D11) | H11: =SUM($E$6:E11) | I11: =IF(G11=0,"",H11/G11) | J11: =IF(A11>$S$2,"予定",IF(G11=0,"－",IF(I11>=1,"完了",IF(H11>=G11,"順調","遅延")))) | K11: =COUNTIFS(明細!$I$5:$I$76,A11,明細!$D$5:$D$76,"バッチ") | L11: =COUNTIFS(明細!$J$5:$J$76,A11,明細!$D$5:$D$76,"バッチ") | M11: =IF(K11=0,0,L11/K11) | N11: =SUM($K$6:K11) | O11: =SUM($L$6:L11) | P11: =IF(N11=0,"",O11/N11) | Q11: =IF(A11>$S$2,"予定",IF(N11=0,"－",IF(P11>=1,"完了",IF(O11>=N11,"順調","遅延")))) | R11: =D11+K11 | S11: =E11+L11
A12: 46081 | B12: =CHOOSE(WEEKDAY(A12,2),"月","火","水","木","金","土","日") | C12: =IF(OR(WEEKDAY(A12,2)>=6,COUNTIF(祝日マスタ!$A:$A,A12)>0),"非営業日","営業日") | D12: =COUNTIFS(明細!$F$5:$F$76,A12,明細!$D$5:$D$76,"バッチ") | E12: =COUNTIFS(明細!$G$5:$G$76,A12,明細!$D$5:$D$76,"バッチ") | F12: =IF(D12=0,0,E12/D12) | G12: =SUM($D$6:D12) | H12: =SUM($E$6:E12) | I12: =IF(G12=0,"",H12/G12) | J12: =IF(A12>$S$2,"予定",IF(G12=0,"－",IF(I12>=1,"完了",IF(H12>=G12,"順調","遅延")))) | K12: =COUNTIFS(明細!$I$5:$I$76,A12,明細!$D$5:$D$76,"バッチ") | L12: =COUNTIFS(明細!$J$5:$J$76,A12,明細!$D$5:$D$76,"バッチ") | M12: =IF(K12=0,0,L12/K12) | N12: =SUM($K$6:K12) | O12: =SUM($L$6:L12) | P12: =IF(N12=0,"",O12/N12) | Q12: =IF(A12>$S$2,"予定",IF(N12=0,"－",IF(P12>=1,"完了",IF(O12>=N12,"順調","遅延")))) | R12: =D12+K12 | S12: =E12+L12
A13: 46082 | B13: =CHOOSE(WEEKDAY(A13,2),"月","火","水","木","金","土","日") | C13: =IF(OR(WEEKDAY(A13,2)>=6,COUNTIF(祝日マスタ!$A:$A,A13)>0),"非営業日","営業日") | D13: =COUNTIFS(明細!$F$5:$F$76,A13,明細!$D$5:$D$76,"バッチ") | E13: =COUNTIFS(明細!$G$5:$G$76,A13,明細!$D$5:$D$76,"バッチ") | F13: =IF(D13=0,0,E13/D13) | G13: =SUM($D$6:D13) | H13: =SUM($E$6:E13) | I13: =IF(G13=0,"",H13/G13) | J13: =IF(A13>$S$2,"予定",IF(G13=0,"－",IF(I13>=1,"完了",IF(H13>=G13,"順調","遅延")))) | K13: =COUNTIFS(明細!$I$5:$I$76,A13,明細!$D$5:$D$76,"バッチ") | L13: =COUNTIFS(明細!$J$5:$J$76,A13,明細!$D$5:$D$76,"バッチ") | M13: =IF(K13=0,0,L13/K13) | N13: =SUM($K$6:K13) | O13: =SUM($L$6:L13) | P13: =IF(N13=0,"",O13/N13) | Q13: =IF(A13>$S$2,"予定",IF(N13=0,"－",IF(P13>=1,"完了",IF(O13>=N13,"順調","遅延")))) | R13: =D13+K13 | S13: =E13+L13
A14: 46083 | B14: =CHOOSE(WEEKDAY(A14,2),"月","火","水","木","金","土","日") | C14: =IF(OR(WEEKDAY(A14,2)>=6,COUNTIF(祝日マスタ!$A:$A,A14)>0),"非営業日","営業日") | D14: =COUNTIFS(明細!$F$5:$F$76,A14,明細!$D$5:$D$76,"バッチ") | E14: =COUNTIFS(明細!$G$5:$G$76,A14,明細!$D$5:$D$76,"バッチ") | F14: =IF(D14=0,0,E14/D14) | G14: =SUM($D$6:D14) | H14: =SUM($E$6:E14) | I14: =IF(G14=0,"",H14/G14) | J14: =IF(A14>$S$2,"予定",IF(G14=0,"－",IF(I14>=1,"完了",IF(H14>=G14,"順調","遅延")))) | K14: =COUNTIFS(明細!$I$5:$I$76,A14,明細!$D$5:$D$76,"バッチ") | L14: =COUNTIFS(明細!$J$5:$J$76,A14,明細!$D$5:$D$76,"バッチ") | M14: =IF(K14=0,0,L14/K14) | N14: =SUM($K$6:K14) | O14: =SUM($L$6:L14) | P14: =IF(N14=0,"",O14/N14) | Q14: =IF(A14>$S$2,"予定",IF(N14=0,"－",IF(P14>=1,"完了",IF(O14>=N14,"順調","遅延")))) | R14: =D14+K14 | S14: =E14+L14
A15: 46084 | B15: =CHOOSE(WEEKDAY(A15,2),"月","火","水","木","金","土","日") | C15: =IF(OR(WEEKDAY(A15,2)>=6,COUNTIF(祝日マスタ!$A:$A,A15)>0),"非営業日","営業日") | D15: =COUNTIFS(明細!$F$5:$F$76,A15,明細!$D$5:$D$76,"バッチ") | E15: =COUNTIFS(明細!$G$5:$G$76,A15,明細!$D$5:$D$76,"バッチ") | F15: =IF(D15=0,0,E15/D15) | G15: =SUM($D$6:D15) | H15: =SUM($E$6:E15) | I15: =IF(G15=0,"",H15/G15) | J15: =IF(A15>$S$2,"予定",IF(G15=0,"－",IF(I15>=1,"完了",IF(H15>=G15,"順調","遅延")))) | K15: =COUNTIFS(明細!$I$5:$I$76,A15,明細!$D$5:$D$76,"バッチ") | L15: =COUNTIFS(明細!$J$5:$J$76,A15,明細!$D$5:$D$76,"バッチ") | M15: =IF(K15=0,0,L15/K15) | N15: =SUM($K$6:K15) | O15: =SUM($L$6:L15) | P15: =IF(N15=0,"",O15/N15) | Q15: =IF(A15>$S$2,"予定",IF(N15=0,"－",IF(P15>=1,"完了",IF(O15>=N15,"順調","遅延")))) | R15: =D15+K15 | S15: =E15+L15
A16: 46085 | B16: =CHOOSE(WEEKDAY(A16,2),"月","火","水","木","金","土","日") | C16: =IF(OR(WEEKDAY(A16,2)>=6,COUNTIF(祝日マスタ!$A:$A,A16)>0),"非営業日","営業日") | D16: =COUNTIFS(明細!$F$5:$F$76,A16,明細!$D$5:$D$76,"バッチ") | E16: =COUNTIFS(明細!$G$5:$G$76,A16,明細!$D$5:$D$76,"バッチ") | F16: =IF(D16=0,0,E16/D16) | G16: =SUM($D$6:D16) | H16: =SUM($E$6:E16) | I16: =IF(G16=0,"",H16/G16) | J16: =IF(A16>$S$2,"予定",IF(G16=0,"－",IF(I16>=1,"完了",IF(H16>=G16,"順調","遅延")))) | K16: =COUNTIFS(明細!$I$5:$I$76,A16,明細!$D$5:$D$76,"バッチ") | L16: =COUNTIFS(明細!$J$5:$J$76,A16,明細!$D$5:$D$76,"バッチ") | M16: =IF(K16=0,0,L16/K16) | N16: =SUM($K$6:K16) | O16: =SUM($L$6:L16) | P16: =IF(N16=0,"",O16/N16) | Q16: =IF(A16>$S$2,"予定",IF(N16=0,"－",IF(P16>=1,"完了",IF(O16>=N16,"順調","遅延")))) | R16: =D16+K16 | S16: =E16+L16
A17: 46086 | B17: =CHOOSE(WEEKDAY(A17,2),"月","火","水","木","金","土","日") | C17: =IF(OR(WEEKDAY(A17,2)>=6,COUNTIF(祝日マスタ!$A:$A,A17)>0),"非営業日","営業日") | D17: =COUNTIFS(明細!$F$5:$F$76,A17,明細!$D$5:$D$76,"バッチ") | E17: =COUNTIFS(明細!$G$5:$G$76,A17,明細!$D$5:$D$76,"バッチ") | F17: =IF(D17=0,0,E17/D17) | G17: =SUM($D$6:D17) | H17: =SUM($E$6:E17) | I17: =IF(G17=0,"",H17/G17) | J17: =IF(A17>$S$2,"予定",IF(G17=0,"－",IF(I17>=1,"完了",IF(H17>=G17,"順調","遅延")))) | K17: =COUNTIFS(明細!$I$5:$I$76,A17,明細!$D$5:$D$76,"バッチ") | L17: =COUNTIFS(明細!$J$5:$J$76,A17,明細!$D$5:$D$76,"バッチ") | M17: =IF(K17=0,0,L17/K17) | N17: =SUM($K$6:K17) | O17: =SUM($L$6:L17) | P17: =IF(N17=0,"",O17/N17) | Q17: =IF(A17>$S$2,"予定",IF(N17=0,"－",IF(P17>=1,"完了",IF(O17>=N17,"順調","遅延")))) | R17: =D17+K17 | S17: =E17+L17
... A30: 46099 | B30: =CHOOSE(WEEKDAY(A30,2),"月","火","水","木","金","土","日") | C30: =IF(OR(WEEKDAY(A30,2)>=6,COUNTIF(祝日マスタ!$A:$A,A30)>0),"非営業日","営業日") | D30: =COUNTIFS(明細!$F$5:$F$76,A30,明細!$D$5:$D$76,"バッチ") | E30: =COUNTIFS(明細!$G$5:$G$76,A30,明細!$D$5:$D$76,"バッチ") | F30: =IF(D30=0,0,E30/D30) | G30: =SUM($D$6:D30) | H30: =SUM($E$6:E30) | I30: =IF(G30=0,"",H30/G30) | J30: =IF(A30>$S$2,"予定",IF(G30=0,"－",IF(I30>=1,"完了",IF(H30>=G30,"順調","遅延")))) | K30: =COUNTIFS(明細!$I$5:$I$76,A30,明細!$D$5:$D$76,"バッチ") | L30: =COUNTIFS(明細!$J$5:$J$76,A30,明細!$D$5:$D$76,"バッチ") | M30: =IF(K30=0,0,L30/K30) | N30: =SUM($K$6:K30) | O30: =SUM($L$6:L30) | P30: =IF(N30=0,"",O30/N30) | Q30: =IF(A30>$S$2,"予定",IF(N30=0,"－",IF(P30>=1,"完了",IF(O30>=N30,"順調","遅延")))) | R30: =D30+K30 | S30: =E30+L30

Sheet 進捗サマリー_基盤
A1: テスト進捗サマリー（基盤）
A2: 集計期間: 2026/02/23 ～ 2026/03/13 (19日間) | R2: 基準日: | S2: =ダッシュボード!$B$2
A3: 共通 | D3: 実施 | K3: 検証 | R3: 合計
A4: 日付 | B4: 曜 | C4: 営業日 | D4: 予定 | E4: 実績 | F4: 消化率 | G4: 予定累計 | H4: 実績累計 | I4: 累計消化率 | J4: 判定 | K4: 予定 | L4: 実績 | M4: 消化率 | N4: 予定累計 | O4: 実績累計 | P4: 累計消化率 | Q4: 判定 | R4: 予定 | S4: 実績
A5: 合計 | D5: =SUM(D6:D24) | E5: =SUM(E6:E24) | F5: =IF(D5=0,0,E5/D5) | G5: =D5 | H5: =E5 | I5: =IF(G5=0,"",H5/G5) | J5: =IF(I5>=1,"完了",IF(H5>=G5,"順調","遅延")) | K5: =SUM(K6:K24) | L5: =SUM(L6:L24) | M5: =IF(K5=0,0,L5/K5) | N5: =K5 | O5: =L5 | P5: =IF(N5=0,"",O5/N5) | Q5: =IF(P5>=1,"完了",IF(O5>=N5,"順調","遅延")) | R5: =D5+K5 | S5: =E5+L5
A6: 46076 | B6: =CHOOSE(WEEKDAY(A6,2),"月","火","水","木","金","土","日") | C6: =IF(OR(WEEKDAY(A6,2)>=6,COUNTIF(祝日マスタ!$A:$A,A6)>0),"非営業日","営業日") | D6: =COUNTIFS(明細!$F$5:$F$76,A6,明細!$D$5:$D$76,"基盤") | E6: =COUNTIFS(明細!$G$5:$G$76,A6,明細!$D$5:$D$76,"基盤") | F6: =IF(D6=0,0,E6/D6) | G6: =SUM($D$6:D6) | H6: =SUM($E$6:E6) | I6: =IF(G6=0,"",H6/G6) | J6: =IF(A6>$S$2,"予定",IF(G6=0,"－",IF(I6>=1,"完了",IF(H6>=G6,"順調","遅延")))) | K6: =COUNTIFS(明細!$I$5:$I$76,A6,明細!$D$5:$D$76,"基盤") | L6: =COUNTIFS(明細!$J$5:$J$76,A6,明細!$D$5:$D$76,"基盤") | M6: =IF(K6=0,0,L6/K6) | N6: =SUM($K$6:K6) | O6: =SUM($L$6:L6) | P6: =IF(N6=0,"",O6/N6) | Q6: =IF(A6>$S$2,"予定",IF(N6=0,"－",IF(P6>=1,"完了",IF(O6>=N6,"順調","遅延")))) | R6: =D6+K6 | S6: =E6+L6
A7: 46077 | B7: =CHOOSE(WEEKDAY(A7,2),"月","火","水","木","金","土","日") | C7: =IF(OR(WEEKDAY(A7,2)>=6,COUNTIF(祝日マスタ!$A:$A,A7)>0),"非営業日","営業日") | D7: =COUNTIFS(明細!$F$5:$F$76,A7,明細!$D$5:$D$76,"基盤") | E7: =COUNTIFS(明細!$G$5:$G$76,A7,明細!$D$5:$D$76,"基盤") | F7: =IF(D7=0,0,E7/D7) | G7: =SUM($D$6:D7) | H7: =SUM($E$6:E7) | I7: =IF(G7=0,"",H7/G7) | J7: =IF(A7>$S$2,"予定",IF(G7=0,"－",IF(I7>=1,"完了",IF(H7>=G7,"順調","遅延")))) | K7: =COUNTIFS(明細!$I$5:$I$76,A7,明細!$D$5:$D$76,"基盤") | L7: =COUNTIFS(明細!$J$5:$J$76,A7,明細!$D$5:$D$76,"基盤") | M7: =IF(K7=0,0,L7/K7) | N7: =SUM($K$6:K7) | O7: =SUM($L$6:L7) | P7: =IF(N7=0,"",O7/N7) | Q7: =IF(A7>$S$2,"予定",IF(N7=0,"－",IF(P7>=1,"完了",IF(O7>=N7,"順調","遅延")))) | R7: =D7+K7 | S7: =E7+L7
A8: 46078 | B8: =CHOOSE(WEEKDAY(A8,2),"月","火","水","木","金","土","日") | C8: =IF(OR(WEEKDAY(A8,2)>=6,COUNTIF(祝日マスタ!$A:$A,A8)>0),"非営業日","営業日") | D8: =COUNTIFS(明細!$F$5:$F$76,A8,明細!$D$5:$D$76,"基盤") | E8: =COUNTIFS(明細!$G$5:$G$76,A8,明細!$D$5:$D$76,"基盤") | F8: =IF(D8=0,0,E8/D8) | G8: =SUM($D$6:D8) | H8: =SUM($E$6:E8) | I8: =IF(G8=0,"",H8/G8) | J8: =IF(A8>$S$2,"予定",IF(G8=0,"－",IF(I8>=1,"完了",IF(H8>=G8,"順調","遅延")))) | K8: =COUNTIFS(明細!$I$5:$I$76,A8,明細!$D$5:$D$76,"基盤") | L8: =COUNTIFS(明細!$J$5:$J$76,A8,明細!$D$5:$D$76,"基盤") | M8: =IF(K8=0,0,L8/K8) | N8: =SUM($K$6:K8) | O8: =SUM($L$6:L8) | P8: =IF(N8=0,"",O8/N8) | Q8: =IF(A8>$S$2,"予定",IF(N8=0,"－",IF(P8>=1,"完了",IF(O8>=N8,"順調","遅延")))) | R8: =D8+K8 | S8: =E8+L8
A9: 46079 | B9: =CHOOSE(WEEKDAY(A9,2),"月","火","水","木","金","土","日") | C9: =IF(OR(WEEKDAY(A9,2)>=6,COUNTIF(祝日マスタ!$A:$A,A9)>0),"非営業日","営業日") | D9: =COUNTIFS(明細!$F$5:$F$76,A9,明細!$D$5:$D$76,"基盤") | E9: =COUNTIFS(明細!$G$5:$G$76,A9,明細!$D$5:$D$76,"基盤") | F9: =IF(D9=0,0,E9/D9) | G9: =SUM($D$6:D9) | H9: =SUM($E$6:E9) | I9: =IF(G9=0,"",H9/G9) | J9: =IF(A9>$S$2,"予定",IF(G9=0,"－",IF(I9>=1,"完了",IF(H9>=G9,"順調","遅延")))) | K9: =COUNTIFS(明細!$I$5:$I$76,A9,明細!$D$5:$D$76,"基盤") | L9: =COUNTIFS(明細!$J$5:$J$76,A9,明細!$D$5:$D$76,"基盤") | M9: =IF(K9=0,0,L9/K9) | N9: =SUM($K$6:K9) | O9: =SUM($L$6:L9) | P9: =IF(N9=0,"",O9/N9) | Q9: =IF(A9>$S$2,"予定",IF(N9=0,"－",IF(P9>=1,"完了",IF(O9>=N9,"順調","遅延")))) | R9: =D9+K9 | S9: =E9+L9
A10: 46080 | B10: =CHOOSE(WEEKDAY(A10,2),"月","火","水","木","金","土","日") | C10: =IF(OR(WEEKDAY(A10,2)>=6,COUNTIF(祝日マスタ!$A:$A,A10)>0),"非営業日","営業日") | D10: =COUNTIFS(明細!$F$5:$F$76,A10,明細!$D$5:$D$76,"基盤") | E10: =COUNTIFS(明細!$G$5:$G$76,A10,明細!$D$5:$D$76,"基盤") | F10: =IF(D10=0,0,E10/D10) | G10: =SUM($D$6:D10) | H10: =SUM($E$6:E10) | I10: =IF(G10=0,"",H10/G10) | J10: =IF(A10>$S$2,"予定",IF(G10=0,"－",IF(I10>=1,"完了",IF(H10>=G10,"順調","遅延")))) | K10: =COUNTIFS(明細!$I$5:$I$76,A10,明細!$D$5:$D$76,"基盤") | L10: =COUNTIFS(明細!$J$5:$J$76,A10,明細!$D$5:$D$76,"基盤") | M10: =IF(K10=0,0,L10/K10) | N10: =SUM($K$6:K10) | O10: =SUM($L$6:L10) | P10: =IF(N10=0,"",O10/N10) | Q10: =IF(A10>$S$2,"予定",IF(N10=0,"－",IF(P10>=1,"完了",IF(O10>=N10,"順調","遅延")))) | R10: =D10+K10 | S10: =E10+L10
A11: 46081 | B11: =CHOOSE(WEEKDAY(A11,2),"月","火","水","木","金","土","日") | C11: =IF(OR(WEEKDAY(A11,2)>=6,COUNTIF(祝日マスタ!$A:$A,A11)>0),"非営業日","営業日") | D11: =COUNTIFS(明細!$F$5:$F$76,A11,明細!$D$5:$D$76,"基盤") | E11: =COUNTIFS(明細!$G$5:$G$76,A11,明細!$D$5:$D$76,"基盤") | F11: =IF(D11=0,0,E11/D11) | G11: =SUM($D$6:D11) | H11: =SUM($E$6:E11) | I11: =IF(G11=0,"",H11/G11) | J11: =IF(A11>$S$2,"予定",IF(G11=0,"－",IF(I11>=1,"完了",IF(H11>=G11,"順調","遅延")))) | K11: =COUNTIFS(明細!$I$5:$I$76,A11,明細!$D$5:$D$76,"基盤") | L11: =COUNTIFS(明細!$J$5:$J$76,A11,明細!$D$5:$D$76,"基盤") | M11: =IF(K11=0,0,L11/K11) | N11: =SUM($K$6:K11) | O11: =SUM($L$6:L11) | P11: =IF(N11=0,"",O11/N11) | Q11: =IF(A11>$S$2,"予定",IF(N11=0,"－",IF(P11>=1,"完了",IF(O11>=N11,"順調","遅延")))) | R11: =D11+K11 | S11: =E11+L11
A12: 46082 | B12: =CHOOSE(WEEKDAY(A12,2),"月","火","水","木","金","土","日") | C12: =IF(OR(WEEKDAY(A12,2)>=6,COUNTIF(祝日マスタ!$A:$A,A12)>0),"非営業日","営業日") | D12: =COUNTIFS(明細!$F$5:$F$76,A12,明細!$D$5:$D$76,"基盤") | E12: =COUNTIFS(明細!$G$5:$G$76,A12,明細!$D$5:$D$76,"基盤") | F12: =IF(D12=0,0,E12/D12) | G12: =SUM($D$6:D12) | H12: =SUM($E$6:E12) | I12: =IF(G12=0,"",H12/G12) | J12: =IF(A12>$S$2,"予定",IF(G12=0,"－",IF(I12>=1,"完了",IF(H12>=G12,"順調","遅延")))) | K12: =COUNTIFS(明細!$I$5:$I$76,A12,明細!$D$5:$D$76,"基盤") | L12: =COUNTIFS(明細!$J$5:$J$76,A12,明細!$D$5:$D$76,"基盤") | M12: =IF(K12=0,0,L12/K12) | N12: =SUM($K$6:K12) | O12: =SUM($L$6:L12) | P12: =IF(N12=0,"",O12/N12) | Q12: =IF(A12>$S$2,"予定",IF(N12=0,"－",IF(P12>=1,"完了",IF(O12>=N12,"順調","遅延")))) | R12: =D12+K12 | S12: =E12+L12
A13: 46083 | B13: =CHOOSE(WEEKDAY(A13,2),"月","火","水","木","金","土","日") | C13: =IF(OR(WEEKDAY(A13,2)>=6,COUNTIF(祝日マスタ!$A:$A,A13)>0),"非営業日","営業日") | D13: =COUNTIFS(明細!$F$5:$F$76,A13,明細!$D$5:$D$76,"基盤") | E13: =COUNTIFS(明細!$G$5:$G$76,A13,明細!$D$5:$D$76,"基盤") | F13: =IF(D13=0,0,E13/D13) | G13: =SUM($D$6:D13) | H13: =SUM($E$6:E13) | I13: =IF(G13=0,"",H13/G13) | J13: =IF(A13>$S$2,"予定",IF(G13=0,"－",IF(I13>=1,"完了",IF(H13>=G13,"順調","遅延")))) | K13: =COUNTIFS(明細!$I$5:$I$76,A13,明細!$D$5:$D$76,"基盤") | L13: =COUNTIFS(明細!$J$5:$J$76,A13,明細!$D$5:$D$76,"基盤") | M13: =IF(K13=0,0,L13/K13) | N13: =SUM($K$6:K13) | O13: =SUM($L$6:L13) | P13: =IF(N13=0,"",O13/N13) | Q13: =IF(A13>$S$2,"予定",IF(N13=0,"－",IF(P13>=1,"完了",IF(O13>=N13,"順調","遅延")))) | R13: =D13+K13 | S13: =E13+L13
A14: 46084 | B14: =CHOOSE(WEEKDAY(A14,2),"月","火","水","木","金","土","日") | C14: =IF(OR(WEEKDAY(A14,2)>=6,COUNTIF(祝日マスタ!$A:$A,A14)>0),"非営業日","営業日") | D14: =COUNTIFS(明細!$F$5:$F$76,A14,明細!$D$5:$D$76,"基盤") | E14: =COUNTIFS(明細!$G$5:$G$76,A14,明細!$D$5:$D$76,"基盤") | F14: =IF(D14=0,0,E14/D14) | G14: =SUM($D$6:D14) | H14: =SUM($E$6:E14) | I14: =IF(G14=0,"",H14/G14) | J14: =IF(A14>$S$2,"予定",IF(G14=0,"－",IF(I14>=1,"完了",IF(H14>=G14,"順調","遅延")))) | K14: =COUNTIFS(明細!$I$5:$I$76,A14,明細!$D$5:$D$76,"基盤") | L14: =COUNTIFS(明細!$J$5:$J$76,A14,明細!$D$5:$D$76,"基盤") | M14: =IF(K14=0,0,L14/K14) | N14: =SUM($K$6:K14) | O14: =SUM($L$6:L14) | P14: =IF(N14=0,"",O14/N14) | Q14: =IF(A14>$S$2,"予定",IF(N14=0,"－",IF(P14>=1,"完了",IF(O14>=N14,"順調","遅延")))) | R14: =D14+K14 | S14: =E14+L14
A15: 46085 | B15: =CHOOSE(WEEKDAY(A15,2),"月","火","水","木","金","土","日") | C15: =IF(OR(WEEKDAY(A15,2)>=6,COUNTIF(祝日マスタ!$A:$A,A15)>0),"非営業日","営業日") | D15: =COUNTIFS(明細!$F$5:$F$76,A15,明細!$D$5:$D$76,"基盤") | E15: =COUNTIFS(明細!$G$5:$G$76,A15,明細!$D$5:$D$76,"基盤") | F15: =IF(D15=0,0,E15/D15) | G15: =SUM($D$6:D15) | H15: =SUM($E$6:E15) | I15: =IF(G15=0,"",H15/G15) | J15: =IF(A15>$S$2,"予定",IF(G15=0,"－",IF(I15>=1,"完了",IF(H15>=G15,"順調","遅延")))) | K15: =COUNTIFS(明細!$I$5:$I$76,A15,明細!$D$5:$D$76,"基盤") | L15: =COUNTIFS(明細!$J$5:$J$76,A15,明細!$D$5:$D$76,"基盤") | M15: =IF(K15=0,0,L15/K15) | N15: =SUM($K$6:K15) | O15: =SUM($L$6:L15) | P15: =IF(N15=0,"",O15/N15) | Q15: =IF(A15>$S$2,"予定",IF(N15=0,"－",IF(P15>=1,"完了",IF(O15>=N15,"順調","遅延")))) | R15: =D15+K15 | S15: =E15+L15
A16: 46086 | B16: =CHOOSE(WEEKDAY(A16,2),"月","火","水","木","金","土","日") | C16: =IF(OR(WEEKDAY(A16,2)>=6,COUNTIF(祝日マスタ!$A:$A,A16)>0),"非営業日","営業日") | D16: =COUNTIFS(明細!$F$5:$F$76,A16,明細!$D$5:$D$76,"基盤") | E16: =COUNTIFS(明細!$G$5:$G$76,A16,明細!$D$5:$D$76,"基盤") | F16: =IF(D16=0,0,E16/D16) | G16: =SUM($D$6:D16) | H16: =SUM($E$6:E16) | I16: =IF(G16=0,"",H16/G16) | J16: =IF(A16>$S$2,"予定",IF(G16=0,"－",IF(I16>=1,"完了",IF(H16>=G16,"順調","遅延")))) | K16: =COUNTIFS(明細!$I$5:$I$76,A16,明細!$D$5:$D$76,"基盤") | L16: =COUNTIFS(明細!$J$5:$J$76,A16,明細!$D$5:$D$76,"基盤") | M16: =IF(K16=0,0,L16/K16) | N16: =SUM($K$6:K16) | O16: =SUM($L$6:L16) | P16: =IF(N16=0,"",O16/N16) | Q16: =IF(A16>$S$2,"予定",IF(N16=0,"－",IF(P16>=1,"完了",IF(O16>=N16,"順調","遅延")))) | R16: =D16+K16 | S16: =E16+L16
A17: 46087 | B17: =CHOOSE(WEEKDAY(A17,2),"月","火","水","木","金","土","日") | C17: =IF(OR(WEEKDAY(A17,2)>=6,COUNTIF(祝日マスタ!$A:$A,A17)>0),"非営業日","営業日") | D17: =COUNTIFS(明細!$F$5:$F$76,A17,明細!$D$5:$D$76,"基盤") | E17: =COUNTIFS(明細!$G$5:$G$76,A17,明細!$D$5:$D$76,"基盤") | F17: =IF(D17=0,0,E17/D17) | G17: =SUM($D$6:D17) | H17: =SUM($E$6:E17) | I17: =IF(G17=0,"",H17/G17) | J17: =IF(A17>$S$2,"予定",IF(G17=0,"－",IF(I17>=1,"完了",IF(H17>=G17,"順調","遅延")))) | K17: =COUNTIFS(明細!$I$5:$I$76,A17,明細!$D$5:$D$76,"基盤") | L17: =COUNTIFS(明細!$J$5:$J$76,A17,明細!$D$5:$D$76,"基盤") | M17: =IF(K17=0,0,L17/K17) | N17: =SUM($K$6:K17) | O17: =SUM($L$6:L17) | P17: =IF(N17=0,"",O17/N17) | Q17: =IF(A17>$S$2,"予定",IF(N17=0,"－",IF(P17>=1,"完了",IF(O17>=N17,"順調","遅延")))) | R17: =D17+K17 | S17: =E17+L17
... A24: 46094 | B24: =CHOOSE(WEEKDAY(A24,2),"月","火","水","木","金","土","日") | C24: =IF(OR(WEEKDAY(A24,2)>=6,COUNTIF(祝日マスタ!$A:$A,A24)>0),"非営業日","営業日") | D24: =COUNTIFS(明細!$F$5:$F$76,A24,明細!$D$5:$D$76,"基盤") | E24: =COUNTIFS(明細!$G$5:$G$76,A24,明細!$D$5:$D$76,"基盤") | F24: =IF(D24=0,0,E24/D24) | G24: =SUM($D$6:D24) | H24: =SUM($E$6:E24) | I24: =IF(G24=0,"",H24/G24) | J24: =IF(A24>$S$2,"予定",IF(G24=0,"－",IF(I24>=1,"完了",IF(H24>=G24,"順調","遅延")))) | K24: =COUNTIFS(明細!$I$5:$I$76,A24,明細!$D$5:$D$76,"基盤") | L24: =COUNTIFS(明細!$J$5:$J$76,A24,明細!$D$5:$D$76,"基盤") | M24: =IF(K24=0,0,L24/K24) | N24: =SUM($K$6:K24) | O24: =SUM($L$6:L24) | P24: =IF(N24=0,"",O24/N24) | Q24: =IF(A24>$S$2,"予定",IF(N24=0,"－",IF(P24>=1,"完了",IF(O24>=N24,"順調","遅延")))) | R24: =D24+K24 | S24: =E24+L24

Sheet 進捗サマリー_運用
A1: テスト進捗サマリー（運用）
A2: 集計期間: 2026/02/23 ～ 2026/03/14 (20日間) | R2: 基準日: | S2: =ダッシュボード!$B$2
A3: 共通 | D3: 実施 | K3: 検証 | R3: 合計
A4: 日付 | B4: 曜 | C4: 営業日 | D4: 予定 | E4: 実績 | F4: 消化率 | G4: 予定累計 | H4: 実績累計 | I4: 累計消化率 | J4: 判定 | K4: 予定 | L4: 実績 | M4: 消化率 | N4: 予定累計 | O4: 実績累計 | P4: 累計消化率 | Q4: 判定 | R4: 予定 | S4: 実績
A5: 合計 | D5: =SUM(D6:D25) | E5: =SUM(E6:E25) | F5: =IF(D5=0,0,E5/D5) | G5: =D5 | H5: =E5 | I5: =IF(G5=0,"",H5/G5) | J5: =IF(I5>=1,"完了",IF(H5>=G5,"順調","遅延")) | K5: =SUM(K6:K25) | L5: =SUM(L6:L25) | M5: =IF(K5=0,0,L5/K5) | N5: =K5 | O5: =L5 | P5: =IF(N5=0,"",O5/N5) | Q5: =IF(P5>=1,"完了",IF(O5>=N5,"順調","遅延")) | R5: =D5+K5 | S5: =E5+L5
A6: 46076 | B6: =CHOOSE(WEEKDAY(A6,2),"月","火","水","木","金","土","日") | C6: =IF(OR(WEEKDAY(A6,2)>=6,COUNTIF(祝日マスタ!$A:$A,A6)>0),"非営業日","営業日") | D6: =COUNTIFS(明細!$F$5:$F$76,A6,明細!$D$5:$D$76,"運用") | E6: =COUNTIFS(明細!$G$5:$G$76,A6,明細!$D$5:$D$76,"運用") | F6: =IF(D6=0,0,E6/D6) | G6: =SUM($D$6:D6) | H6: =SUM($E$6:E6) | I6: =IF(G6=0,"",H6/G6) | J6: =IF(A6>$S$2,"予定",IF(G6=0,"－",IF(I6>=1,"完了",IF(H6>=G6,"順調","遅延")))) | K6: =COUNTIFS(明細!$I$5:$I$76,A6,明細!$D$5:$D$76,"運用") | L6: =COUNTIFS(明細!$J$5:$J$76,A6,明細!$D$5:$D$76,"運用") | M6: =IF(K6=0,0,L6/K6) | N6: =SUM($K$6:K6) | O6: =SUM($L$6:L6) | P6: =IF(N6=0,"",O6/N6) | Q6: =IF(A6>$S$2,"予定",IF(N6=0,"－",IF(P6>=1,"完了",IF(O6>=N6,"順調","遅延")))) | R6: =D6+K6 | S6: =E6+L6
A7: 46077 | B7: =CHOOSE(WEEKDAY(A7,2),"月","火","水","木","金","土","日") | C7: =IF(OR(WEEKDAY(A7,2)>=6,COUNTIF(祝日マスタ!$A:$A,A7)>0),"非営業日","営業日") | D7: =COUNTIFS(明細!$F$5:$F$76,A7,明細!$D$5:$D$76,"運用") | E7: =COUNTIFS(明細!$G$5:$G$76,A7,明細!$D$5:$D$76,"運用") | F7: =IF(D7=0,0,E7/D7) | G7: =SUM($D$6:D7) | H7: =SUM($E$6:E7) | I7: =IF(G7=0,"",H7/G7) | J7: =IF(A7>$S$2,"予定",IF(G7=0,"－",IF(I7>=1,"完了",IF(H7>=G7,"順調","遅延")))) | K7: =COUNTIFS(明細!$I$5:$I$76,A7,明細!$D$5:$D$76,"運用") | L7: =COUNTIFS(明細!$J$5:$J$76,A7,明細!$D$5:$D$76,"運用") | M7: =IF(K7=0,0,L7/K7) | N7: =SUM($K$6:K7) | O7: =SUM($L$6:L7) | P7: =IF(N7=0,"",O7/N7) | Q7: =IF(A7>$S$2,"予定",IF(N7=0,"－",IF(P7>=1,"完了",IF(O7>=N7,"順調","遅延")))) | R7: =D7+K7 | S7: =E7+L7
A8: 46078 | B8: =CHOOSE(WEEKDAY(A8,2),"月","火","水","木","金","土","日") | C8: =IF(OR(WEEKDAY(A8,2)>=6,COUNTIF(祝日マスタ!$A:$A,A8)>0),"非営業日","営業日") | D8: =COUNTIFS(明細!$F$5:$F$76,A8,明細!$D$5:$D$76,"運用") | E8: =COUNTIFS(明細!$G$5:$G$76,A8,明細!$D$5:$D$76,"運用") | F8: =IF(D8=0,0,E8/D8) | G8: =SUM($D$6:D8) | H8: =SUM($E$6:E8) | I8: =IF(G8=0,"",H8/G8) | J8: =IF(A8>$S$2,"予定",IF(G8=0,"－",IF(I8>=1,"完了",IF(H8>=G8,"順調","遅延")))) | K8: =COUNTIFS(明細!$I$5:$I$76,A8,明細!$D$5:$D$76,"運用") | L8: =COUNTIFS(明細!$J$5:$J$76,A8,明細!$D$5:$D$76,"運用") | M8: =IF(K8=0,0,L8/K8) | N8: =SUM($K$6:K8) | O8: =SUM($L$6:L8) | P8: =IF(N8=0,"",O8/N8) | Q8: =IF(A8>$S$2,"予定",IF(N8=0,"－",IF(P8>=1,"完了",IF(O8>=N8,"順調","遅延")))) | R8: =D8+K8 | S8: =E8+L8
A9: 46079 | B9: =CHOOSE(WEEKDAY(A9,2),"月","火","水","木","金","土","日") | C9: =IF(OR(WEEKDAY(A9,2)>=6,COUNTIF(祝日マスタ!$A:$A,A9)>0),"非営業日","営業日") | D9: =COUNTIFS(明細!$F$5:$F$76,A9,明細!$D$5:$D$76,"運用") | E9: =COUNTIFS(明細!$G$5:$G$76,A9,明細!$D$5:$D$76,"運用") | F9: =IF(D9=0,0,E9/D9) | G9: =SUM($D$6:D9) | H9: =SUM($E$6:E9) | I9: =IF(G9=0,"",H9/G9) | J9: =IF(A9>$S$2,"予定",IF(G9=0,"－",IF(I9>=1,"完了",IF(H9>=G9,"順調","遅延")))) | K9: =COUNTIFS(明細!$I$5:$I$76,A9,明細!$D$5:$D$76,"運用") | L9: =COUNTIFS(明細!$J$5:$J$76,A9,明細!$D$5:$D$76,"運用") | M9: =IF(K9=0,0,L9/K9) | N9: =SUM($K$6:K9) | O9: =SUM($L$6:L9) | P9: =IF(N9=0,"",O9/N9) | Q9: =IF(A9>$S$2,"予定",IF(N9=0,"－",IF(P9>=1,"完了",IF(O9>=N9,"順調","遅延")))) | R9: =D9+K9 | S9: =E9+L9
A10: 46080 | B10: =CHOOSE(WEEKDAY(A10,2),"月","火","水","木","金","土","日") | C10: =IF(OR(WEEKDAY(A10,2)>=6,COUNTIF(祝日マスタ!$A:$A,A10)>0),"非営業日","営業日") | D10: =COUNTIFS(明細!$F$5:$F$76,A10,明細!$D$5:$D$76,"運用") | E10: =COUNTIFS(明細!$G$5:$G$76,A10,明細!$D$5:$D$76,"運用") | F10: =IF(D10=0,0,E10/D10) | G10: =SUM($D$6:D10) | H10: =SUM($E$6:E10) | I10: =IF(G10=0,"",H10/G10) | J10: =IF(A10>$S$2,"予定",IF(G10=0,"－",IF(I10>=1,"完了",IF(H10>=G10,"順調","遅延")))) | K10: =COUNTIFS(明細!$I$5:$I$76,A10,明細!$D$5:$D$76,"運用") | L10: =COUNTIFS(明細!$J$5:$J$76,A10,明細!$D$5:$D$76,"運用") | M10: =IF(K10=0,0,L10/K10) | N10: =SUM($K$6:K10) | O10: =SUM($L$6:L10) | P10: =IF(N10=0,"",O10/N10) | Q10: =IF(A10>$S$2,"予定",IF(N10=0,"－",IF(P10>=1,"完了",IF(O10>=N10,"順調","遅延")))) | R10: =D10+K10 | S10: =E10+L10
A11: 46081 | B11: =CHOOSE(WEEKDAY(A11,2),"月","火","水","木","金","土","日") | C11: =IF(OR(WEEKDAY(A11,2)>=6,COUNTIF(祝日マスタ!$A:$A,A11)>0),"非営業日","営業日") | D11: =COUNTIFS(明細!$F$5:$F$76,A11,明細!$D$5:$D$76,"運用") | E11: =COUNTIFS(明細!$G$5:$G$76,A11,明細!$D$5:$D$76,"運用") | F11: =IF(D11=0,0,E11/D11) | G11: =SUM($D$6:D11) | H11: =SUM($E$6:E11) | I11: =IF(G11=0,"",H11/G11) | J11: =IF(A11>$S$2,"予定",IF(G11=0,"－",IF(I11>=1,"完了",IF(H11>=G11,"順調","遅延")))) | K11: =COUNTIFS(明細!$I$5:$I$76,A11,明細!$D$5:$D$76,"運用") | L11: =COUNTIFS(明細!$J$5:$J$76,A11,明細!$D$5:$D$76,"運用") | M11: =IF(K11=0,0,L11/K11) | N11: =SUM($K$6:K11) | O11: =SUM($L$6:L11) | P11: =IF(N11=0,"",O11/N11) | Q11: =IF(A11>$S$2,"予定",IF(N11=0,"－",IF(P11>=1,"完了",IF(O11>=N11,"順調","遅延")))) | R11: =D11+K11 | S11: =E11+L11
A12: 46082 | B12: =CHOOSE(WEEKDAY(A12,2),"月","火","水","木","金","土","日") | C12: =IF(OR(WEEKDAY(A12,2)>=6,COUNTIF(祝日マスタ!$A:$A,A12)>0),"非営業日","営業日") | D12: =COUNTIFS(明細!$F$5:$F$76,A12,明細!$D$5:$D$76,"運用") | E12: =COUNTIFS(明細!$G$5:$G$76,A12,明細!$D$5:$D$76,"運用") | F12: =IF(D12=0,0,E12/D12) | G12: =SUM($D$6:D12) | H12: =SUM($E$6:E12) | I12: =IF(G12=0,"",H12/G12) | J12: =IF(A12>$S$2,"予定",IF(G12=0,"－",IF(I12>=1,"完了",IF(H12>=G12,"順調","遅延")))) | K12: =COUNTIFS(明細!$I$5:$I$76,A12,明細!$D$5:$D$76,"運用") | L12: =COUNTIFS(明細!$J$5:$J$76,A12,明細!$D$5:$D$76,"運用") | M12: =IF(K12=0,0,L12/K12) | N12: =SUM($K$6:K12) | O12: =SUM($L$6:L12) | P12: =IF(N12=0,"",O12/N12) | Q12: =IF(A12>$S$2,"予定",IF(N12=0,"－",IF(P12>=1,"完了",IF(O12>=N12,"順調","遅延")))) | R12: =D12+K12 | S12: =E12+L12
A13: 46083 | B13: =CHOOSE(WEEKDAY(A13,2),"月","火","水","木","金","土","日") | C13: =IF(OR(WEEKDAY(A13,2)>=6,COUNTIF(祝日マスタ!$A:$A,A13)>0),"非営業日","営業日") | D13: =COUNTIFS(明細!$F$5:$F$76,A13,明細!$D$5:$D$76,"運用") | E13: =COUNTIFS(明細!$G$5:$G$76,A13,明細!$D$5:$D$76,"運用") | F13: =IF(D13=0,0,E13/D13) | G13: =SUM($D$6:D13) | H13: =SUM($E$6:E13) | I13: =IF(G13=0,"",H13/G13) | J13: =IF(A13>$S$2,"予定",IF(G13=0,"－",IF(I13>=1,"完了",IF(H13>=G13,"順調","遅延")))) | K13: =COUNTIFS(明細!$I$5:$I$76,A13,明細!$D$5:$D$76,"運用") | L13: =COUNTIFS(明細!$J$5:$J$76,A13,明細!$D$5:$D$76,"運用") | M13: =IF(K13=0,0,L13/K13) | N13: =SUM($K$6:K13) | O13: =SUM($L$6:L13) | P13: =IF(N13=0,"",O13/N13) | Q13: =IF(A13>$S$2,"予定",IF(N13=0,"－",IF(P13>=1,"完了",IF(O13>=N13,"順調","遅延")))) | R13: =D13+K13 | S13: =E13+L13
A14: 46084 | B14: =CHOOSE(WEEKDAY(A14,2),"月","火","水","木","金","土","日") | C14: =IF(OR(WEEKDAY(A14,2)>=6,COUNTIF(祝日マスタ!$A:$A,A14)>0),"非営業日","営業日") | D14: =COUNTIFS(明細!$F$5:$F$76,A14,明細!$D$5:$D$76,"運用") | E14: =COUNTIFS(明細!$G$5:$G$76,A14,明細!$D$5:$D$76,"運用") | F14: =IF(D14=0,0,E14/D14) | G14: =SUM($D$6:D14) | H14: =SUM($E$6:E14) | I14: =IF(G14=0,"",H14/G14) | J14: =IF(A14>$S$2,"予定",IF(G14=0,"－",IF(I14>=1,"完了",IF(H14>=G14,"順調","遅延")))) | K14: =COUNTIFS(明細!$I$5:$I$76,A14,明細!$D$5:$D$76,"運用") | L14: =COUNTIFS(明細!$J$5:$J$76,A14,明細!$D$5:$D$76,"運用") | M14: =IF(K14=0,0,L14/K14) | N14: =SUM($K$6:K14) | O14: =SUM($L$6:L14) | P14: =IF(N14=0,"",O14/N14) | Q14: =IF(A14>$S$2,"予定",IF(N14=0,"－",IF(P14>=1,"完了",IF(O14>=N14,"順調","遅延")))) | R14: =D14+K14 | S14: =E14+L14
A15: 46085 | B15: =CHOOSE(WEEKDAY(A15,2),"月","火","水","木","金","土","日") | C15: =IF(OR(WEEKDAY(A15,2)>=6,COUNTIF(祝日マスタ!$A:$A,A15)>0),"非営業日","営業日") | D15: =COUNTIFS(明細!$F$5:$F$76,A15,明細!$D$5:$D$76,"運用") | E15: =COUNTIFS(明細!$G$5:$G$76,A15,明細!$D$5:$D$76,"運用") | F15: =IF(D15=0,0,E15/D15) | G15: =SUM($D$6:D15) | H15: =SUM($E$6:E15) | I15: =IF(G15=0,"",H15/G15) | J15: =IF(A15>$S$2,"予定",IF(G15=0,"－",IF(I15>=1,"完了",IF(H15>=G15,"順調","遅延")))) | K15: =COUNTIFS(明細!$I$5:$I$76,A15,明細!$D$5:$D$76,"運用") | L15: =COUNTIFS(明細!$J$5:$J$76,A15,明細!$D$5:$D$76,"運用") | M15: =IF(K15=0,0,L15/K15) | N15: =SUM($K$6:K15) | O15: =SUM($L$6:L15) | P15: =IF(N15=0,"",O15/N15) | Q15: =IF(A15>$S$2,"予定",IF(N15=0,"－",IF(P15>=1,"完了",IF(O15>=N15,"順調","遅延")))) | R15: =D15+K15 | S15: =E15+L15
A16: 46086 | B16: =CHOOSE(WEEKDAY(A16,2),"月","火","水","木","金","土","日") | C16: =IF(OR(WEEKDAY(A16,2)>=6,COUNTIF(祝日マスタ!$A:$A,A16)>0),"非営業日","営業日") | D16: =COUNTIFS(明細!$F$5:$F$76,A16,明細!$D$5:$D$76,"運用") | E16: =COUNTIFS(明細!$G$5:$G$76,A16,明細!$D$5:$D$76,"運用") | F16: =IF(D16=0,0,E16/D16) | G16: =SUM($D$6:D16) | H16: =SUM($E$6:E16) | I16: =IF(G16=0,"",H16/G16) | J16: =IF(A16>$S$2,"予定",IF(G16=0,"－",IF(I16>=1,"完了",IF(H16>=G16,"順調","遅延")))) | K16: =COUNTIFS(明細!$I$5:$I$76,A16,明細!$D$5:$D$76,"運用") | L16: =COUNTIFS(明細!$J$5:$J$76,A16,明細!$D$5:$D$76,"運用") | M16: =IF(K16=0,0,L16/K16) | N16: =SUM($K$6:K16) | O16: =SUM($L$6:L16) | P16: =IF(N16=0,"",O16/N16) | Q16: =IF(A16>$S$2,"予定",IF(N16=0,"－",IF(P16>=1,"完了",IF(O16>=N16,"順調","遅延")))) | R16: =D16+K16 | S16: =E16+L16
