Workbook

Sheet ダッシュボード
A1: テスト進捗ダッシュボード
A2: 基準日: | B2: 46091 | F2: 週範囲From: | G2: 2026/03/01 | H2: To: | I2: 2026/03/07
A4: ■ 実施進捗
A5: チーム | B5: 日次 | D5: 週次 | H5: 総計
B6: 予定 | C6: 実績 | D6: 予定 | E6: 実績 | F6: 残数 | G6: 遅延 | H6: 総数 | I6: 予定累計 | J6: 実績累計 | K6: 残数 | L6: 遅延 | M6: 予定消化率 | N6: 実績消化率 | O6: 乖離 | P6: 状態
A7: 全体 | B7: =IFERROR(INDEX('進捗サマリー_ALL'!D6:D191,MATCH($B$2,'進捗サマリー_ALL'!A6:A191,0)),0) | C7: =IFERROR(INDEX('進捗サマリー_ALL'!E6:E191,MATCH($B$2,'進捗サマリー_ALL'!A6:A191,0)),0) | D7: =IF(OR($G$2="",$I$2=""),"-",SUMIFS('進捗サマリー_ALL'!D6:D191,'進捗サマリー_ALL'!A6:A191,">="&$G$2,'進捗サマリー_ALL'!A6:A191,"<="&$I$2)) | E7: =IF(OR($G$2="",$I$2=""),"-",SUMIFS('進捗サマリー_ALL'!E6:E191,'進捗サマリー_ALL'!A6:A191,">="&$G$2,'進捗サマリー_ALL'!A6:A191,"<="&$I$2)) | F7: =IF(OR($G$2="",$I$2=""),"-",D7-E7) | G7: =IF(OR($G$2="",$I$2=""),"-",IF(F7>0,F7,0)) | H7: ='進捗サマリー_ALL'!D5 | I7: =IFERROR(INDEX('進捗サマリー_ALL'!G6:G191,MATCH($B$2,'進捗サマリー_ALL'!A6:A191,0)),0) | J7: =IFERROR(INDEX('進捗サマリー_ALL'!H6:H191,MATCH($B$2,'進捗サマリー_ALL'!A6:A191,0)),0) | K7: =H7-J7 | L7: =I7-J7 | M7: =IF(H7=0,0,I7/H7) | N7: =IF(H7=0,0,J7/H7) | O7: =N7-M7 | P7: =IF(J7>=H7,"完了",IF(L7>0,"遅延","順調"))
A8: その他 | B8: =IFERROR(INDEX('進捗サマリー_その他'!D6:D171,MATCH($B$2,'進捗サマリー_その他'!A6:A171,0)),0) | C8: =IFERROR(INDEX('進捗サマリー_その他'!E6:E171,MATCH($B$2,'進捗サマリー_その他'!A6:A171,0)),0) | D8: =IF(OR($G$2="",$I$2=""),"-",SUMIFS('進捗サマリー_その他'!D6:D171,'進捗サマリー_その他'!A6:A171,">="&$G$2,'進捗サマリー_その他'!A6:A171,"<="&$I$2)) | E8: =IF(OR($G$2="",$I$2=""),"-",SUMIFS('進捗サマリー_その他'!E6:E171,'進捗サマリー_その他'!A6:A171,">="&$G$2,'進捗サマリー_その他'!A6:A171,"<="&$I$2)) | F8: =IF(OR($G$2="",$I$2=""),"-",D8-E8) | G8: =IF(OR($G$2="",$I$2=""),"-",IF(F8>0,F8,0)) | H8: ='進捗サマリー_その他'!D5 | I8: =IFERROR(INDEX('進捗サマリー_その他'!G6:G171,MATCH($B$2,'進捗サマリー_その他'!A6:A171,0)),0) | J8: =IFERROR(INDEX('進捗サマリー_その他'!H6:H171,MATCH($B$2,'進捗サマリー_その他'!A6:A171,0)),0) | K8: =H8-J8 | L8: =I8-J8 | M8: =IF(H8=0,0,I8/H8) | N8: =IF(H8=0,0,J8/H8) | O8: =N8-M8 | P8: =IF(J8>=H8,"完了",IF(L8>0,"遅延","順調"))
A9: オンライン | B9: =IFERROR(INDEX('進捗サマリー_オンライン'!D6:D189,MATCH($B$2,'進捗サマリー_オンライン'!A6:A189,0)),0) | C9: =IFERROR(INDEX('進捗サマリー_オンライン'!E6:E189,MATCH($B$2,'進捗サマリー_オンライン'!A6:A189,0)),0) | D9: =IF(OR($G$2="",$I$2=""),"-",SUMIFS('進捗サマリー_オンライン'!D6:D189,'進捗サマリー_オンライン'!A6:A189,">="&$G$2,'進捗サマリー_オンライン'!A6:A189,"<="&$I$2)) | E9: =IF(OR($G$2="",$I$2=""),"-",SUMIFS('進捗サマリー_オンライン'!E6:E189,'進捗サマリー_オンライン'!A6:A189,">="&$G$2,'進捗サマリー_オンライン'!A6:A189,"<="&$I$2)) | F9: =IF(OR($G$2="",$I$2=""),"-",D9-E9) | G9: =IF(OR($G$2="",$I$2=""),"-",IF(F9>0,F9,0)) | H9: ='進捗サマリー_オンライン'!D5 | I9: =IFERROR(INDEX('進捗サマリー_オンライン'!G6:G189,MATCH($B$2,'進捗サマリー_オンライン'!A6:A189,0)),0) | J9: =IFERROR(INDEX('進捗サマリー_オンライン'!H6:H189,MATCH($B$2,'進捗サマリー_オンライン'!A6:A189,0)),0) | K9: =H9-J9 | L9: =I9-J9 | M9: =IF(H9=0,0,I9/H9) | N9: =IF(H9=0,0,J9/H9) | O9: =N9-M9 | P9: =IF(J9>=H9,"完了",IF(L9>0,"遅延","順調"))
A10: バッチ | B10: =IFERROR(INDEX('進捗サマリー_バッチ'!D6:D182,MATCH($B$2,'進捗サマリー_バッチ'!A6:A182,0)),0) | C10: =IFERROR(INDEX('進捗サマリー_バッチ'!E6:E182,MATCH($B$2,'進捗サマリー_バッチ'!A6:A182,0)),0) | D10: =IF(OR($G$2="",$I$2=""),"-",SUMIFS('進捗サマリー_バッチ'!D6:D182,'進捗サマリー_バッチ'!A6:A182,">="&$G$2,'進捗サマリー_バッチ'!A6:A182,"<="&$I$2)) | E10: =IF(OR($G$2="",$I$2=""),"-",SUMIFS('進捗サマリー_バッチ'!E6:E182,'進捗サマリー_バッチ'!A6:A182,">="&$G$2,'進捗サマリー_バッチ'!A6:A182,"<="&$I$2)) | F10: =IF(OR($G$2="",$I$2=""),"-",D10-E10) | G10: =IF(OR($G$2="",$I$2=""),"-",IF(F10>0,F10,0)) | H10: ='進捗サマリー_バッチ'!D5 | I10: =IFERROR(INDEX('進捗サマリー_バッチ'!G6:G182,MATCH($B$2,'進捗サマリー_バッチ'!A6:A182,0)),0) | J10: =IFERROR(INDEX('進捗サマリー_バッチ'!H6:H182,MATCH($B$2,'進捗サマリー_バッチ'!A6:A182,0)),0) | K10: =H10-J10 | L10: =I10-J10 | M10: =IF(H10=0,0,I10/H10) | N10: =IF(H10=0,0,J10/H10) | O10: =N10-M10 | P10: =IF(J10>=H10,"完了",IF(L10>0,"遅延","順調"))
A11: 基盤 | B11: =IFERROR(INDEX('進捗サマリー_基盤'!D6:D183,MATCH($B$2,'進捗サマリー_基盤'!A6:A183,0)),0) | C11: =IFERROR(INDEX('進捗サマリー_基盤'!E6:E183,MATCH($B$2,'進捗サマリー_基盤'!A6:A183,0)),0) | D11: =IF(OR($G$2="",$I$2=""),"-",SUMIFS('進捗サマリー_基盤'!D6:D183,'進捗サマリー_基盤'!A6:A183,">="&$G$2,'進捗サマリー_基盤'!A6:A183,"<="&$I$2)) | E11: =IF(OR($G$2="",$I$2=""),"-",SUMIFS('進捗サマリー_基盤'!E6:E183,'進捗サマリー_基盤'!A6:A183,">="&$G$2,'進捗サマリー_基盤'!A6:A183,"<="&$I$2)) | F11: =IF(OR($G$2="",$I$2=""),"-",D11-E11) | G11: =IF(OR($G$2="",$I$2=""),"-",IF(F11>0,F11,0)) | H11: ='進捗サマリー_基盤'!D5 | I11: =IFERROR(INDEX('進捗サマリー_基盤'!G6:G183,MATCH($B$2,'進捗サマリー_基盤'!A6:A183,0)),0) | J11: =IFERROR(INDEX('進捗サマリー_基盤'!H6:H183,MATCH($B$2,'進捗サマリー_基盤'!A6:A183,0)),0) | K11: =H11-J11 | L11: =I11-J11 | M11: =IF(H11=0,0,I11/H11) | N11: =IF(H11=0,0,J11/H11) | O11: =N11-M11 | P11: =IF(J11>=H11,"完了",IF(L11>0,"遅延","順調"))
A12: 運用 | B12: =IFERROR(INDEX('進捗サマリー_運用'!D6:D184,MATCH($B$2,'進捗サマリー_運用'!A6:A184,0)),0) | C12: =IFERROR(INDEX('進捗サマリー_運用'!E6:E184,MATCH($B$2,'進捗サマリー_運用'!A6:A184,0)),0) | D12: =IF(OR($G$2="",$I$2=""),"-",SUMIFS('進捗サマリー_運用'!D6:D184,'進捗サマリー_運用'!A6:A184,">="&$G$2,'進捗サマリー_運用'!A6:A184,"<="&$I$2)) | E12: =IF(OR($G$2="",$I$2=""),"-",SUMIFS('進捗サマリー_運用'!E6:E184,'進捗サマリー_運用'!A6:A184,">="&$G$2,'進捗サマリー_運用'!A6:A184,"<="&$I$2)) | F12: =IF(OR($G$2="",$I$2=""),"-",D12-E12) | G12: =IF(OR($G$2="",$I$2=""),"-",IF(F12>0,F12,0)) | H12: ='進捗サマリー_運用'!D5 | I12: =IFERROR(INDEX('進捗サマリー_運用'!G6:G184,MATCH($B$2,'進捗サマリー_運用'!A6:A184,0)),0) | J12: =IFERROR(INDEX('進捗サマリー_運用'!H6:H184,MATCH($B$2,'進捗サマリー_運用'!A6:A184,0)),0) | K12: =H12-J12 | L12: =I12-J12 | M12: =IF(H12=0,0,I12/H12) | N12: =IF(H12=0,0,J12/H12) | O12: =N12-M12 | P12: =IF(J12>=H12,"完了",IF(L12>0,"遅延","順調"))
A14: ■ 検証進捗
A15: チーム | B15: 日次 | D15: 週次 | H15: 総計
B16: 予定 | C16: 実績 | D16: 予定 | E16: 実績 | F16: 残数 | G16: 遅延 | H16: 総数 | I16: 予定累計 | J16: 実績累計 | K16: 残数 | L16: 遅延 | M16: 予定消化率 | N16: 実績消化率 | O16: 乖離 | P16: 状態
A17: 全体 | B17: =IFERROR(INDEX('進捗サマリー_ALL'!K6:K191,MATCH($B$2,'進捗サマリー_ALL'!A6:A191,0)),0) | C17: =IFERROR(INDEX('進捗サマリー_ALL'!L6:L191,MATCH($B$2,'進捗サマリー_ALL'!A6:A191,0)),0) | D17: =IF(OR($G$2="",$I$2=""),"-",SUMIFS('進捗サマリー_ALL'!K6:K191,'進捗サマリー_ALL'!A6:A191,">="&$G$2,'進捗サマリー_ALL'!A6:A191,"<="&$I$2)) | E17: =IF(OR($G$2="",$I$2=""),"-",SUMIFS('進捗サマリー_ALL'!L6:L191,'進捗サマリー_ALL'!A6:A191,">="&$G$2,'進捗サマリー_ALL'!A6:A191,"<="&$I$2)) | F17: =IF(OR($G$2="",$I$2=""),"-",D17-E17) | G17: =IF(OR($G$2="",$I$2=""),"-",IF(F17>0,F17,0)) | H17: ='進捗サマリー_ALL'!K5 | I17: =IFERROR(INDEX('進捗サマリー_ALL'!N6:N191,MATCH($B$2,'進捗サマリー_ALL'!A6:A191,0)),0) | J17: =IFERROR(INDEX('進捗サマリー_ALL'!O6:O191,MATCH($B$2,'進捗サマリー_ALL'!A6:A191,0)),0) | K17: =H17-J17 | L17: =I17-J17 | M17: =IF(H17=0,0,I17/H17) | N17: =IF(H17=0,0,J17/H17) | O17: =N17-M17 | P17: =IF(J17>=H17,"完了",IF(L17>0,"遅延","順調"))
A18: その他 | B18: =IFERROR(INDEX('進捗サマリー_その他'!K6:K171,MATCH($B$2,'進捗サマリー_その他'!A6:A171,0)),0) | C18: =IFERROR(INDEX('進捗サマリー_その他'!L6:L171,MATCH($B$2,'進捗サマリー_その他'!A6:A171,0)),0) | D18: =IF(OR($G$2="",$I$2=""),"-",SUMIFS('進捗サマリー_その他'!K6:K171,'進捗サマリー_その他'!A6:A171,">="&$G$2,'進捗サマリー_その他'!A6:A171,"<="&$I$2)) | E18: =IF(OR($G$2="",$I$2=""),"-",SUMIFS('進捗サマリー_その他'!L6:L171,'進捗サマリー_その他'!A6:A171,">="&$G$2,'進捗サマリー_その他'!A6:A171,"<="&$I$2)) | F18: =IF(OR($G$2="",$I$2=""),"-",D18-E18) | G18: =IF(OR($G$2="",$I$2=""),"-",IF(F18>0,F18,0)) | H18: ='進捗サマリー_その他'!K5 | I18: =IFERROR(INDEX('進捗サマリー_その他'!N6:N171,MATCH($B$2,'進捗サマリー_その他'!A6:A171,0)),0) | J18: =IFERROR(INDEX('進捗サマリー_その他'!O6:O171,MATCH($B$2,'進捗サマリー_その他'!A6:A171,0)),0) | K18: =H18-J18 | L18: =I18-J18 | M18: =IF(H18=0,0,I18/H18) | N18: =IF(H18=0,0,J18/H18) | O18: =N18-M18 | P18: =IF(J18>=H18,"完了",IF(L18>0,"遅延","順調"))
A19: オンライン | B19: =IFERROR(INDEX('進捗サマリー_オンライン'!K6:K189,MATCH($B$2,'進捗サマリー_オンライン'!A6:A189,0)),0) | C19: =IFERROR(INDEX('進捗サマリー_オンライン'!L6:L189,MATCH($B$2,'進捗サマリー_オンライン'!A6:A189,0)),0) | D19: =IF(OR($G$2="",$I$2=""),"-",SUMIFS('進捗サマリー_オンライン'!K6:K189,'進捗サマリー_オンライン'!A6:A189,">="&$G$2,'進捗サマリー_オンライン'!A6:A189,"<="&$I$2)) | E19: =IF(OR($G$2="",$I$2=""),"-",SUMIFS('進捗サマリー_オンライン'!L6:L189,'進捗サマリー_オンライン'!A6:A189,">="&$G$2,'進捗サマリー_オンライン'!A6:A189,"<="&$I$2)) | F19: =IF(OR($G$2="",$I$2=""),"-",D19-E19) | G19: =IF(OR($G$2="",$I$2=""),"-",IF(F19>0,F19,0)) | H19: ='進捗サマリー_オンライン'!K5 | I19: =IFERROR(INDEX('進捗サマリー_オンライン'!N6:N189,MATCH($B$2,'進捗サマリー_オンライン'!A6:A189,0)),0) | J19: =IFERROR(INDEX('進捗サマリー_オンライン'!O6:O189,MATCH($B$2,'進捗サマリー_オンライン'!A6:A189,0)),0) | K19: =H19-J19 | L19: =I19-J19 | M19: =IF(H19=0,0,I19/H19) | N19: =IF(H19=0,0,J19/H19) | O19: =N19-M19 | P19: =IF(J19>=H19,"完了",IF(L19>0,"遅延","順調"))
A20: バッチ | B20: =IFERROR(INDEX('進捗サマリー_バッチ'!K6:K182,MATCH($B$2,'進捗サマリー_バッチ'!A6:A182,0)),0) | C20: =IFERROR(INDEX('進捗サマリー_バッチ'!L6:L182,MATCH($B$2,'進捗サマリー_バッチ'!A6:A182,0)),0) | D20: =IF(OR($G$2="",$I$2=""),"-",SUMIFS('進捗サマリー_バッチ'!K6:K182,'進捗サマリー_バッチ'!A6:A182,">="&$G$2,'進捗サマリー_バッチ'!A6:A182,"<="&$I$2)) | E20: =IF(OR($G$2="",$I$2=""),"-",SUMIFS('進捗サマリー_バッチ'!L6:L182,'進捗サマリー_バッチ'!A6:A182,">="&$G$2,'進捗サマリー_バッチ'!A6:A182,"<="&$I$2)) | F20: =IF(OR($G$2="",$I$2=""),"-",D20-E20) | G20: =IF(OR($G$2="",$I$2=""),"-",IF(F20>0,F20,0)) | H20: ='進捗サマリー_バッチ'!K5 | I20: =IFERROR(INDEX('進捗サマリー_バッチ'!N6:N182,MATCH($B$2,'進捗サマリー_バッチ'!A6:A182,0)),0) | J20: =IFERROR(INDEX('進捗サマリー_バッチ'!O6:O182,MATCH($B$2,'進捗サマリー_バッチ'!A6:A182,0)),0) | K20: =H20-J20 | L20: =I20-J20 | M20: =IF(H20=0,0,I20/H20) | N20: =IF(H20=0,0,J20/H20) | O20: =N20-M20 | P20: =IF(J20>=H20,"完了",IF(L20>0,"遅延","順調"))
A21: 基盤 | B21: =IFERROR(INDEX('進捗サマリー_基盤'!K6:K183,MATCH($B$2,'進捗サマリー_基盤'!A6:A183,0)),0) | C21: =IFERROR(INDEX('進捗サマリー_基盤'!L6:L183,MATCH($B$2,'進捗サマリー_基盤'!A6:A183,0)),0) | D21: =IF(OR($G$2="",$I$2=""),"-",SUMIFS('進捗サマリー_基盤'!K6:K183,'進捗サマリー_基盤'!A6:A183,">="&$G$2,'進捗サマリー_基盤'!A6:A183,"<="&$I$2)) | E21: =IF(OR($G$2="",$I$2=""),"-",SUMIFS('進捗サマリー_基盤'!L6:L183,'進捗サマリー_基盤'!A6:A183,">="&$G$2,'進捗サマリー_基盤'!A6:A183,"<="&$I$2)) | F21: =IF(OR($G$2="",$I$2=""),"-",D21-E21) | G21: =IF(OR($G$2="",$I$2=""),"-",IF(F21>0,F21,0)) | H21: ='進捗サマリー_基盤'!K5 | I21: =IFERROR(INDEX('進捗サマリー_基盤'!N6:N183,MATCH($B$2,'進捗サマリー_基盤'!A6:A183,0)),0) | J21: =IFERROR(INDEX('進捗サマリー_基盤'!O6:O183,MATCH($B$2,'進捗サマリー_基盤'!A6:A183,0)),0) | K21: =H21-J21 | L21: =I21-J21 | M21: =IF(H21=0,0,I21/H21) | N21: =IF(H21=0,0,J21/H21) | O21: =N21-M21 | P21: =IF(J21>=H21,"完了",IF(L21>0,"遅延","順調"))
A22: 運用 | B22: =IFERROR(INDEX('進捗サマリー_運用'!K6:K184,MATCH($B$2,'進捗サマリー_運用'!A6:A184,0)),0) | C22: =IFERROR(INDEX('進捗サマリー_運用'!L6:L184,MATCH($B$2,'進捗サマリー_運用'!A6:A184,0)),0) | D22: =IF(OR($G$2="",$I$2=""),"-",SUMIFS('進捗サマリー_運用'!K6:K184,'進捗サマリー_運用'!A6:A184,">="&$G$2,'進捗サマリー_運用'!A6:A184,"<="&$I$2)) | E22: =IF(OR($G$2="",$I$2=""),"-",SUMIFS('進捗サマリー_運用'!L6:L184,'進捗サマリー_運用'!A6:A184,">="&$G$2,'進捗サマリー_運用'!A6:A184,"<="&$I$2)) | F22: =IF(OR($G$2="",$I$2=""),"-",D22-E22) | G22: =IF(OR($G$2="",$I$2=""),"-",IF(F22>0,F22,0)) | H22: ='進捗サマリー_運用'!K5 | I22: =IFERROR(INDEX('進捗サマリー_運用'!N6:N184,MATCH($B$2,'進捗サマリー_運用'!A6:A184,0)),0) | J22: =IFERROR(INDEX('進捗サマリー_運用'!O6:O184,MATCH($B$2,'進捗サマリー_運用'!A6:A184,0)),0) | K22: =H22-J22 | L22: =I22-J22 | M22: =IF(H22=0,0,I22/H22) | N22: =IF(H22=0,0,J22/H22) | O22: =N22-M22 | P22: =IF(J22>=H22,"完了",IF(L22>0,"遅延","順調"))
A24: ■ 進捗推移チャート（左: 実施 / 右: 検証） ※実施予定=青、検証予定=緑、実績=オレンジ

Sheet 欠陥ダッシュボード
A1: 欠陥ダッシュボード
A2: 基準日: 2026/03/10
A4: 1. 欠陥サマリー
A5: チーム | B5: 未完了 | C5: 予定超過 | H5: 滞留(7日超)
C6: 調査 | D6: 対応 | E6: 横展開 | F6: 検証 | G6: 合計 | H6: 調査 | I6: 対応 | J6: 横展開 | K6: 検証 | L6: 合計
A7: 全体 | B7: =COUNTBLANK('欠陥詳細_ALL'!V$4:V$75) | C7: =COUNTIFS('欠陥詳細_ALL'!I$4:I$75,"<"&DATE(2026,3,10),'欠陥詳細_ALL'!J$4:J$75,"") | D7: =COUNTIFS('欠陥詳細_ALL'!N$4:N$75,"<"&DATE(2026,3,10),'欠陥詳細_ALL'!O$4:O$75,"") | E7: =COUNTIFS('欠陥詳細_ALL'!P$4:P$75,"有",'欠陥詳細_ALL'!R$4:R$75,"<"&DATE(2026,3,10),'欠陥詳細_ALL'!S$4:S$75,"") | F7: =COUNTIFS('欠陥詳細_ALL'!T$4:T$75,"<"&DATE(2026,3,10),'欠陥詳細_ALL'!V$4:V$75,"") | G7: =SUM(C7:F7) | H7: =COUNTIFS('欠陥詳細_ALL'!I$4:I$75,"<"&DATE(2026,3,10)-7,'欠陥詳細_ALL'!J$4:J$75,"") | I7: =COUNTIFS('欠陥詳細_ALL'!N$4:N$75,"<"&DATE(2026,3,10)-7,'欠陥詳細_ALL'!O$4:O$75,"") | J7: =COUNTIFS('欠陥詳細_ALL'!P$4:P$75,"有",'欠陥詳細_ALL'!R$4:R$75,"<"&DATE(2026,3,10)-7,'欠陥詳細_ALL'!S$4:S$75,"") | K7: =COUNTIFS('欠陥詳細_ALL'!T$4:T$75,"<"&DATE(2026,3,10)-7,'欠陥詳細_ALL'!V$4:V$75,"") | L7: =SUM(H7:K7)
A8: オンライン | B8: =COUNTBLANK('欠陥詳細_オンライン'!V$4:V$29) | C8: =COUNTIFS('欠陥詳細_オンライン'!I$4:I$29,"<"&DATE(2026,3,10),'欠陥詳細_オンライン'!J$4:J$29,"") | D8: =COUNTIFS('欠陥詳細_オンライン'!N$4:N$29,"<"&DATE(2026,3,10),'欠陥詳細_オンライン'!O$4:O$29,"") | E8: =COUNTIFS('欠陥詳細_オンライン'!P$4:P$29,"有",'欠陥詳細_オンライン'!R$4:R$29,"<"&DATE(2026,3,10),'欠陥詳細_オンライン'!S$4:S$29,"") | F8: =COUNTIFS('欠陥詳細_オンライン'!T$4:T$29,"<"&DATE(2026,3,10),'欠陥詳細_オンライン'!V$4:V$29,"") | G8: =SUM(C8:F8) | H8: =COUNTIFS('欠陥詳細_オンライン'!I$4:I$29,"<"&DATE(2026,3,10)-7,'欠陥詳細_オンライン'!J$4:J$29,"") | I8: =COUNTIFS('欠陥詳細_オンライン'!N$4:N$29,"<"&DATE(2026,3,10)-7,'欠陥詳細_オンライン'!O$4:O$29,"") | J8: =COUNTIFS('欠陥詳細_オンライン'!P$4:P$29,"有",'欠陥詳細_オンライン'!R$4:R$29,"<"&DATE(2026,3,10)-7,'欠陥詳細_オンライン'!S$4:S$29,"") | K8: =COUNTIFS('欠陥詳細_オンライン'!T$4:T$29,"<"&DATE(2026,3,10)-7,'欠陥詳細_オンライン'!V$4:V$29,"") | L8: =SUM(H8:K8)
A9: バッチ | B9: =COUNTBLANK('欠陥詳細_バッチ'!V$4:V$20) | C9: =COUNTIFS('欠陥詳細_バッチ'!I$4:I$20,"<"&DATE(2026,3,10),'欠陥詳細_バッチ'!J$4:J$20,"") | D9: =COUNTIFS('欠陥詳細_バッチ'!N$4:N$20,"<"&DATE(2026,3,10),'欠陥詳細_バッチ'!O$4:O$20,"") | E9: =COUNTIFS('欠陥詳細_バッチ'!P$4:P$20,"有",'欠陥詳細_バッチ'!R$4:R$20,"<"&DATE(2026,3,10),'欠陥詳細_バッチ'!S$4:S$20,"") | F9: =COUNTIFS('欠陥詳細_バッチ'!T$4:T$20,"<"&DATE(2026,3,10),'欠陥詳細_バッチ'!V$4:V$20,"") | G9: =SUM(C9:F9) | H9: =COUNTIFS('欠陥詳細_バッチ'!I$4:I$20,"<"&DATE(2026,3,10)-7,'欠陥詳細_バッチ'!J$4:J$20,"") | I9: =COUNTIFS('欠陥詳細_バッチ'!N$4:N$20,"<"&DATE(2026,3,10)-7,'欠陥詳細_バッチ'!O$4:O$20,"") | J9: =COUNTIFS('欠陥詳細_バッチ'!P$4:P$20,"有",'欠陥詳細_バッチ'!R$4:R$20,"<"&DATE(2026,3,10)-7,'欠陥詳細_バッチ'!S$4:S$20,"") | K9: =COUNTIFS('欠陥詳細_バッチ'!T$4:T$20,"<"&DATE(2026,3,10)-7,'欠陥詳細_バッチ'!V$4:V$20,"") | L9: =SUM(H9:K9)
A10: 基盤 | B10: =COUNTBLANK('欠陥詳細_基盤'!V$4:V$16) | C10: =COUNTIFS('欠陥詳細_基盤'!I$4:I$16,"<"&DATE(2026,3,10),'欠陥詳細_基盤'!J$4:J$16,"") | D10: =COUNTIFS('欠陥詳細_基盤'!N$4:N$16,"<"&DATE(2026,3,10),'欠陥詳細_基盤'!O$4:O$16,"") | E10: =COUNTIFS('欠陥詳細_基盤'!P$4:P$16,"有",'欠陥詳細_基盤'!R$4:R$16,"<"&DATE(2026,3,10),'欠陥詳細_基盤'!S$4:S$16,"") | F10: =COUNTIFS('欠陥詳細_基盤'!T$4:T$16,"<"&DATE(2026,3,10),'欠陥詳細_基盤'!V$4:V$16,"") | G10: =SUM(C10:F10) | H10: =COUNTIFS('欠陥詳細_基盤'!I$4:I$16,"<"&DATE(2026,3,10)-7,'欠陥詳細_基盤'!J$4:J$16,"") | I10: =COUNTIFS('欠陥詳細_基盤'!N$4:N$16,"<"&DATE(2026,3,10)-7,'欠陥詳細_基盤'!O$4:O$16,"") | J10: =COUNTIFS('欠陥詳細_基盤'!P$4:P$16,"有",'欠陥詳細_基盤'!R$4:R$16,"<"&DATE(2026,3,10)-7,'欠陥詳細_基盤'!S$4:S$16,"") | K10: =COUNTIFS('欠陥詳細_基盤'!T$4:T$16,"<"&DATE(2026,3,10)-7,'欠陥詳細_基盤'!V$4:V$16,"") | L10: =SUM(H10:K10)
A11: 運用 | B11: =COUNTBLANK('欠陥詳細_運用'!V$4:V$19) | C11: =COUNTIFS('欠陥詳細_運用'!I$4:I$19,"<"&DATE(2026,3,10),'欠陥詳細_運用'!J$4:J$19,"") | D11: =COUNTIFS('欠陥詳細_運用'!N$4:N$19,"<"&DATE(2026,3,10),'欠陥詳細_運用'!O$4:O$19,"") | E11: =COUNTIFS('欠陥詳細_運用'!P$4:P$19,"有",'欠陥詳細_運用'!R$4:R$19,"<"&DATE(2026,3,10),'欠陥詳細_運用'!S$4:S$19,"") | F11: =COUNTIFS('欠陥詳細_運用'!T$4:T$19,"<"&DATE(2026,3,10),'欠陥詳細_運用'!V$4:V$19,"") | G11: =SUM(C11:F11) | H11: =COUNTIFS('欠陥詳細_運用'!I$4:I$19,"<"&DATE(2026,3,10)-7,'欠陥詳細_運用'!J$4:J$19,"") | I11: =COUNTIFS('欠陥詳細_運用'!N$4:N$19,"<"&DATE(2026,3,10)-7,'欠陥詳細_運用'!O$4:O$19,"") | J11: =COUNTIFS('欠陥詳細_運用'!P$4:P$19,"有",'欠陥詳細_運用'!R$4:R$19,"<"&DATE(2026,3,10)-7,'欠陥詳細_運用'!S$4:S$19,"") | K11: =COUNTIFS('欠陥詳細_運用'!T$4:T$19,"<"&DATE(2026,3,10)-7,'欠陥詳細_運用'!V$4:V$19,"") | L11: =SUM(H11:K11)
A14: 2. 対応状況別欠陥数
A15: チーム | B15: 対応状況 | H15: 合計 | I15: 検出状況
B16: 01:未着手 | C16: 02:調査中 | D16: 03:対応中 | E16: 04:検証中 | F16: 05:完了 | G16: 98:保留 | I16: 新規検出 | J16: 週検出 | K16: 累積検出
A17: 全体 | B17: =COUNTIFS('欠陥詳細_ALL'!C$4:C$75,"01:未着手") | C17: =COUNTIFS('欠陥詳細_ALL'!C$4:C$75,"02:調査中") | D17: =COUNTIFS('欠陥詳細_ALL'!C$4:C$75,"03:対応中") | E17: =COUNTIFS('欠陥詳細_ALL'!C$4:C$75,"04:検証中") | F17: =COUNTIFS('欠陥詳細_ALL'!C$4:C$75,"05:完了") | G17: =COUNTIFS('欠陥詳細_ALL'!C$4:C$75,"98:保留") | H17: =SUM(B17:G17) | I17: =COUNTIFS('欠陥詳細_ALL'!E$4:E$75,">="&WORKDAY('ダッシュボード'!$B$2,-1,'祝日マスタ'!$A$5:$A$500),'欠陥詳細_ALL'!E$4:E$75,"<="&'ダッシュボード'!$B$2) | J17: =COUNTIFS('欠陥詳細_ALL'!E$4:E$75,">="&'ダッシュボード'!$G$2,'欠陥詳細_ALL'!E$4:E$75,"<="&'ダッシュボード'!$I$2) | K17: =COUNTA('欠陥詳細_ALL'!C$4:C$75)
A18: オンライン | B18: =COUNTIFS('欠陥詳細_オンライン'!C$4:C$29,"01:未着手") | C18: =COUNTIFS('欠陥詳細_オンライン'!C$4:C$29,"02:調査中") | D18: =COUNTIFS('欠陥詳細_オンライン'!C$4:C$29,"03:対応中") | E18: =COUNTIFS('欠陥詳細_オンライン'!C$4:C$29,"04:検証中") | F18: =COUNTIFS('欠陥詳細_オンライン'!C$4:C$29,"05:完了") | G18: =COUNTIFS('欠陥詳細_オンライン'!C$4:C$29,"98:保留") | H18: =SUM(B18:G18) | I18: =COUNTIFS('欠陥詳細_オンライン'!E$4:E$29,">="&WORKDAY('ダッシュボード'!$B$2,-1,'祝日マスタ'!$A$5:$A$500),'欠陥詳細_オンライン'!E$4:E$29,"<="&'ダッシュボード'!$B$2) | J18: =COUNTIFS('欠陥詳細_オンライン'!E$4:E$29,">="&'ダッシュボード'!$G$2,'欠陥詳細_オンライン'!E$4:E$29,"<="&'ダッシュボード'!$I$2) | K18: =COUNTA('欠陥詳細_オンライン'!C$4:C$29)
A19: バッチ | B19: =COUNTIFS('欠陥詳細_バッチ'!C$4:C$20,"01:未着手") | C19: =COUNTIFS('欠陥詳細_バッチ'!C$4:C$20,"02:調査中") | D19: =COUNTIFS('欠陥詳細_バッチ'!C$4:C$20,"03:対応中") | E19: =COUNTIFS('欠陥詳細_バッチ'!C$4:C$20,"04:検証中") | F19: =COUNTIFS('欠陥詳細_バッチ'!C$4:C$20,"05:完了") | G19: =COUNTIFS('欠陥詳細_バッチ'!C$4:C$20,"98:保留") | H19: =SUM(B19:G19) | I19: =COUNTIFS('欠陥詳細_バッチ'!E$4:E$20,">="&WORKDAY('ダッシュボード'!$B$2,-1,'祝日マスタ'!$A$5:$A$500),'欠陥詳細_バッチ'!E$4:E$20,"<="&'ダッシュボード'!$B$2) | J19: =COUNTIFS('欠陥詳細_バッチ'!E$4:E$20,">="&'ダッシュボード'!$G$2,'欠陥詳細_バッチ'!E$4:E$20,"<="&'ダッシュボード'!$I$2) | K19: =COUNTA('欠陥詳細_バッチ'!C$4:C$20)
A20: 基盤 | B20: =COUNTIFS('欠陥詳細_基盤'!C$4:C$16,"01:未着手") | C20: =COUNTIFS('欠陥詳細_基盤'!C$4:C$16,"02:調査中") | D20: =COUNTIFS('欠陥詳細_基盤'!C$4:C$16,"03:対応中") | E20: =COUNTIFS('欠陥詳細_基盤'!C$4:C$16,"04:検証中") | F20: =COUNTIFS('欠陥詳細_基盤'!C$4:C$16,"05:完了") | G20: =COUNTIFS('欠陥詳細_基盤'!C$4:C$16,"98:保留") | H20: =SUM(B20:G20) | I20: =COUNTIFS('欠陥詳細_基盤'!E$4:E$16,">="&WORKDAY('ダッシュボード'!$B$2,-1,'祝日マスタ'!$A$5:$A$500),'欠陥詳細_基盤'!E$4:E$16,"<="&'ダッシュボード'!$B$2) | J20: =COUNTIFS('欠陥詳細_基盤'!E$4:E$16,">="&'ダッシュボード'!$G$2,'欠陥詳細_基盤'!E$4:E$16,"<="&'ダッシュボード'!$I$2) | K20: =COUNTA('欠陥詳細_基盤'!C$4:C$16)
A21: 運用 | B21: =COUNTIFS('欠陥詳細_運用'!C$4:C$19,"01:未着手") | C21: =COUNTIFS('欠陥詳細_運用'!C$4:C$19,"02:調査中") | D21: =COUNTIFS('欠陥詳細_運用'!C$4:C$19,"03:対応中") | E21: =COUNTIFS('欠陥詳細_運用'!C$4:C$19,"04:検証中") | F21: =COUNTIFS('欠陥詳細_運用'!C$4:C$19,"05:完了") | G21: =COUNTIFS('欠陥詳細_運用'!C$4:C$19,"98:保留") | H21: =SUM(B21:G21) | I21: =COUNTIFS('欠陥詳細_運用'!E$4:E$19,">="&WORKDAY('ダッシュボード'!$B$2,-1,'祝日マスタ'!$A$5:$A$500),'欠陥詳細_運用'!E$4:E$19,"<="&'ダッシュボード'!$B$2) | J21: =COUNTIFS('欠陥詳細_運用'!E$4:E$19,">="&'ダッシュボード'!$G$2,'欠陥詳細_運用'!E$4:E$19,"<="&'ダッシュボード'!$I$2) | K21: =COUNTA('欠陥詳細_運用'!C$4:C$19)
A24: 3. 緊急度別欠陥数
A25: チーム | B25: 緊急度 | E25: 合計
B26: 中 | C26: 低 | D26: 高
A27: 全体 | B27: =COUNTIFS('欠陥詳細_ALL'!G$4:G$75,"中") | C27: =COUNTIFS('欠陥詳細_ALL'!G$4:G$75,"低") | D27: =COUNTIFS('欠陥詳細_ALL'!G$4:G$75,"高") | E27: =SUM(B27:D27)
A28: オンライン | B28: =COUNTIFS('欠陥詳細_オンライン'!G$4:G$29,"中") | C28: =COUNTIFS('欠陥詳細_オンライン'!G$4:G$29,"低") | D28: =COUNTIFS('欠陥詳細_オンライン'!G$4:G$29,"高") | E28: =SUM(B28:D28)
A29: バッチ | B29: =COUNTIFS('欠陥詳細_バッチ'!G$4:G$20,"中") | C29: =COUNTIFS('欠陥詳細_バッチ'!G$4:G$20,"低") | D29: =COUNTIFS('欠陥詳細_バッチ'!G$4:G$20,"高") | E29: =SUM(B29:D29)
A30: 基盤 | B30: =COUNTIFS('欠陥詳細_基盤'!G$4:G$16,"中") | C30: =COUNTIFS('欠陥詳細_基盤'!G$4:G$16,"低") | D30: =COUNTIFS('欠陥詳細_基盤'!G$4:G$16,"高") | E30: =SUM(B30:D30)
A31: 運用 | B31: =COUNTIFS('欠陥詳細_運用'!G$4:G$19,"中") | C31: =COUNTIFS('欠陥詳細_運用'!G$4:G$19,"低") | D31: =COUNTIFS('欠陥詳細_運用'!G$4:G$19,"高") | E31: =SUM(B31:D31)
A34: 4. 業務機能分類
A35: 業務機能分類 | B35: チーム別件数
B36: 全体 | C36: オンライン | D36: バッチ | E36: 基盤 | F36: 運用
A37: 01_委託者登録 | B37: =COUNTIFS('欠陥詳細_ALL'!F$4:F$75,"01_委託者登録") | C37: =COUNTIFS('欠陥詳細_オンライン'!F$4:F$29,"01_委託者登録") | D37: =COUNTIFS('欠陥詳細_バッチ'!F$4:F$20,"01_委託者登録") | E37: =COUNTIFS('欠陥詳細_基盤'!F$4:F$16,"01_委託者登録") | F37: =COUNTIFS('欠陥詳細_運用'!F$4:F$19,"01_委託者登録")
A38: 02_受付 | B38: =COUNTIFS('欠陥詳細_ALL'!F$4:F$75,"02_受付") | C38: =COUNTIFS('欠陥詳細_オンライン'!F$4:F$29,"02_受付") | D38: =COUNTIFS('欠陥詳細_バッチ'!F$4:F$20,"02_受付") | E38: =COUNTIFS('欠陥詳細_基盤'!F$4:F$16,"02_受付") | F38: =COUNTIFS('欠陥詳細_運用'!F$4:F$19,"02_受付")
A39: 03_請求 | B39: =COUNTIFS('欠陥詳細_ALL'!F$4:F$75,"03_請求") | C39: =COUNTIFS('欠陥詳細_オンライン'!F$4:F$29,"03_請求") | D39: =COUNTIFS('欠陥詳細_バッチ'!F$4:F$20,"03_請求") | E39: =COUNTIFS('欠陥詳細_基盤'!F$4:F$16,"03_請求") | F39: =COUNTIFS('欠陥詳細_運用'!F$4:F$19,"03_請求")
A40: 04_欠陥・返戻 | B40: =COUNTIFS('欠陥詳細_ALL'!F$4:F$75,"04_欠陥・返戻") | C40: =COUNTIFS('欠陥詳細_オンライン'!F$4:F$29,"04_欠陥・返戻") | D40: =COUNTIFS('欠陥詳細_バッチ'!F$4:F$20,"04_欠陥・返戻") | E40: =COUNTIFS('欠陥詳細_基盤'!F$4:F$16,"04_欠陥・返戻") | F40: =COUNTIFS('欠陥詳細_運用'!F$4:F$19,"04_欠陥・返戻")
A41: 05_清算 | B41: =COUNTIFS('欠陥詳細_ALL'!F$4:F$75,"05_清算") | C41: =COUNTIFS('欠陥詳細_オンライン'!F$4:F$29,"05_清算") | D41: =COUNTIFS('欠陥詳細_バッチ'!F$4:F$20,"05_清算") | E41: =COUNTIFS('欠陥詳細_基盤'!F$4:F$16,"05_清算") | F41: =COUNTIFS('欠陥詳細_運用'!F$4:F$19,"05_清算")
A42: 06_受入準備 | B42: =COUNTIFS('欠陥詳細_ALL'!F$4:F$75,"06_受入準備") | C42: =COUNTIFS('欠陥詳細_オンライン'!F$4:F$29,"06_受入準備") | D42: =COUNTIFS('欠陥詳細_バッチ'!F$4:F$20,"06_受入準備") | E42: =COUNTIFS('欠陥詳細_基盤'!F$4:F$16,"06_受入準備") | F42: =COUNTIFS('欠陥詳細_運用'!F$4:F$19,"06_受入準備")
A43: 07_口振契約受付 | B43: =COUNTIFS('欠陥詳細_ALL'!F$4:F$75,"07_口振契約受付") | C43: =COUNTIFS('欠陥詳細_オンライン'!F$4:F$29,"07_口振契約受付") | D43: =COUNTIFS('欠陥詳細_バッチ'!F$4:F$20,"07_口振契約受付") | E43: =COUNTIFS('欠陥詳細_基盤'!F$4:F$16,"07_口振契約受付") | F43: =COUNTIFS('欠陥詳細_運用'!F$4:F$19,"07_口振契約受付")
A44: 08_事務支(変更通知) | B44: =COUNTIFS('欠陥詳細_ALL'!F$4:F$75,"08_事務支(変更通知)") | C44: =COUNTIFS('欠陥詳細_オンライン'!F$4:F$29,"08_事務支(変更通知)") | D44: =COUNTIFS('欠陥詳細_バッチ'!F$4:F$20,"08_事務支(変更通知)") | E44: =COUNTIFS('欠陥詳細_基盤'!F$4:F$16,"08_事務支(変更通知)") | F44: =COUNTIFS('欠陥詳細_運用'!F$4:F$19,"08_事務支(変更通知)")
A45: 09_事務支(その他) | B45: =COUNTIFS('欠陥詳細_ALL'!F$4:F$75,"09_事務支(その他)") | C45: =COUNTIFS('欠陥詳細_オンライン'!F$4:F$29,"09_事務支(その他)") | D45: =COUNTIFS('欠陥詳細_バッチ'!F$4:F$20,"09_事務支(その他)") | E45: =COUNTIFS('欠陥詳細_基盤'!F$4:F$16,"09_事務支(その他)") | F45: =COUNTIFS('欠陥詳細_運用'!F$4:F$19,"09_事務支(その他)")
A46: 10_共通 | B46: =COUNTIFS('欠陥詳細_ALL'!F$4:F$75,"10_共通") | C46: =COUNTIFS('欠陥詳細_オンライン'!F$4:F$29,"10_共通") | D46: =COUNTIFS('欠陥詳細_バッチ'!F$4:F$20,"10_共通") | E46: =COUNTIFS('欠陥詳細_基盤'!F$4:F$16,"10_共通") | F46: =COUNTIFS('欠陥詳細_運用'!F$4:F$19,"10_共通")
A47: 20_移行 | B47: =COUNTIFS('欠陥詳細_ALL'!F$4:F$75,"20_移行") | C47: =COUNTIFS('欠陥詳細_オンライン'!F$4:F$29,"20_移行") | D47: =COUNTIFS('欠陥詳細_バッチ'!F$4:F$20,"20_移行") | E47: =COUNTIFS('欠陥詳細_基盤'!F$4:F$16,"20_移行") | F47: =COUNTIFS('欠陥詳細_運用'!F$4:F$19,"20_移行")
...

Sheet 要対応一覧
A1: 要対応一覧（61件）
A2: 基準日: 2026/03/10
A4: ■ 遅延サマリー
A5: 項目 | B5: 遅延件数
A6: 実施者_遅延 | B6: =COUNTIF(明細!$H$5:$H$363,"遅延")
A7: 検証者_遅延 | B7: =COUNTIF(明細!$K$5:$K$363,"遅延")
A9: ■ 遅延一覧
A10: No. | B10: チーム名 | C10: シート名 | D10: テストID | E10: 実施予定 | F10: 実施実績 | G10: 検証予定 | H10: 検証実績
A11: 1 | B11: バッチ | C11: ITB-002_在庫更新 | D11: ITB-002_在庫更新-002 | E11: 2026/01/14 | F11: 2026/01/16 | G11: 2026/01/16 | H11: 未完了
A12: 2 | B12: バッチ | C12: ITB-002_在庫更新 | D12: ITB-002_在庫更新-003 | E12: 2026/02/10 | F12: 未完了 | G12: 2026/02/13 | H12: 未完了
A13: 3 | B13: バッチ | C13: ITB-002_在庫更新 | D13: ITB-002_在庫更新-004 | E13: 2026/03/04 | F13: 2026/03/06 | G13: 2026/03/06 | H13: 未完了
A14: 4 | B14: バッチ | C14: ITB-003_レポート生成 | D14: ITB-003_レポート生成-004 | E14: 2026/02/28 | F14: 2026/02/26 | G14: 2026/03/02 | H14: 未完了
A15: 5 | B15: バッチ | C15: ITB-001_月次締め | D15: ITB-001_月次締め-002 | E15: 2025/12/24 | F15: 2025/12/27 | G15: 2025/12/25 | H15: 未完了
A16: 6 | B16: バッチ | C16: ITB-001_月次締め | D16: ITB-001_月次締め-003 | E16: 2026/01/06 | F16: 2026/01/05 | G16: 2026/01/08 | H16: 未完了
A17: 7 | B17: バッチ | C17: ITB-001_月次締め | D17: ITB-001_月次締め-004 | E17: 2026/01/17 | F17: 2026/01/16 | G17: 2026/01/21 | H17: 未完了
A18: 8 | B18: バッチ | C18: ITB-001_月次締め | D18: ITB-001_月次締め-008 | E18: 2026/03/10 | F18: 未完了 | G18: 2026/03/14 | H18: 未完了
A19: 9 | B19: バッチ | C19: ITB-002_請求書発行 | D19: ITB-002_請求書発行-002 | E19: 2025/12/26 | F19: 2025/12/29 | G19: 2025/12/29 | H19: 未完了
A20: 10 | B20: バッチ | C20: ITB-002_請求書発行 | D20: ITB-002_請求書発行-008 | E20: 2026/03/10 | F20: 未完了 | G20: 2026/03/13 | H20: 未完了
A21: 11 | B21: バッチ | C21: ITB-001_外部システム連携 | D21: ITB-001_外部システム連携-003 | E21: 2026/01/20 | F21: 2026/01/20 | G21: 2026/01/24 | H21: 未完了
A22: 12 | B22: バッチ | C22: ITB-001_外部システム連携 | D22: ITB-001_外部システム連携-005 | E22: 2026/03/02 | F22: 2026/03/02 | G22: 2026/03/07 | H22: 未完了
... A71: 61 | B71: 基盤 | C71: ITB-003_監査ログ | D71: ITB-003_監査ログ-004 | E71: 2026/03/02 | F71: 2026/03/04 | G71: 2026/03/07 | H71: 未完了

Sheet 進捗サマリー_ALL
A1: テスト進捗サマリー（全体）
A2: 集計期間: 2025/12/07 ～ 2026/06/10 (186日間) | R2: 基準日: | S2: =ダッシュボード!$B$2
A3: 共通 | D3: 実施 | K3: 検証 | R3: 合計
A4: 日付 | B4: 曜 | C4: 営業日 | D4: 予定 | E4: 実績 | F4: 消化率 | G4: 予定累計 | H4: 実績累計 | I4: 累計消化率 | J4: 判定 | K4: 予定 | L4: 実績 | M4: 消化率 | N4: 予定累計 | O4: 実績累計 | P4: 累計消化率 | Q4: 判定 | R4: 予定 | S4: 実績
A5: 合計 | D5: =SUM(D6:D191) | E5: =SUM(E6:E191) | F5: =IF(D5=0,0,E5/D5) | G5: =D5 | H5: =E5 | I5: =IF(G5=0,"",H5/G5) | J5: =IF(I5>=1,"完了",IF(H5>=G5,"順調","遅延")) | K5: =SUM(K6:K191) | L5: =SUM(L6:L191) | M5: =IF(K5=0,0,L5/K5) | N5: =K5 | O5: =L5 | P5: =IF(N5=0,"",O5/N5) | Q5: =IF(P5>=1,"完了",IF(O5>=N5,"順調","遅延")) | R5: =D5+K5 | S5: =E5+L5
A6: 45998 | B6: =CHOOSE(WEEKDAY(A6,2),"月","火","水","木","金","土","日") | C6: =IF(OR(WEEKDAY(A6,2)>=6,COUNTIF(祝日マスタ!$A:$A,A6)>0),"非営業日","営業日") | D6: =COUNTIFS(明細!$F$5:$F$363,A6) | E6: =COUNTIFS(明細!$G$5:$G$363,A6) | F6: =IF(D6=0,0,E6/D6) | G6: =SUM($D$6:D6) | H6: =SUM($E$6:E6) | I6: =IF(G6=0,"",H6/G6) | J6: =IF(A6>$S$2,"予定",IF(G6=0,"－",IF(I6>=1,"完了",IF(H6>=G6,"順調","遅延")))) | K6: =COUNTIFS(明細!$I$5:$I$363,A6) | L6: =COUNTIFS(明細!$J$5:$J$363,A6) | M6: =IF(K6=0,0,L6/K6) | N6: =SUM($K$6:K6) | O6: =SUM($L$6:L6) | P6: =IF(N6=0,"",O6/N6) | Q6: =IF(A6>$S$2,"予定",IF(N6=0,"－",IF(P6>=1,"完了",IF(O6>=N6,"順調","遅延")))) | R6: =D6+K6 | S6: =E6+L6
A7: 45999 | B7: =CHOOSE(WEEKDAY(A7,2),"月","火","水","木","金","土","日") | C7: =IF(OR(WEEKDAY(A7,2)>=6,COUNTIF(祝日マスタ!$A:$A,A7)>0),"非営業日","営業日") | D7: =COUNTIFS(明細!$F$5:$F$363,A7) | E7: =COUNTIFS(明細!$G$5:$G$363,A7) | F7: =IF(D7=0,0,E7/D7) | G7: =SUM($D$6:D7) | H7: =SUM($E$6:E7) | I7: =IF(G7=0,"",H7/G7) | J7: =IF(A7>$S$2,"予定",IF(G7=0,"－",IF(I7>=1,"完了",IF(H7>=G7,"順調","遅延")))) | K7: =COUNTIFS(明細!$I$5:$I$363,A7) | L7: =COUNTIFS(明細!$J$5:$J$363,A7) | M7: =IF(K7=0,0,L7/K7) | N7: =SUM($K$6:K7) | O7: =SUM($L$6:L7) | P7: =IF(N7=0,"",O7/N7) | Q7: =IF(A7>$S$2,"予定",IF(N7=0,"－",IF(P7>=1,"完了",IF(O7>=N7,"順調","遅延")))) | R7: =D7+K7 | S7: =E7+L7
A8: 46000 | B8: =CHOOSE(WEEKDAY(A8,2),"月","火","水","木","金","土","日") | C8: =IF(OR(WEEKDAY(A8,2)>=6,COUNTIF(祝日マスタ!$A:$A,A8)>0),"非営業日","営業日") | D8: =COUNTIFS(明細!$F$5:$F$363,A8) | E8: =COUNTIFS(明細!$G$5:$G$363,A8) | F8: =IF(D8=0,0,E8/D8) | G8: =SUM($D$6:D8) | H8: =SUM($E$6:E8) | I8: =IF(G8=0,"",H8/G8) | J8: =IF(A8>$S$2,"予定",IF(G8=0,"－",IF(I8>=1,"完了",IF(H8>=G8,"順調","遅延")))) | K8: =COUNTIFS(明細!$I$5:$I$363,A8) | L8: =COUNTIFS(明細!$J$5:$J$363,A8) | M8: =IF(K8=0,0,L8/K8) | N8: =SUM($K$6:K8) | O8: =SUM($L$6:L8) | P8: =IF(N8=0,"",O8/N8) | Q8: =IF(A8>$S$2,"予定",IF(N8=0,"－",IF(P8>=1,"完了",IF(O8>=N8,"順調","遅延")))) | R8: =D8+K8 | S8: =E8+L8
A9: 46001 | B9: =CHOOSE(WEEKDAY(A9,2),"月","火","水","木","金","土","日") | C9: =IF(OR(WEEKDAY(A9,2)>=6,COUNTIF(祝日マスタ!$A:$A,A9)>0),"非営業日","営業日") | D9: =COUNTIFS(明細!$F$5:$F$363,A9) | E9: =COUNTIFS(明細!$G$5:$G$363,A9) | F9: =IF(D9=0,0,E9/D9) | G9: =SUM($D$6:D9) | H9: =SUM($E$6:E9) | I9: =IF(G9=0,"",H9/G9) | J9: =IF(A9>$S$2,"予定",IF(G9=0,"－",IF(I9>=1,"完了",IF(H9>=G9,"順調","遅延")))) | K9: =COUNTIFS(明細!$I$5:$I$363,A9) | L9: =COUNTIFS(明細!$J$5:$J$363,A9) | M9: =IF(K9=0,0,L9/K9) | N9: =SUM($K$6:K9) | O9: =SUM($L$6:L9) | P9: =IF(N9=0,"",O9/N9) | Q9: =IF(A9>$S$2,"予定",IF(N9=0,"－",IF(P9>=1,"完了",IF(O9>=N9,"順調","遅延")))) | R9: =D9+K9 | S9: =E9+L9
A10: 46002 | B10: =CHOOSE(WEEKDAY(A10,2),"月","火","水","木","金","土","日") | C10: =IF(OR(WEEKDAY(A10,2)>=6,COUNTIF(祝日マスタ!$A:$A,A10)>0),"非営業日","営業日") | D10: =COUNTIFS(明細!$F$5:$F$363,A10) | E10: =COUNTIFS(明細!$G$5:$G$363,A10) | F10: =IF(D10=0,0,E10/D10) | G10: =SUM($D$6:D10) | H10: =SUM($E$6:E10) | I10: =IF(G10=0,"",H10/G10) | J10: =IF(A10>$S$2,"予定",IF(G10=0,"－",IF(I10>=1,"完了",IF(H10>=G10,"順調","遅延")))) | K10: =COUNTIFS(明細!$I$5:$I$363,A10) | L10: =COUNTIFS(明細!$J$5:$J$363,A10) | M10: =IF(K10=0,0,L10/K10) | N10: =SUM($K$6:K10) | O10: =SUM($L$6:L10) | P10: =IF(N10=0,"",O10/N10) | Q10: =IF(A10>$S$2,"予定",IF(N10=0,"－",IF(P10>=1,"完了",IF(O10>=N10,"順調","遅延")))) | R10: =D10+K10 | S10: =E10+L10
A11: 46003 | B11: =CHOOSE(WEEKDAY(A11,2),"月","火","水","木","金","土","日") | C11: =IF(OR(WEEKDAY(A11,2)>=6,COUNTIF(祝日マスタ!$A:$A,A11)>0),"非営業日","営業日") | D11: =COUNTIFS(明細!$F$5:$F$363,A11) | E11: =COUNTIFS(明細!$G$5:$G$363,A11) | F11: =IF(D11=0,0,E11/D11) | G11: =SUM($D$6:D11) | H11: =SUM($E$6:E11) | I11: =IF(G11=0,"",H11/G11) | J11: =IF(A11>$S$2,"予定",IF(G11=0,"－",IF(I11>=1,"完了",IF(H11>=G11,"順調","遅延")))) | K11: =COUNTIFS(明細!$I$5:$I$363,A11) | L11: =COUNTIFS(明細!$J$5:$J$363,A11) | M11: =IF(K11=0,0,L11/K11) | N11: =SUM($K$6:K11) | O11: =SUM($L$6:L11) | P11: =IF(N11=0,"",O11/N11) | Q11: =IF(A11>$S$2,"予定",IF(N11=0,"－",IF(P11>=1,"完了",IF(O11>=N11,"順調","遅延")))) | R11: =D11+K11 | S11: =E11+L11
A12: 46004 | B12: =CHOOSE(WEEKDAY(A12,2),"月","火","水","木","金","土","日") | C12: =IF(OR(WEEKDAY(A12,2)>=6,COUNTIF(祝日マスタ!$A:$A,A12)>0),"非営業日","営業日") | D12: =COUNTIFS(明細!$F$5:$F$363,A12) | E12: =COUNTIFS(明細!$G$5:$G$363,A12) | F12: =IF(D12=0,0,E12/D12) | G12: =SUM($D$6:D12) | H12: =SUM($E$6:E12) | I12: =IF(G12=0,"",H12/G12) | J12: =IF(A12>$S$2,"予定",IF(G12=0,"－",IF(I12>=1,"完了",IF(H12>=G12,"順調","遅延")))) | K12: =COUNTIFS(明細!$I$5:$I$363,A12) | L12: =COUNTIFS(明細!$J$5:$J$363,A12) | M12: =IF(K12=0,0,L12/K12) | N12: =SUM($K$6:K12) | O12: =SUM($L$6:L12) | P12: =IF(N12=0,"",O12/N12) | Q12: =IF(A12>$S$2,"予定",IF(N12=0,"－",IF(P12>=1,"完了",IF(O12>=N12,"順調","遅延")))) | R12: =D12+K12 | S12: =E12+L12
A13: 46005 | B13: =CHOOSE(WEEKDAY(A13,2),"月","火","水","木","金","土","日") | C13: =IF(OR(WEEKDAY(A13,2)>=6,COUNTIF(祝日マスタ!$A:$A,A13)>0),"非営業日","営業日") | D13: =COUNTIFS(明細!$F$5:$F$363,A13) | E13: =COUNTIFS(明細!$G$5:$G$363,A13) | F13: =IF(D13=0,0,E13/D13) | G13: =SUM($D$6:D13) | H13: =SUM($E$6:E13) | I13: =IF(G13=0,"",H13/G13) | J13: =IF(A13>$S$2,"予定",IF(G13=0,"－",IF(I13>=1,"完了",IF(H13>=G13,"順調","遅延")))) | K13: =COUNTIFS(明細!$I$5:$I$363,A13) | L13: =COUNTIFS(明細!$J$5:$J$363,A13) | M13: =IF(K13=0,0,L13/K13) | N13: =SUM($K$6:K13) | O13: =SUM($L$6:L13) | P13: =IF(N13=0,"",O13/N13) | Q13: =IF(A13>$S$2,"予定",IF(N13=0,"－",IF(P13>=1,"完了",IF(O13>=N13,"順調","遅延")))) | R13: =D13+K13 | S13: =E13+L13
A14: 46006 | B14: =CHOOSE(WEEKDAY(A14,2),"月","火","水","木","金","土","日") | C14: =IF(OR(WEEKDAY(A14,2)>=6,COUNTIF(祝日マスタ!$A:$A,A14)>0),"非営業日","営業日") | D14: =COUNTIFS(明細!$F$5:$F$363,A14) | E14: =COUNTIFS(明細!$G$5:$G$363,A14) | F14: =IF(D14=0,0,E14/D14) | G14: =SUM($D$6:D14) | H14: =SUM($E$6:E14) | I14: =IF(G14=0,"",H14/G14) | J14: =IF(A14>$S$2,"予定",IF(G14=0,"－",IF(I14>=1,"完了",IF(H14>=G14,"順調","遅延")))) | K14: =COUNTIFS(明細!$I$5:$I$363,A14) | L14: =COUNTIFS(明細!$J$5:$J$363,A14) | M14: =IF(K14=0,0,L14/K14) | N14: =SUM($K$6:K14) | O14: =SUM($L$6:L14) | P14: =IF(N14=0,"",O14/N14) | Q14: =IF(A14>$S$2,"予定",IF(N14=0,"－",IF(P14>=1,"完了",IF(O14>=N14,"順調","遅延")))) | R14: =D14+K14 | S14: =E14+L14
A15: 46007 | B15: =CHOOSE(WEEKDAY(A15,2),"月","火","水","木","金","土","日") | C15: =IF(OR(WEEKDAY(A15,2)>=6,COUNTIF(祝日マスタ!$A:$A,A15)>0),"非営業日","営業日") | D15: =COUNTIFS(明細!$F$5:$F$363,A15) | E15: =COUNTIFS(明細!$G$5:$G$363,A15) | F15: =IF(D15=0,0,E15/D15) | G15: =SUM($D$6:D15) | H15: =SUM($E$6:E15) | I15: =IF(G15=0,"",H15/G15) | J15: =IF(A15>$S$2,"予定",IF(G15=0,"－",IF(I15>=1,"完了",IF(H15>=G15,"順調","遅延")))) | K15: =COUNTIFS(明細!$I$5:$I$363,A15) | L15: =COUNTIFS(明細!$J$5:$J$363,A15) | M15: =IF(K15=0,0,L15/K15) | N15: =SUM($K$6:K15) | O15: =SUM($L$6:L15) | P15: =IF(N15=0,"",O15/N15) | Q15: =IF(A15>$S$2,"予定",IF(N15=0,"－",IF(P15>=1,"完了",IF(O15>=N15,"順調","遅延")))) | R15: =D15+K15 | S15: =E15+L15
A16: 46008 | B16: =CHOOSE(WEEKDAY(A16,2),"月","火","水","木","金","土","日") | C16: =IF(OR(WEEKDAY(A16,2)>=6,COUNTIF(祝日マスタ!$A:$A,A16)>0),"非営業日","営業日") | D16: =COUNTIFS(明細!$F$5:$F$363,A16) | E16: =COUNTIFS(明細!$G$5:$G$363,A16) | F16: =IF(D16=0,0,E16/D16) | G16: =SUM($D$6:D16) | H16: =SUM($E$6:E16) | I16: =IF(G16=0,"",H16/G16) | J16: =IF(A16>$S$2,"予定",IF(G16=0,"－",IF(I16>=1,"完了",IF(H16>=G16,"順調","遅延")))) | K16: =COUNTIFS(明細!$I$5:$I$363,A16) | L16: =COUNTIFS(明細!$J$5:$J$363,A16) | M16: =IF(K16=0,0,L16/K16) | N16: =SUM($K$6:K16) | O16: =SUM($L$6:L16) | P16: =IF(N16=0,"",O16/N16) | Q16: =IF(A16>$S$2,"予定",IF(N16=0,"－",IF(P16>=1,"完了",IF(O16>=N16,"順調","遅延")))) | R16: =D16+K16 | S16: =E16+L16
A17: 46009 | B17: =CHOOSE(WEEKDAY(A17,2),"月","火","水","木","金","土","日") | C17: =IF(OR(WEEKDAY(A17,2)>=6,COUNTIF(祝日マスタ!$A:$A,A17)>0),"非営業日","営業日") | D17: =COUNTIFS(明細!$F$5:$F$363,A17) | E17: =COUNTIFS(明細!$G$5:$G$363,A17) | F17: =IF(D17=0,0,E17/D17) | G17: =SUM($D$6:D17) | H17: =SUM($E$6:E17) | I17: =IF(G17=0,"",H17/G17) | J17: =IF(A17>$S$2,"予定",IF(G17=0,"－",IF(I17>=1,"完了",IF(H17>=G17,"順調","遅延")))) | K17: =COUNTIFS(明細!$I$5:$I$363,A17) | L17: =COUNTIFS(明細!$J$5:$J$363,A17) | M17: =IF(K17=0,0,L17/K17) | N17: =SUM($K$6:K17) | O17: =SUM($L$6:L17) | P17: =IF(N17=0,"",O17/N17) | Q17: =IF(A17>$S$2,"予定",IF(N17=0,"－",IF(P17>=1,"完了",IF(O17>=N17,"順調","遅延")))) | R17: =D17+K17 | S17: =E17+L17
... A191: 46183 | B191: =CHOOSE(WEEKDAY(A191,2),"月","火","水","木","金","土","日") | C191: =IF(OR(WEEKDAY(A191,2)>=6,COUNTIF(祝日マスタ!$A:$A,A191)>0),"非営業日","営業日") | D191: =COUNTIFS(明細!$F$5:$F$363,A191) | E191: =COUNTIFS(明細!$G$5:$G$363,A191) | F191: =IF(D191=0,0,E191/D191) | G191: =SUM($D$6:D191) | H191: =SUM($E$6:E191) | I191: =IF(G191=0,"",H191/G191) | J191: =IF(A191>$S$2,"予定",IF(G191=0,"－",IF(I191>=1,"完了",IF(H191>=G191,"順調","遅延")))) | K191: =COUNTIFS(明細!$I$5:$I$363,A191) | L191: =COUNTIFS(明細!$J$5:$J$363,A191) | M191: =IF(K191=0,0,L191/K191) | N191: =SUM($K$6:K191) | O191: =SUM($L$6:L191) | P191: =IF(N191=0,"",O191/N191) | Q191: =IF(A191>$S$2,"予定",IF(N191=0,"－",IF(P191>=1,"完了",IF(O191>=N191,"順調","遅延")))) | R191: =D191+K191 | S191: =E191+L191

Sheet 進捗サマリー_その他
A1: テスト進捗サマリー（その他）
A2: 集計期間: 2025/12/23 ～ 2026/06/06 (166日間) | R2: 基準日: | S2: =ダッシュボード!$B$2
A3: 共通 | D3: 実施 | K3: 検証 | R3: 合計
A4: 日付 | B4: 曜 | C4: 営業日 | D4: 予定 | E4: 実績 | F4: 消化率 | G4: 予定累計 | H4: 実績累計 | I4: 累計消化率 | J4: 判定 | K4: 予定 | L4: 実績 | M4: 消化率 | N4: 予定累計 | O4: 実績累計 | P4: 累計消化率 | Q4: 判定 | R4: 予定 | S4: 実績
A5: 合計 | D5: =SUM(D6:D171) | E5: =SUM(E6:E171) | F5: =IF(D5=0,0,E5/D5) | G5: =D5 | H5: =E5 | I5: =IF(G5=0,"",H5/G5) | J5: =IF(I5>=1,"完了",IF(H5>=G5,"順調","遅延")) | K5: =SUM(K6:K171) | L5: =SUM(L6:L171) | M5: =IF(K5=0,0,L5/K5) | N5: =K5 | O5: =L5 | P5: =IF(N5=0,"",O5/N5) | Q5: =IF(P5>=1,"完了",IF(O5>=N5,"順調","遅延")) | R5: =D5+K5 | S5: =E5+L5
A6: 46014 | B6: =CHOOSE(WEEKDAY(A6,2),"月","火","水","木","金","土","日") | C6: =IF(OR(WEEKDAY(A6,2)>=6,COUNTIF(祝日マスタ!$A:$A,A6)>0),"非営業日","営業日") | D6: =COUNTIFS(明細!$F$5:$F$363,A6,明細!$D$5:$D$363,"その他") | E6: =COUNTIFS(明細!$G$5:$G$363,A6,明細!$D$5:$D$363,"その他") | F6: =IF(D6=0,0,E6/D6) | G6: =SUM($D$6:D6) | H6: =SUM($E$6:E6) | I6: =IF(G6=0,"",H6/G6) | J6: =IF(A6>$S$2,"予定",IF(G6=0,"－",IF(I6>=1,"完了",IF(H6>=G6,"順調","遅延")))) | K6: =COUNTIFS(明細!$I$5:$I$363,A6,明細!$D$5:$D$363,"その他") | L6: =COUNTIFS(明細!$J$5:$J$363,A6,明細!$D$5:$D$363,"その他") | M6: =IF(K6=0,0,L6/K6) | N6: =SUM($K$6:K6) | O6: =SUM($L$6:L6) | P6: =IF(N6=0,"",O6/N6) | Q6: =IF(A6>$S$2,"予定",IF(N6=0,"－",IF(P6>=1,"完了",IF(O6>=N6,"順調","遅延")))) | R6: =D6+K6 | S6: =E6+L6
A7: 46015 | B7: =CHOOSE(WEEKDAY(A7,2),"月","火","水","木","金","土","日") | C7: =IF(OR(WEEKDAY(A7,2)>=6,COUNTIF(祝日マスタ!$A:$A,A7)>0),"非営業日","営業日") | D7: =COUNTIFS(明細!$F$5:$F$363,A7,明細!$D$5:$D$363,"その他") | E7: =COUNTIFS(明細!$G$5:$G$363,A7,明細!$D$5:$D$363,"その他") | F7: =IF(D7=0,0,E7/D7) | G7: =SUM($D$6:D7) | H7: =SUM($E$6:E7) | I7: =IF(G7=0,"",H7/G7) | J7: =IF(A7>$S$2,"予定",IF(G7=0,"－",IF(I7>=1,"完了",IF(H7>=G7,"順調","遅延")))) | K7: =COUNTIFS(明細!$I$5:$I$363,A7,明細!$D$5:$D$363,"その他") | L7: =COUNTIFS(明細!$J$5:$J$363,A7,明細!$D$5:$D$363,"その他") | M7: =IF(K7=0,0,L7/K7) | N7: =SUM($K$6:K7) | O7: =SUM($L$6:L7) | P7: =IF(N7=0,"",O7/N7) | Q7: =IF(A7>$S$2,"予定",IF(N7=0,"－",IF(P7>=1,"完了",IF(O7>=N7,"順調","遅延")))) | R7: =D7+K7 | S7: =E7+L7
A8: 46016 | B8: =CHOOSE(WEEKDAY(A8,2),"月","火","水","木","金","土","日") | C8: =IF(OR(WEEKDAY(A8,2)>=6,COUNTIF(祝日マスタ!$A:$A,A8)>0),"非営業日","営業日") | D8: =COUNTIFS(明細!$F$5:$F$363,A8,明細!$D$5:$D$363,"その他") | E8: =COUNTIFS(明細!$G$5:$G$363,A8,明細!$D$5:$D$363,"その他") | F8: =IF(D8=0,0,E8/D8) | G8: =SUM($D$6:D8) | H8: =SUM($E$6:E8) | I8: =IF(G8=0,"",H8/G8) | J8: =IF(A8>$S$2,"予定",IF(G8=0,"－",IF(I8>=1,"完了",IF(H8>=G8,"順調","遅延")))) | K8: =COUNTIFS(明細!$I$5:$I$363,A8,明細!$D$5:$D$363,"その他") | L8: =COUNTIFS(明細!$J$5:$J$363,A8,明細!$D$5:$D$363,"その他") | M8: =IF(K8=0,0,L8/K8) | N8: =SUM($K$6:K8) | O8: =SUM($L$6:L8) | P8: =IF(N8=0,"",O8/N8) | Q8: =IF(A8>$S$2,"予定",IF(N8=0,"－",IF(P8>=1,"完了",IF(O8>=N8,"順調","遅延")))) | R8: =D8+K8 | S8: =E8+L8
A9: 46017 | B9: =CHOOSE(WEEKDAY(A9,2),"月","火","水","木","金","土","日") | C9: =IF(OR(WEEKDAY(A9,2)>=6,COUNTIF(祝日マスタ!$A:$A,A9)>0),"非営業日","営業日") | D9: =COUNTIFS(明細!$F$5:$F$363,A9,明細!$D$5:$D$363,"その他") | E9: =COUNTIFS(明細!$G$5:$G$363,A9,明細!$D$5:$D$363,"その他") | F9: =IF(D9=0,0,E9/D9) | G9: =SUM($D$6:D9) | H9: =SUM($E$6:E9) | I9: =IF(G9=0,"",H9/G9) | J9: =IF(A9>$S$2,"予定",IF(G9=0,"－",IF(I9>=1,"完了",IF(H9>=G9,"順調","遅延")))) | K9: =COUNTIFS(明細!$I$5:$I$363,A9,明細!$D$5:$D$363,"その他") | L9: =COUNTIFS(明細!$J$5:$J$363,A9,明細!$D$5:$D$363,"その他") | M9: =IF(K9=0,0,L9/K9) | N9: =SUM($K$6:K9) | O9: =SUM($L$6:L9) | P9: =IF(N9=0,"",O9/N9) | Q9: =IF(A9>$S$2,"予定",IF(N9=0,"－",IF(P9>=1,"完了",IF(O9>=N9,"順調","遅延")))) | R9: =D9+K9 | S9: =E9+L9
A10: 46018 | B10: =CHOOSE(WEEKDAY(A10,2),"月","火","水","木","金","土","日") | C10: =IF(OR(WEEKDAY(A10,2)>=6,COUNTIF(祝日マスタ!$A:$A,A10)>0),"非営業日","営業日") | D10: =COUNTIFS(明細!$F$5:$F$363,A10,明細!$D$5:$D$363,"その他") | E10: =COUNTIFS(明細!$G$5:$G$363,A10,明細!$D$5:$D$363,"その他") | F10: =IF(D10=0,0,E10/D10) | G10: =SUM($D$6:D10) | H10: =SUM($E$6:E10) | I10: =IF(G10=0,"",H10/G10) | J10: =IF(A10>$S$2,"予定",IF(G10=0,"－",IF(I10>=1,"完了",IF(H10>=G10,"順調","遅延")))) | K10: =COUNTIFS(明細!$I$5:$I$363,A10,明細!$D$5:$D$363,"その他") | L10: =COUNTIFS(明細!$J$5:$J$363,A10,明細!$D$5:$D$363,"その他") | M10: =IF(K10=0,0,L10/K10) | N10: =SUM($K$6:K10) | O10: =SUM($L$6:L10) | P10: =IF(N10=0,"",O10/N10) | Q10: =IF(A10>$S$2,"予定",IF(N10=0,"－",IF(P10>=1,"完了",IF(O10>=N10,"順調","遅延")))) | R10: =D10+K10 | S10: =E10+L10
A11: 46019 | B11: =CHOOSE(WEEKDAY(A11,2),"月","火","水","木","金","土","日") | C11: =IF(OR(WEEKDAY(A11,2)>=6,COUNTIF(祝日マスタ!$A:$A,A11)>0),"非営業日","営業日") | D11: =COUNTIFS(明細!$F$5:$F$363,A11,明細!$D$5:$D$363,"その他") | E11: =COUNTIFS(明細!$G$5:$G$363,A11,明細!$D$5:$D$363,"その他") | F11: =IF(D11=0,0,E11/D11) | G11: =SUM($D$6:D11) | H11: =SUM($E$6:E11) | I11: =IF(G11=0,"",H11/G11) | J11: =IF(A11>$S$2,"予定",IF(G11=0,"－",IF(I11>=1,"完了",IF(H11>=G11,"順調","遅延")))) | K11: =COUNTIFS(明細!$I$5:$I$363,A11,明細!$D$5:$D$363,"その他") | L11: =COUNTIFS(明細!$J$5:$J$363,A11,明細!$D$5:$D$363,"その他") | M11: =IF(K11=0,0,L11/K11) | N11: =SUM($K$6:K11) | O11: =SUM($L$6:L11) | P11: =IF(N11=0,"",O11/N11) | Q11: =IF(A11>$S$2,"予定",IF(N11=0,"－",IF(P11>=1,"完了",IF(O11>=N11,"順調","遅延")))) | R11: =D11+K11 | S11: =E11+L11
A12: 46020 | B12: =CHOOSE(WEEKDAY(A12,2),"月","火","水","木","金","土","日") | C12: =IF(OR(WEEKDAY(A12,2)>=6,COUNTIF(祝日マスタ!$A:$A,A12)>0),"非営業日","営業日") | D12: =COUNTIFS(明細!$F$5:$F$363,A12,明細!$D$5:$D$363,"その他") | E12: =COUNTIFS(明細!$G$5:$G$363,A12,明細!$D$5:$D$363,"その他") | F12: =IF(D12=0,0,E12/D12) | G12: =SUM($D$6:D12) | H12: =SUM($E$6:E12) | I12: =IF(G12=0,"",H12/G12) | J12: =IF(A12>$S$2,"予定",IF(G12=0,"－",IF(I12>=1,"完了",IF(H12>=G12,"順調","遅延")))) | K12: =COUNTIFS(明細!$I$5:$I$363,A12,明細!$D$5:$D$363,"その他") | L12: =COUNTIFS(明細!$J$5:$J$363,A12,明細!$D$5:$D$363,"その他") | M12: =IF(K12=0,0,L12/K12) | N12: =SUM($K$6:K12) | O12: =SUM($L$6:L12) | P12: =IF(N12=0,"",O12/N12) | Q12: =IF(A12>$S$2,"予定",IF(N12=0,"－",IF(P12>=1,"完了",IF(O12>=N12,"順調","遅延")))) | R12: =D12+K12 | S12: =E12+L12
A13: 46021 | B13: =CHOOSE(WEEKDAY(A13,2),"月","火","水","木","金","土","日") | C13: =IF(OR(WEEKDAY(A13,2)>=6,COUNTIF(祝日マスタ!$A:$A,A13)>0),"非営業日","営業日") | D13: =COUNTIFS(明細!$F$5:$F$363,A13,明細!$D$5:$D$363,"その他") | E13: =COUNTIFS(明細!$G$5:$G$363,A13,明細!$D$5:$D$363,"その他") | F13: =IF(D13=0,0,E13/D13) | G13: =SUM($D$6:D13) | H13: =SUM($E$6:E13) | I13: =IF(G13=0,"",H13/G13) | J13: =IF(A13>$S$2,"予定",IF(G13=0,"－",IF(I13>=1,"完了",IF(H13>=G13,"順調","遅延")))) | K13: =COUNTIFS(明細!$I$5:$I$363,A13,明細!$D$5:$D$363,"その他") | L13: =COUNTIFS(明細!$J$5:$J$363,A13,明細!$D$5:$D$363,"その他") | M13: =IF(K13=0,0,L13/K13) | N13: =SUM($K$6:K13) | O13: =SUM($L$6:L13) | P13: =IF(N13=0,"",O13/N13) | Q13: =IF(A13>$S$2,"予定",IF(N13=0,"－",IF(P13>=1,"完了",IF(O13>=N13,"順調","遅延")))) | R13: =D13+K13 | S13: =E13+L13
A14: 46022 | B14: =CHOOSE(WEEKDAY(A14,2),"月","火","水","木","金","土","日") | C14: =IF(OR(WEEKDAY(A14,2)>=6,COUNTIF(祝日マスタ!$A:$A,A14)>0),"非営業日","営業日") | D14: =COUNTIFS(明細!$F$5:$F$363,A14,明細!$D$5:$D$363,"その他") | E14: =COUNTIFS(明細!$G$5:$G$363,A14,明細!$D$5:$D$363,"その他") | F14: =IF(D14=0,0,E14/D14) | G14: =SUM($D$6:D14) | H14: =SUM($E$6:E14) | I14: =IF(G14=0,"",H14/G14) | J14: =IF(A14>$S$2,"予定",IF(G14=0,"－",IF(I14>=1,"完了",IF(H14>=G14,"順調","遅延")))) | K14: =COUNTIFS(明細!$I$5:$I$363,A14,明細!$D$5:$D$363,"その他") | L14: =COUNTIFS(明細!$J$5:$J$363,A14,明細!$D$5:$D$363,"その他") | M14: =IF(K14=0,0,L14/K14) | N14: =SUM($K$6:K14) | O14: =SUM($L$6:L14) | P14: =IF(N14=0,"",O14/N14) | Q14: =IF(A14>$S$2,"予定",IF(N14=0,"－",IF(P14>=1,"完了",IF(O14>=N14,"順調","遅延")))) | R14: =D14+K14 | S14: =E14+L14
A15: 46023 | B15: =CHOOSE(WEEKDAY(A15,2),"月","火","水","木","金","土","日") | C15: =IF(OR(WEEKDAY(A15,2)>=6,COUNTIF(祝日マスタ!$A:$A,A15)>0),"非営業日","営業日") | D15: =COUNTIFS(明細!$F$5:$F$363,A15,明細!$D$5:$D$363,"その他") | E15: =COUNTIFS(明細!$G$5:$G$363,A15,明細!$D$5:$D$363,"その他") | F15: =IF(D15=0,0,E15/D15) | G15: =SUM($D$6:D15) | H15: =SUM($E$6:E15) | I15: =IF(G15=0,"",H15/G15) | J15: =IF(A15>$S$2,"予定",IF(G15=0,"－",IF(I15>=1,"完了",IF(H15>=G15,"順調","遅延")))) | K15: =COUNTIFS(明細!$I$5:$I$363,A15,明細!$D$5:$D$363,"その他") | L15: =COUNTIFS(明細!$J$5:$J$363,A15,明細!$D$5:$D$363,"その他") | M15: =IF(K15=0,0,L15/K15) | N15: =SUM($K$6:K15) | O15: =SUM($L$6:L15) | P15: =IF(N15=0,"",O15/N15) | Q15: =IF(A15>$S$2,"予定",IF(N15=0,"－",IF(P15>=1,"完了",IF(O15>=N15,"順調","遅延")))) | R15: =D15+K15 | S15: =E15+L15
A16: 46024 | B16: =CHOOSE(WEEKDAY(A16,2),"月","火","水","木","金","土","日") | C16: =IF(OR(WEEKDAY(A16,2)>=6,COUNTIF(祝日マスタ!$A:$A,A16)>0),"非営業日","営業日") | D16: =COUNTIFS(明細!$F$5:$F$363,A16,明細!$D$5:$D$363,"その他") | E16: =COUNTIFS(明細!$G$5:$G$363,A16,明細!$D$5:$D$363,"その他") | F16: =IF(D16=0,0,E16/D16) | G16: =SUM($D$6:D16) | H16: =SUM($E$6:E16) | I16: =IF(G16=0,"",H16/G16) | J16: =IF(A16>$S$2,"予定",IF(G16=0,"－",IF(I16>=1,"完了",IF(H16>=G16,"順調","遅延")))) | K16: =COUNTIFS(明細!$I$5:$I$363,A16,明細!$D$5:$D$363,"その他") | L16: =COUNTIFS(明細!$J$5:$J$363,A16,明細!$D$5:$D$363,"その他") | M16: =IF(K16=0,0,L16/K16) | N16: =SUM($K$6:K16) | O16: =SUM($L$6:L16) | P16: =IF(N16=0,"",O16/N16) | Q16: =IF(A16>$S$2,"予定",IF(N16=0,"－",IF(P16>=1,"完了",IF(O16>=N16,"順調","遅延")))) | R16: =D16+K16 | S16: =E16+L16
A17: 46025 | B17: =CHOOSE(WEEKDAY(A17,2),"月","火","水","木","金","土","日") | C17: =IF(OR(WEEKDAY(A17,2)>=6,COUNTIF(祝日マスタ!$A:$A,A17)>0),"非営業日","営業日") | D17: =COUNTIFS(明細!$F$5:$F$363,A17,明細!$D$5:$D$363,"その他") | E17: =COUNTIFS(明細!$G$5:$G$363,A17,明細!$D$5:$D$363,"その他") | F17: =IF(D17=0,0,E17/D17) | G17: =SUM($D$6:D17) | H17: =SUM($E$6:E17) | I17: =IF(G17=0,"",H17/G17) | J17: =IF(A17>$S$2,"予定",IF(G17=0,"－",IF(I17>=1,"完了",IF(H17>=G17,"順調","遅延")))) | K17: =COUNTIFS(明細!$I$5:$I$363,A17,明細!$D$5:$D$363,"その他") | L17: =COUNTIFS(明細!$J$5:$J$363,A17,明細!$D$5:$D$363,"その他") | M17: =IF(K17=0,0,L17/K17) | N17: =SUM($K$6:K17) | O17: =SUM($L$6:L17) | P17: =IF(N17=0,"",O17/N17) | Q17: =IF(A17>$S$2,"予定",IF(N17=0,"－",IF(P17>=1,"完了",IF(O17>=N17,"順調","遅延")))) | R17: =D17+K17 | S17: =E17+L17
... A171: 46179 | B171: =CHOOSE(WEEKDAY(A171,2),"月","火","水","木","金","土","日") | C171: =IF(OR(WEEKDAY(A171,2)>=6,COUNTIF(祝日マスタ!$A:$A,A171)>0),"非営業日","営業日") | D171: =COUNTIFS(明細!$F$5:$F$363,A171,明細!$D$5:$D$363,"その他") | E171: =COUNTIFS(明細!$G$5:$G$363,A171,明細!$D$5:$D$363,"その他") | F171: =IF(D171=0,0,E171/D171) | G171: =SUM($D$6:D171) | H171: =SUM($E$6:E171) | I171: =IF(G171=0,"",H171/G171) | J171: =IF(A171>$S$2,"予定",IF(G171=0,"－",IF(I171>=1,"完了",IF(H171>=G171,"順調","遅延")))) | K171: =COUNTIFS(明細!$I$5:$I$363,A171,明細!$D$5:$D$363,"その他") | L171: =COUNTIFS(明細!$J$5:$J$363,A171,明細!$D$5:$D$363,"その他") | M171: =IF(K171=0,0,L171/K171) | N171: =SUM($K$6:K171) | O171: =SUM($L$6:L171) | P171: =IF(N171=0,"",O171/N171) | Q171: =IF(A171>$S$2,"予定",IF(N171=0,"－",IF(P171>=1,"完了",IF(O171>=N171,"順調","遅延")))) | R171: =D171+K171 | S171: =E171+L171

Sheet 進捗サマリー_オンライン
A1: テスト進捗サマリー（オンライン）
A2: 集計期間: 2025/12/07 ～ 2026/06/08 (184日間) | R2: 基準日: | S2: =ダッシュボード!$B$2
A3: 共通 | D3: 実施 | K3: 検証 | R3: 合計
A4: 日付 | B4: 曜 | C4: 営業日 | D4: 予定 | E4: 実績 | F4: 消化率 | G4: 予定累計 | H4: 実績累計 | I4: 累計消化率 | J4: 判定 | K4: 予定 | L4: 実績 | M4: 消化率 | N4: 予定累計 | O4: 実績累計 | P4: 累計消化率 | Q4: 判定 | R4: 予定 | S4: 実績
A5: 合計 | D5: =SUM(D6:D189) | E5: =SUM(E6:E189) | F5: =IF(D5=0,0,E5/D5) | G5: =D5 | H5: =E5 | I5: =IF(G5=0,"",H5/G5) | J5: =IF(I5>=1,"完了",IF(H5>=G5,"順調","遅延")) | K5: =SUM(K6:K189) | L5: =SUM(L6:L189) | M5: =IF(K5=0,0,L5/K5) | N5: =K5 | O5: =L5 | P5: =IF(N5=0,"",O5/N5) | Q5: =IF(P5>=1,"完了",IF(O5>=N5,"順調","遅延")) | R5: =D5+K5 | S5: =E5+L5
A6: 45998 | B6: =CHOOSE(WEEKDAY(A6,2),"月","火","水","木","金","土","日") | C6: =IF(OR(WEEKDAY(A6,2)>=6,COUNTIF(祝日マスタ!$A:$A,A6)>0),"非営業日","営業日") | D6: =COUNTIFS(明細!$F$5:$F$363,A6,明細!$D$5:$D$363,"オンライン") | E6: =COUNTIFS(明細!$G$5:$G$363,A6,明細!$D$5:$D$363,"オンライン") | F6: =IF(D6=0,0,E6/D6) | G6: =SUM($D$6:D6) | H6: =SUM($E$6:E6) | I6: =IF(G6=0,"",H6/G6) | J6: =IF(A6>$S$2,"予定",IF(G6=0,"－",IF(I6>=1,"完了",IF(H6>=G6,"順調","遅延")))) | K6: =COUNTIFS(明細!$I$5:$I$363,A6,明細!$D$5:$D$363,"オンライン") | L6: =COUNTIFS(明細!$J$5:$J$363,A6,明細!$D$5:$D$363,"オンライン") | M6: =IF(K6=0,0,L6/K6) | N6: =SUM($K$6:K6) | O6: =SUM($L$6:L6) | P6: =IF(N6=0,"",O6/N6) | Q6: =IF(A6>$S$2,"予定",IF(N6=0,"－",IF(P6>=1,"完了",IF(O6>=N6,"順調","遅延")))) | R6: =D6+K6 | S6: =E6+L6
A7: 45999 | B7: =CHOOSE(WEEKDAY(A7,2),"月","火","水","木","金","土","日") | C7: =IF(OR(WEEKDAY(A7,2)>=6,COUNTIF(祝日マスタ!$A:$A,A7)>0),"非営業日","営業日") | D7: =COUNTIFS(明細!$F$5:$F$363,A7,明細!$D$5:$D$363,"オンライン") | E7: =COUNTIFS(明細!$G$5:$G$363,A7,明細!$D$5:$D$363,"オンライン") | F7: =IF(D7=0,0,E7/D7) | G7: =SUM($D$6:D7) | H7: =SUM($E$6:E7) | I7: =IF(G7=0,"",H7/G7) | J7: =IF(A7>$S$2,"予定",IF(G7=0,"－",IF(I7>=1,"完了",IF(H7>=G7,"順調","遅延")))) | K7: =COUNTIFS(明細!$I$5:$I$363,A7,明細!$D$5:$D$363,"オンライン") | L7: =COUNTIFS(明細!$J$5:$J$363,A7,明細!$D$5:$D$363,"オンライン") | M7: =IF(K7=0,0,L7/K7) | N7: =SUM($K$6:K7) | O7: =SUM($L$6:L7) | P7: =IF(N7=0,"",O7/N7) | Q7: =IF(A7>$S$2,"予定",IF(N7=0,"－",IF(P7>=1,"完了",IF(O7>=N7,"順調","遅延")))) | R7: =D7+K7 | S7: =E7+L7
A8: 46000 | B8: =CHOOSE(WEEKDAY(A8,2),"月","火","水","木","金","土","日") | C8: =IF(OR(WEEKDAY(A8,2)>=6,COUNTIF(祝日マスタ!$A:$A,A8)>0),"非営業日","営業日") | D8: =COUNTIFS(明細!$F$5:$F$363,A8,明細!$D$5:$D$363,"オンライン") | E8: =COUNTIFS(明細!$G$5:$G$363,A8,明細!$D$5:$D$363,"オンライン") | F8: =IF(D8=0,0,E8/D8) | G8: =SUM($D$6:D8) | H8: =SUM($E$6:E8) | I8: =IF(G8=0,"",H8/G8) | J8: =IF(A8>$S$2,"予定",IF(G8=0,"－",IF(I8>=1,"完了",IF(H8>=G8,"順調","遅延")))) | K8: =COUNTIFS(明細!$I$5:$I$363,A8,明細!$D$5:$D$363,"オンライン") | L8: =COUNTIFS(明細!$J$5:$J$363,A8,明細!$D$5:$D$363,"オンライン") | M8: =IF(K8=0,0,L8/K8) | N8: =SUM($K$6:K8) | O8: =SUM($L$6:L8) | P8: =IF(N8=0,"",O8/N8) | Q8: =IF(A8>$S$2,"予定",IF(N8=0,"－",IF(P8>=1,"完了",IF(O8>=N8,"順調","遅延")))) | R8: =D8+K8 | S8: =E8+L8
A9: 46001 | B9: =CHOOSE(WEEKDAY(A9,2),"月","火","水","木","金","土","日") | C9: =IF(OR(WEEKDAY(A9,2)>=6,COUNTIF(祝日マスタ!$A:$A,A9)>0),"非営業日","営業日") | D9: =COUNTIFS(明細!$F$5:$F$363,A9,明細!$D$5:$D$363,"オンライン") | E9: =COUNTIFS(明細!$G$5:$G$363,A9,明細!$D$5:$D$363,"オンライン") | F9: =IF(D9=0,0,E9/D9) | G9: =SUM($D$6:D9) | H9: =SUM($E$6:E9) | I9: =IF(G9=0,"",H9/G9) | J9: =IF(A9>$S$2,"予定",IF(G9=0,"－",IF(I9>=1,"完了",IF(H9>=G9,"順調","遅延")))) | K9: =COUNTIFS(明細!$I$5:$I$363,A9,明細!$D$5:$D$363,"オンライン") | L9: =COUNTIFS(明細!$J$5:$J$363,A9,明細!$D$5:$D$363,"オンライン") | M9: =IF(K9=0,0,L9/K9) | N9: =SUM($K$6:K9) | O9: =SUM($L$6:L9) | P9: =IF(N9=0,"",O9/N9) | Q9: =IF(A9>$S$2,"予定",IF(N9=0,"－",IF(P9>=1,"完了",IF(O9>=N9,"順調","遅延")))) | R9: =D9+K9 | S9: =E9+L9
A10: 46002 | B10: =CHOOSE(WEEKDAY(A10,2),"月","火","水","木","金","土","日") | C10: =IF(OR(WEEKDAY(A10,2)>=6,COUNTIF(祝日マスタ!$A:$A,A10)>0),"非営業日","営業日") | D10: =COUNTIFS(明細!$F$5:$F$363,A10,明細!$D$5:$D$363,"オンライン") | E10: =COUNTIFS(明細!$G$5:$G$363,A10,明細!$D$5:$D$363,"オンライン") | F10: =IF(D10=0,0,E10/D10) | G10: =SUM($D$6:D10) | H10: =SUM($E$6:E10) | I10: =IF(G10=0,"",H10/G10) | J10: =IF(A10>$S$2,"予定",IF(G10=0,"－",IF(I10>=1,"完了",IF(H10>=G10,"順調","遅延")))) | K10: =COUNTIFS(明細!$I$5:$I$363,A10,明細!$D$5:$D$363,"オンライン") | L10: =COUNTIFS(明細!$J$5:$J$363,A10,明細!$D$5:$D$363,"オンライン") | M10: =IF(K10=0,0,L10/K10) | N10: =SUM($K$6:K10) | O10: =SUM($L$6:L10) | P10: =IF(N10=0,"",O10/N10) | Q10: =IF(A10>$S$2,"予定",IF(N10=0,"－",IF(P10>=1,"完了",IF(O10>=N10,"順調","遅延")))) | R10: =D10+K10 | S10: =E10+L10
A11: 46003 | B11: =CHOOSE(WEEKDAY(A11,2),"月","火","水","木","金","土","日") | C11: =IF(OR(WEEKDAY(A11,2)>=6,COUNTIF(祝日マスタ!$A:$A,A11)>0),"非営業日","営業日") | D11: =COUNTIFS(明細!$F$5:$F$363,A11,明細!$D$5:$D$363,"オンライン") | E11: =COUNTIFS(明細!$G$5:$G$363,A11,明細!$D$5:$D$363,"オンライン") | F11: =IF(D11=0,0,E11/D11) | G11: =SUM($D$6:D11) | H11: =SUM($E$6:E11) | I11: =IF(G11=0,"",H11/G11) | J11: =IF(A11>$S$2,"予定",IF(G11=0,"－",IF(I11>=1,"完了",IF(H11>=G11,"順調","遅延")))) | K11: =COUNTIFS(明細!$I$5:$I$363,A11,明細!$D$5:$D$363,"オンライン") | L11: =COUNTIFS(明細!$J$5:$J$363,A11,明細!$D$5:$D$363,"オンライン") | M11: =IF(K11=0,0,L11/K11) | N11: =SUM($K$6:K11) | O11: =SUM($L$6:L11) | P11: =IF(N11=0,"",O11/N11) | Q11: =IF(A11>$S$2,"予定",IF(N11=0,"－",IF(P11>=1,"完了",IF(O11>=N11,"順調","遅延")))) | R11: =D11+K11 | S11: =E11+L11
A12: 46004 | B12: =CHOOSE(WEEKDAY(A12,2),"月","火","水","木","金","土","日") | C12: =IF(OR(WEEKDAY(A12,2)>=6,COUNTIF(祝日マスタ!$A:$A,A12)>0),"非営業日","営業日") | D12: =COUNTIFS(明細!$F$5:$F$363,A12,明細!$D$5:$D$363,"オンライン") | E12: =COUNTIFS(明細!$G$5:$G$363,A12,明細!$D$5:$D$363,"オンライン") | F12: =IF(D12=0,0,E12/D12) | G12: =SUM($D$6:D12) | H12: =SUM($E$6:E12) | I12: =IF(G12=0,"",H12/G12) | J12: =IF(A12>$S$2,"予定",IF(G12=0,"－",IF(I12>=1,"完了",IF(H12>=G12,"順調","遅延")))) | K12: =COUNTIFS(明細!$I$5:$I$363,A12,明細!$D$5:$D$363,"オンライン") | L12: =COUNTIFS(明細!$J$5:$J$363,A12,明細!$D$5:$D$363,"オンライン") | M12: =IF(K12=0,0,L12/K12) | N12: =SUM($K$6:K12) | O12: =SUM($L$6:L12) | P12: =IF(N12=0,"",O12/N12) | Q12: =IF(A12>$S$2,"予定",IF(N12=0,"－",IF(P12>=1,"完了",IF(O12>=N12,"順調","遅延")))) | R12: =D12+K12 | S12: =E12+L12
A13: 46005 | B13: =CHOOSE(WEEKDAY(A13,2),"月","火","水","木","金","土","日") | C13: =IF(OR(WEEKDAY(A13,2)>=6,COUNTIF(祝日マスタ!$A:$A,A13)>0),"非営業日","営業日") | D13: =COUNTIFS(明細!$F$5:$F$363,A13,明細!$D$5:$D$363,"オンライン") | E13: =COUNTIFS(明細!$G$5:$G$363,A13,明細!$D$5:$D$363,"オンライン") | F13: =IF(D13=0,0,E13/D13) | G13: =SUM($D$6:D13) | H13: =SUM($E$6:E13) | I13: =IF(G13=0,"",H13/G13) | J13: =IF(A13>$S$2,"予定",IF(G13=0,"－",IF(I13>=1,"完了",IF(H13>=G13,"順調","遅延")))) | K13: =COUNTIFS(明細!$I$5:$I$363,A13,明細!$D$5:$D$363,"オンライン") | L13: =COUNTIFS(明細!$J$5:$J$363,A13,明細!$D$5:$D$363,"オンライン") | M13: =IF(K13=0,0,L13/K13) | N13: =SUM($K$6:K13) | O13: =SUM($L$6:L13) | P13: =IF(N13=0,"",O13/N13) | Q13: =IF(A13>$S$2,"予定",IF(N13=0,"－",IF(P13>=1,"完了",IF(O13>=N13,"順調","遅延")))) | R13: =D13+K13 | S13: =E13+L13
A14: 46006 | B14: =CHOOSE(WEEKDAY(A14,2),"月","火","水","木","金","土","日") | C14: =IF(OR(WEEKDAY(A14,2)>=6,COUNTIF(祝日マスタ!$A:$A,A14)>0),"非営業日","営業日") | D14: =COUNTIFS(明細!$F$5:$F$363,A14,明細!$D$5:$D$363,"オンライン") | E14: =COUNTIFS(明細!$G$5:$G$363,A14,明細!$D$5:$D$363,"オンライン") | F14: =IF(D14=0,0,E14/D14) | G14: =SUM($D$6:D14) | H14: =SUM($E$6:E14) | I14: =IF(G14=0,"",H14/G14) | J14: =IF(A14>$S$2,"予定",IF(G14=0,"－",IF(I14>=1,"完了",IF(H14>=G14,"順調","遅延")))) | K14: =COUNTIFS(明細!$I$5:$I$363,A14,明細!$D$5:$D$363,"オンライン") | L14: =COUNTIFS(明細!$J$5:$J$363,A14,明細!$D$5:$D$363,"オンライン") | M14: =IF(K14=0,0,L14/K14) | N14: =SUM($K$6:K14) | O14: =SUM($L$6:L14) | P14: =IF(N14=0,"",O14/N14) | Q14: =IF(A14>$S$2,"予定",IF(N14=0,"－",IF(P14>=1,"完了",IF(O14>=N14,"順調","遅延")))) | R14: =D14+K14 | S14: =E14+L14
A15: 46007 | B15: =CHOOSE(WEEKDAY(A15,2),"月","火","水","木","金","土","日") | C15: =IF(OR(WEEKDAY(A15,2)>=6,COUNTIF(祝日マスタ!$A:$A,A15)>0),"非営業日","営業日") | D15: =COUNTIFS(明細!$F$5:$F$363,A15,明細!$D$5:$D$363,"オンライン") | E15: =COUNTIFS(明細!$G$5:$G$363,A15,明細!$D$5:$D$363,"オンライン") | F15: =IF(D15=0,0,E15/D15) | G15: =SUM($D$6:D15) | H15: =SUM($E$6:E15) | I15: =IF(G15=0,"",H15/G15) | J15: =IF(A15>$S$2,"予定",IF(G15=0,"－",IF(I15>=1,"完了",IF(H15>=G15,"順調","遅延")))) | K15: =COUNTIFS(明細!$I$5:$I$363,A15,明細!$D$5:$D$363,"オンライン") | L15: =COUNTIFS(明細!$J$5:$J$363,A15,明細!$D$5:$D$363,"オンライン") | M15: =IF(K15=0,0,L15/K15) | N15: =SUM($K$6:K15) | O15: =SUM($L$6:L15) | P15: =IF(N15=0,"",O15/N15) | Q15: =IF(A15>$S$2,"予定",IF(N15=0,"－",IF(P15>=1,"完了",IF(O15>=N15,"順調","遅延")))) | R15: =D15+K15 | S15: =E15+L15
A16: 46008 | B16: =CHOOSE(WEEKDAY(A16,2),"月","火","水","木","金","土","日") | C16: =IF(OR(WEEKDAY(A16,2)>=6,COUNTIF(祝日マスタ!$A:$A,A16)>0),"非営業日","営業日") | D16: =COUNTIFS(明細!$F$5:$F$363,A16,明細!$D$5:$D$363,"オンライン") | E16: =COUNTIFS(明細!$G$5:$G$363,A16,明細!$D$5:$D$363,"オンライン") | F16: =IF(D16=0,0,E16/D16) | G16: =SUM($D$6:D16) | H16: =SUM($E$6:E16) | I16: =IF(G16=0,"",H16/G16) | J16: =IF(A16>$S$2,"予定",IF(G16=0,"－",IF(I16>=1,"完了",IF(H16>=G16,"順調","遅延")))) | K16: =COUNTIFS(明細!$I$5:$I$363,A16,明細!$D$5:$D$363,"オンライン") | L16: =COUNTIFS(明細!$J$5:$J$363,A16,明細!$D$5:$D$363,"オンライン") | M16: =IF(K16=0,0,L16/K16) | N16: =SUM($K$6:K16) | O16: =SUM($L$6:L16) | P16: =IF(N16=0,"",O16/N16) | Q16: =IF(A16>$S$2,"予定",IF(N16=0,"－",IF(P16>=1,"完了",IF(O16>=N16,"順調","遅延")))) | R16: =D16+K16 | S16: =E16+L16
A17: 46009 | B17: =CHOOSE(WEEKDAY(A17,2),"月","火","水","木","金","土","日") | C17: =IF(OR(WEEKDAY(A17,2)>=6,COUNTIF(祝日マスタ!$A:$A,A17)>0),"非営業日","営業日") | D17: =COUNTIFS(明細!$F$5:$F$363,A17,明細!$D$5:$D$363,"オンライン") | E17: =COUNTIFS(明細!$G$5:$G$363,A17,明細!$D$5:$D$363,"オンライン") | F17: =IF(D17=0,0,E17/D17) | G17: =SUM($D$6:D17) | H17: =SUM($E$6:E17) | I17: =IF(G17=0,"",H17/G17) | J17: =IF(A17>$S$2,"予定",IF(G17=0,"－",IF(I17>=1,"完了",IF(H17>=G17,"順調","遅延")))) | K17: =COUNTIFS(明細!$I$5:$I$363,A17,明細!$D$5:$D$363,"オンライン") | L17: =COUNTIFS(明細!$J$5:$J$363,A17,明細!$D$5:$D$363,"オンライン") | M17: =IF(K17=0,0,L17/K17) | N17: =SUM($K$6:K17) | O17: =SUM($L$6:L17) | P17: =IF(N17=0,"",O17/N17) | Q17: =IF(A17>$S$2,"予定",IF(N17=0,"－",IF(P17>=1,"完了",IF(O17>=N17,"順調","遅延")))) | R17: =D17+K17 | S17: =E17+L17
... A189: 46181 | B189: =CHOOSE(WEEKDAY(A189,2),"月","火","水","木","金","土","日") | C189: =IF(OR(WEEKDAY(A189,2)>=6,COUNTIF(祝日マスタ!$A:$A,A189)>0),"非営業日","営業日") | D189: =COUNTIFS(明細!$F$5:$F$363,A189,明細!$D$5:$D$363,"オンライン") | E189: =COUNTIFS(明細!$G$5:$G$363,A189,明細!$D$5:$D$363,"オンライン") | F189: =IF(D189=0,0,E189/D189) | G189: =SUM($D$6:D189) | H189: =SUM($E$6:E189) | I189: =IF(G189=0,"",H189/G189) | J189: =IF(A189>$S$2,"予定",IF(G189=0,"－",IF(I189>=1,"完了",IF(H189>=G189,"順調","遅延")))) | K189: =COUNTIFS(明細!$I$5:$I$363,A189,明細!$D$5:$D$363,"オンライン") | L189: =COUNTIFS(明細!$J$5:$J$363,A189,明細!$D$5:$D$363,"オンライン") | M189: =IF(K189=0,0,L189/K189) | N189: =SUM($K$6:K189) | O189: =SUM($L$6:L189) | P189: =IF(N189=0,"",O189/N189) | Q189: =IF(A189>$S$2,"予定",IF(N189=0,"－",IF(P189>=1,"完了",IF(O189>=N189,"順調","遅延")))) | R189: =D189+K189 | S189: =E189+L189

Sheet 進捗サマリー_バッチ
A1: テスト進捗サマリー（バッチ）
A2: 集計期間: 2025/12/11 ～ 2026/06/05 (177日間) | R2: 基準日: | S2: =ダッシュボード!$B$2
A3: 共通 | D3: 実施 | K3: 検証 | R3: 合計
A4: 日付 | B4: 曜 | C4: 営業日 | D4: 予定 | E4: 実績 | F4: 消化率 | G4: 予定累計 | H4: 実績累計 | I4: 累計消化率 | J4: 判定 | K4: 予定 | L4: 実績 | M4: 消化率 | N4: 予定累計 | O4: 実績累計 | P4: 累計消化率 | Q4: 判定 | R4: 予定 | S4: 実績
A5: 合計 | D5: =SUM(D6:D182) | E5: =SUM(E6:E182) | F5: =IF(D5=0,0,E5/D5) | G5: =D5 | H5: =E5 | I5: =IF(G5=0,"",H5/G5) | J5: =IF(I5>=1,"完了",IF(H5>=G5,"順調","遅延")) | K5: =SUM(K6:K182) | L5: =SUM(L6:L182) | M5: =IF(K5=0,0,L5/K5) | N5: =K5 | O5: =L5 | P5: =IF(N5=0,"",O5/N5) | Q5: =IF(P5>=1,"完了",IF(O5>=N5,"順調","遅延")) | R5: =D5+K5 | S5: =E5+L5
A6: 46002 | B6: =CHOOSE(WEEKDAY(A6,2),"月","火","水","木","金","土","日") | C6: =IF(OR(WEEKDAY(A6,2)>=6,COUNTIF(祝日マスタ!$A:$A,A6)>0),"非営業日","営業日") | D6: =COUNTIFS(明細!$F$5:$F$363,A6,明細!$D$5:$D$363,"バッチ") | E6: =COUNTIFS(明細!$G$5:$G$363,A6,明細!$D$5:$D$363,"バッチ") | F6: =IF(D6=0,0,E6/D6) | G6: =SUM($D$6:D6) | H6: =SUM($E$6:E6) | I6: =IF(G6=0,"",H6/G6) | J6: =IF(A6>$S$2,"予定",IF(G6=0,"－",IF(I6>=1,"完了",IF(H6>=G6,"順調","遅延")))) | K6: =COUNTIFS(明細!$I$5:$I$363,A6,明細!$D$5:$D$363,"バッチ") | L6: =COUNTIFS(明細!$J$5:$J$363,A6,明細!$D$5:$D$363,"バッチ") | M6: =IF(K6=0,0,L6/K6) | N6: =SUM($K$6:K6) | O6: =SUM($L$6:L6) | P6: =IF(N6=0,"",O6/N6) | Q6: =IF(A6>$S$2,"予定",IF(N6=0,"－",IF(P6>=1,"完了",IF(O6>=N6,"順調","遅延")))) | R6: =D6+K6 | S6: =E6+L6
A7: 46003 | B7: =CHOOSE(WEEKDAY(A7,2),"月","火","水","木","金","土","日") | C7: =IF(OR(WEEKDAY(A7,2)>=6,COUNTIF(祝日マスタ!$A:$A,A7)>0),"非営業日","営業日") | D7: =COUNTIFS(明細!$F$5:$F$363,A7,明細!$D$5:$D$363,"バッチ") | E7: =COUNTIFS(明細!$G$5:$G$363,A7,明細!$D$5:$D$363,"バッチ") | F7: =IF(D7=0,0,E7/D7) | G7: =SUM($D$6:D7) | H7: =SUM($E$6:E7) | I7: =IF(G7=0,"",H7/G7) | J7: =IF(A7>$S$2,"予定",IF(G7=0,"－",IF(I7>=1,"完了",IF(H7>=G7,"順調","遅延")))) | K7: =COUNTIFS(明細!$I$5:$I$363,A7,明細!$D$5:$D$363,"バッチ") | L7: =COUNTIFS(明細!$J$5:$J$363,A7,明細!$D$5:$D$363,"バッチ") | M7: =IF(K7=0,0,L7/K7) | N7: =SUM($K$6:K7) | O7: =SUM($L$6:L7) | P7: =IF(N7=0,"",O7/N7) | Q7: =IF(A7>$S$2,"予定",IF(N7=0,"－",IF(P7>=1,"完了",IF(O7>=N7,"順調","遅延")))) | R7: =D7+K7 | S7: =E7+L7
A8: 46004 | B8: =CHOOSE(WEEKDAY(A8,2),"月","火","水","木","金","土","日") | C8: =IF(OR(WEEKDAY(A8,2)>=6,COUNTIF(祝日マスタ!$A:$A,A8)>0),"非営業日","営業日") | D8: =COUNTIFS(明細!$F$5:$F$363,A8,明細!$D$5:$D$363,"バッチ") | E8: =COUNTIFS(明細!$G$5:$G$363,A8,明細!$D$5:$D$363,"バッチ") | F8: =IF(D8=0,0,E8/D8) | G8: =SUM($D$6:D8) | H8: =SUM($E$6:E8) | I8: =IF(G8=0,"",H8/G8) | J8: =IF(A8>$S$2,"予定",IF(G8=0,"－",IF(I8>=1,"完了",IF(H8>=G8,"順調","遅延")))) | K8: =COUNTIFS(明細!$I$5:$I$363,A8,明細!$D$5:$D$363,"バッチ") | L8: =COUNTIFS(明細!$J$5:$J$363,A8,明細!$D$5:$D$363,"バッチ") | M8: =IF(K8=0,0,L8/K8) | N8: =SUM($K$6:K8) | O8: =SUM($L$6:L8) | P8: =IF(N8=0,"",O8/N8) | Q8: =IF(A8>$S$2,"予定",IF(N8=0,"－",IF(P8>=1,"完了",IF(O8>=N8,"順調","遅延")))) | R8: =D8+K8 | S8: =E8+L8
A9: 46005 | B9: =CHOOSE(WEEKDAY(A9,2),"月","火","水","木","金","土","日") | C9: =IF(OR(WEEKDAY(A9,2)>=6,COUNTIF(祝日マスタ!$A:$A,A9)>0),"非営業日","営業日") | D9: =COUNTIFS(明細!$F$5:$F$363,A9,明細!$D$5:$D$363,"バッチ") | E9: =COUNTIFS(明細!$G$5:$G$363,A9,明細!$D$5:$D$363,"バッチ") | F9: =IF(D9=0,0,E9/D9) | G9: =SUM($D$6:D9) | H9: =SUM($E$6:E9) | I9: =IF(G9=0,"",H9/G9) | J9: =IF(A9>$S$2,"予定",IF(G9=0,"－",IF(I9>=1,"完了",IF(H9>=G9,"順調","遅延")))) | K9: =COUNTIFS(明細!$I$5:$I$363,A9,明細!$D$5:$D$363,"バッチ") | L9: =COUNTIFS(明細!$J$5:$J$363,A9,明細!$D$5:$D$363,"バッチ") | M9: =IF(K9=0,0,L9/K9) | N9: =SUM($K$6:K9) | O9: =SUM($L$6:L9) | P9: =IF(N9=0,"",O9/N9) | Q9: =IF(A9>$S$2,"予定",IF(N9=0,"－",IF(P9>=1,"完了",IF(O9>=N9,"順調","遅延")))) | R9: =D9+K9 | S9: =E9+L9
A10: 46006 | B10: =CHOOSE(WEEKDAY(A10,2),"月","火","水","木","金","土","日") | C10: =IF(OR(WEEKDAY(A10,2)>=6,COUNTIF(祝日マスタ!$A:$A,A10)>0),"非営業日","営業日") | D10: =COUNTIFS(明細!$F$5:$F$363,A10,明細!$D$5:$D$363,"バッチ") | E10: =COUNTIFS(明細!$G$5:$G$363,A10,明細!$D$5:$D$363,"バッチ") | F10: =IF(D10=0,0,E10/D10) | G10: =SUM($D$6:D10) | H10: =SUM($E$6:E10) | I10: =IF(G10=0,"",H10/G10) | J10: =IF(A10>$S$2,"予定",IF(G10=0,"－",IF(I10>=1,"完了",IF(H10>=G10,"順調","遅延")))) | K10: =COUNTIFS(明細!$I$5:$I$363,A10,明細!$D$5:$D$363,"バッチ") | L10: =COUNTIFS(明細!$J$5:$J$363,A10,明細!$D$5:$D$363,"バッチ") | M10: =IF(K10=0,0,L10/K10) | N10: =SUM($K$6:K10) | O10: =SUM($L$6:L10) | P10: =IF(N10=0,"",O10/N10) | Q10: =IF(A10>$S$2,"予定",IF(N10=0,"－",IF(P10>=1,"完了",IF(O10>=N10,"順調","遅延")))) | R10: =D10+K10 | S10: =E10+L10
A11: 46007 | B11: =CHOOSE(WEEKDAY(A11,2),"月","火","水","木","金","土","日") | C11: =IF(OR(WEEKDAY(A11,2)>=6,COUNTIF(祝日マスタ!$A:$A,A11)>0),"非営業日","営業日") | D11: =COUNTIFS(明細!$F$5:$F$363,A11,明細!$D$5:$D$363,"バッチ") | E11: =COUNTIFS(明細!$G$5:$G$363,A11,明細!$D$5:$D$363,"バッチ") | F11: =IF(D11=0,0,E11/D11) | G11: =SUM($D$6:D11) | H11: =SUM($E$6:E11) | I11: =IF(G11=0,"",H11/G11) | J11: =IF(A11>$S$2,"予定",IF(G11=0,"－",IF(I11>=1,"完了",IF(H11>=G11,"順調","遅延")))) | K11: =COUNTIFS(明細!$I$5:$I$363,A11,明細!$D$5:$D$363,"バッチ") | L11: =COUNTIFS(明細!$J$5:$J$363,A11,明細!$D$5:$D$363,"バッチ") | M11: =IF(K11=0,0,L11/K11) | N11: =SUM($K$6:K11) | O11: =SUM($L$6:L11) | P11: =IF(N11=0,"",O11/N11) | Q11: =IF(A11>$S$2,"予定",IF(N11=0,"－",IF(P11>=1,"完了",IF(O11>=N11,"順調","遅延")))) | R11: =D11+K11 | S11: =E11+L11
A12: 46008 | B12: =CHOOSE(WEEKDAY(A12,2),"月","火","水","木","金","土","日") | C12: =IF(OR(WEEKDAY(A12,2)>=6,COUNTIF(祝日マスタ!$A:$A,A12)>0),"非営業日","営業日") | D12: =COUNTIFS(明細!$F$5:$F$363,A12,明細!$D$5:$D$363,"バッチ") | E12: =COUNTIFS(明細!$G$5:$G$363,A12,明細!$D$5:$D$363,"バッチ") | F12: =IF(D12=0,0,E12/D12) | G12: =SUM($D$6:D12) | H12: =SUM($E$6:E12) | I12: =IF(G12=0,"",H12/G12) | J12: =IF(A12>$S$2,"予定",IF(G12=0,"－",IF(I12>=1,"完了",IF(H12>=G12,"順調","遅延")))) | K12: =COUNTIFS(明細!$I$5:$I$363,A12,明細!$D$5:$D$363,"バッチ") | L12: =COUNTIFS(明細!$J$5:$J$363,A12,明細!$D$5:$D$363,"バッチ") | M12: =IF(K12=0,0,L12/K12) | N12: =SUM($K$6:K12) | O12: =SUM($L$6:L12) | P12: =IF(N12=0,"",O12/N12) | Q12: =IF(A12>$S$2,"予定",IF(N12=0,"－",IF(P12>=1,"完了",IF(O12>=N12,"順調","遅延")))) | R12: =D12+K12 | S12: =E12+L12
